File: BreakingLoadData/Kevlar/200mm/Trial1/17-4PH-300C-4h-482-1h-02-Test Run 8 07-22-25 16 19 28 PM/DAQ- Crosshead, … - (Timed).csv
"File Path: C:\Users\Administrator\Desktop\Test Run 8 07-22-25 16 19 28 PM\DAQ- Crosshead, … - (Timed).csv   "
"Test: 17-4PH"
"Test Run: Test Run 8"
"Date: 7/22/2025 4:17:56 PM"
""
""
"Crosshead ","Load ","Time ","Extensometer "
"mm","kN","sec","mm"
"9.31489623212656E-05","0.0800752182006836","0.00999999977648258","4.5745252919005E-05"
"0.00186297916116018","0.0965070877075195","0.0900000035762787","0.000247855126644936"
"0.00395883080273052","0.113551856994629","0.170000001788139","0.000509863241404673"
"0.0061944056142238","0.129022094726563","0.25","0.00068104753836451"
"0.00824368271423737","0.14081379699707","0.330000013113022","0.000808590925771568"
"0.0102463855000678","0.152183807373047","0.409999996423721","0.000942914425650088"
"0.0123888112284476","0.163011184692383","0.490000009536743","0.00104146624835266"
"0.0144380883284612","0.172894821166992","0.569999992847443","0.00122463347906887"
"0.0163942168001086","0.182507415771484","0.649999976158142","0.00130003127196687"
"0.0184900691237999","0.192685668945312","0.730000019073486","0.00146915567711403"
"0.0204927710001357","0.202354522705078","0.810000002384186","0.00148768242524966"
"0.0224954728764715","0.212270263671875","0.889999985694885","0.00167301789133489"
"0.0245913252001628","0.222393493652344","0.970000028610229","0.0018425089365337"
"0.0266406023001764","0.23221891784668","1.04999995231628","0.00197476492758142"
"0.0286433041765122","0.242172958374023","1.12999999523163","0.00207218931791431"
"0.0306925830955151","0.253598327636719","1.21000003814697","0.0022314839043247"
"0.0327418601955287","0.263668762207031","1.28999996185303","0.00237368112721015"
"0.0346979868481867","0.274533142089844","1.37000000476837","0.0025408648980374"
"0.0367472639482003","0.286071594238281","1.45000004768372","0.00264992854681623"
"0.0388431144529022","0.298658538818359","1.52999997138977","0.00286274780592066"
"0.040799244743539","0.310084045410156","1.61000001430511","0.00300972510558495"
"0.0428485218435526","0.323273345947266","1.69000005722046","0.00321590960083995"
"0.0449443723482545","0.337212005615234","1.76999998092651","0.00340967608281062"
"0.0469005026388913","0.350878326416016","1.85000002384186","0.0036181691029924"
"0.0489497797389049","0.365206176757813","1.92999994754791","0.00378498225472867"
"0.0510456302436069","0.380545257568359","2.00999999046326","0.00404745924242889"
"0.0530017568962649","0.394542907714844","2.08999991416931","0.00431394664701656"
"0.0550510339962784","0.410281829833984","2.17000007629395","0.00448128639618517"
"0.0571468881389592","0.426710510253906","2.25","0.00474931721328176"
"0.0591495881963056","0.44174072265625","2.32999992370605","0.004928987891617"
"0.0611522918916307","0.457870056152344","2.41000008583069","0.00518510523761506"
"0.0632481460343115","0.474234375","2.49000000953674","0.00541696908840095"
"0.0652508460916579","0.490020080566406","2.5699999332428","0.00562166542295017"
"0.0672069727443159","0.505968200683594","2.65000009536743","0.00585761335969437"
"0.0693028268869966","0.52315576171875","2.73000001907349","0.00614166083323653"
"0.0713521003490314","0.539710388183594","2.80999994277954","0.00639394784229808"
"0.073308234277647","0.55544580078125","2.89000010490417","0.00658429917166359"
"0.0754040811443701","0.572553833007812","2.97000002861023","0.00685395798427635"
"0.0774533618823625","0.588926208496094","3.04999995231628","0.00704659669281682"
"0.0794094885350205","0.605321044921875","3.13000011444092","0.00729108160157921"
"0.0814587619970553","0.622939270019531","3.21000003814697","0.00761230603529839"
"0.0835080427350476","0.640215637207031","3.28999996185303","0.00789791374700144"
"0.085510742792394","0.65692626953125","3.36999988555908","0.00812460439192364"
"0.0875600235303864","0.674611694335937","3.45000004768372","0.00838116920931498"
"0.0896558703971095","0.692689819335938","3.52999997138977","0.00861609350977233"
"0.0916120043257251","0.709395812988281","3.60999989509583","0.00886141697264975"
"0.0936612777877599","0.727396240234375","3.69000005722046","0.00910755443328526"
"0.0957571319304407","0.745498291015625","3.76999998092651","0.00932197508518584"
"0.0977132585830986","0.761527648925781","3.84999990463257","0.00961214846029179"
"0.0997625320451334","0.779455871582031","3.9300000667572","0.00990543412626721"
"0.101858386187814","0.797443542480469","4.01000022888184","0.0101370123957167"
"0.103861086245161","0.81363720703125","4.09000015258789","0.0103506263258168"
"0.105863793578465","0.830969299316406","4.17000007629395","0.0106047746157856"
"0.107959647721145","0.848593627929688","4.25","0.0108622261905111"
"0.109915774373803","0.865344848632812","4.32999992370605","0.0111433228084934"
"0.11191847443115","0.881965637207031","4.40999984741211","0.0113988844532287"
"0.11401432857383","0.900082824707031","4.48999977111816","0.0116925666588941"
"0.116017028631177","0.916518188476563","4.57000017166138","0.0119451251521241"
"0.118019728688523","0.932951354980469","4.65000009536743","0.0121357397802058"
"0.120115582831204","0.951363586425781","4.73000001907349","0.0124581492855214"
"0.122118290164508","0.96857080078125","4.80999994277954","0.0126539771372336"
"0.124120982945897","0.98553173828125","4.8899998664856","0.0129986901811208"
"0.126216837088577","1.00417651367187","4.96999979019165","0.0131691731439787"
"0.128266110550612","1.02111157226562","5.05000019073486","0.0133717448989046"
"0.130222251755185","1.03769653320312","5.13000011444092","0.0137069191623596"
"0.132318091345951","1.05543933105469","5.21000003814697","0.0139383191708475"
"0.134367379359901","1.07319653320313","5.28999996185303","0.0141967739182292"
"0.136323506012559","1.08988305664063","5.36999988555908","0.0145961830639862"
"0.138372779474594","1.10857897949219","5.44999980926514","0.0147396358443075"
"0.140468633617274","1.12671337890625","5.53000020980835","0.0149554489325965"
"0.142424760269932","1.14301403808594","5.6100001335144","0.0151931317304843"
"0.144474033731967","1.16088903808594","5.69000005722046","0.0153984219650738"
"0.146523307194002","1.17907067871094","5.76999998092651","0.015685984180891"
"0.148526014527306","1.19587414550781","5.84999990463257","0.0159028113557724"
"0.15052872186061","1.21364318847656","5.92999982833862","0.0161991047207266"
"0.152624576003291","1.232564453125","6.01000022888184","0.016380516171921"
"0.154627268784679","1.25017858886719","6.09000015258789","0.0167638336279197"
"0.156629976117983","1.26738427734375","6.17000007629395","0.0169829509104602"
"0.158772396389395","1.28656018066406","6.25","0.0172161198861431"
"0.160775103722699","1.30391760253906","6.32999992370605","0.0174659780896036"
"0.162731230375357","1.32090344238281","6.40999984741211","0.0177227484527975"
"0.164827084518038","1.33997778320312","6.48999977111816","0.0179949165612925"
"0.166829791851342","1.35764636230469","6.57000017166138","0.0182412059075432"
"0.16883248463273","1.37444775390625","6.65000009536743","0.0184145701496163"
"0.170928338775411","1.39350500488281","6.73000001907349","0.0187389232451096"
"0.172931046108715","1.41113037109375","6.80999994277954","0.0189923030120553"
"0.174933738890104","1.427900390625","6.8899998664856","0.0192044626601273"
"0.176983026904054","1.44637561035156","6.96999979019165","0.0194178392121103"
"0.179032300366089","1.4646181640625","7.05000019073486","0.0197151384782046"
"0.180988427018747","1.48179431152344","7.13000011444092","0.0199296227947343"
"0.183084281161427","1.5005126953125","7.21000003814697","0.0201809798454633"
"0.185133554623462","1.51924279785156","7.28999996185303","0.0204034131456865"
"0.187136261956766","1.53587292480469","7.36999988555908","0.0207160665013362"
"0.189185535418801","1.55441125488281","7.44999980926514","0.020987774405512"
"0.191281389561482","1.57288061523438","7.53000020980835","0.021224261217867"
"0.19323751621414","1.58893481445313","7.6100001335144","0.0213814255403122"
"0.195240223547444","1.60698364257812","7.69000005722046","0.0216530570469331"
"0.197336077690125","1.62588403320313","7.76999998092651","0.0218845125345979"
"0.199338770471513","1.6424560546875","7.84999990463257","0.0221269874600694"
"0.201341477804817","1.66009362792969","7.92999982833862","0.0223982078750851"
"0.203483898076229","1.67904028320313","8.01000022888184","0.0227040691243019"
"0.205440024728887","1.69618981933594","8.09000015258789","0.0228694298129994"
"0.207442732062191","1.7134462890625","8.17000007629395","0.0231042049563257"
"0.209538586204872","1.732068359375","8.25","0.023341846826952"
"0.21149471285753","1.74935754394531","8.32999992370605","0.023616945327376"
"0.213497420190834","1.76662670898438","8.40999984741211","0.0238323518715333"
"0.215639840462245","1.78620764160156","8.48999977111816","0.0241053476202069"
"0.217642547795549","1.80409680175781","8.56999969482422","0.0243923987000016"
"0.219645240576938","1.82111401367188","8.64999961853027","0.0246241506829392"
"0.221741094719619","1.84035095214844","8.72999954223633","0.0248787146119867"
"0.223743802052923","1.85826123046875","8.8100004196167","0.0250427965511335"
"0.225746509386227","1.87528649902344","8.89000034332275","0.025371351512149"
"0.227795782848261","1.89356921386719","8.97000026702881","0.0256004350376315"
"0.229845056310296","1.91171313476563","9.05000019073486","0.0257860538113164"
"0.231801182962954","1.92819897460938","9.13000011444092","0.0260322340182029"
"0.233897037105635","1.94628576660156","9.21000003814697","0.0262421726802131"
"0.23594631056767","1.9651962890625","9.28999996185303","0.0265478483925108"
"0.237902437220328","1.98182971191406","9.36999988555908","0.0267001632892061"
"0.239951725234278","1.99908435058594","9.44999980926514","0.0269997453870019"
"0.242047564825043","2.017994140625","9.52999973297119","0.0272606976068346"
"0.244003706029616","2.0347041015625","9.60999965667725","0.0274796329904348"
"0.246052979491651","2.05219165039063","9.6899995803833","0.0277705694315955"
"0.248148833634332","2.07095874023438","9.77000045776367","0.0279994983429788"
"0.25010496028699","2.08811694335937","9.85000038146973","0.0281361335510155"
"0.252154219197109","2.10564501953125","9.93000030517578","0.0284565630863653"
"0.25425007333979","2.12503930664063","10.0100002288818","0.0286483445961494"
"0.256252795225009","2.14161840820312","10.0900001525879","0.0288693354377756"
"0.258255488006398","2.15819995117188","10.1700000762939","0.0291414507955778"
"0.260351342149079","2.17683618164062","10.25","0.0293568173219683"
"0.262354034930468","2.19407495117188","10.3299999237061","0.0295700428978307"
"0.264310161583126","2.2107431640625","10.4099998474121","0.0297958558803657"
"0.266406015725806","2.229501953125","10.4899997711182","0.0300609590340173"
"0.268455303739756","2.24621923828125","10.5699996948242","0.0302742791973287"
"0.270411430392414","2.26200854492187","10.6499996185303","0.0305271751130931"
"0.272507284535095","2.28012426757813","10.7299995422363","0.0307232148770709"
"0.274509977316484","2.2975732421875","10.8100004196167","0.0309867136820685"
"0.276512699201703","2.31378833007813","10.8900003433228","0.0311883086396847"
"0.278608524240553","2.33212060546875","10.9700002670288","0.031450814276468"
"0.280657812254503","2.34946655273438","11.0500001907349","0.0316661207762081"
"0.282613938907161","2.3657421875","11.1300001144409","0.0318365564453416"
"0.284709793049842","2.38227709960938","11.210000038147","0.0320394210575614"
"0.286759081063792","2.399650390625","11.289999961853","0.0323378735629376"
"0.28871520771645","2.41498681640625","11.3699998855591","0.0325827568303794"
"0.29076446662657","2.43184716796875","11.4499998092651","0.0327364068652969"
"0.29286032076925","2.45012353515625","11.5299997329712","0.0329161775880493"
"0.294816447421908","2.46545629882813","11.6099996566772","0.0331675473717041"
"0.296865735435858","2.48214599609375","11.6899995803833","0.0334209726133849"
"0.298961589578539","2.49996997070313","11.7700004577637","0.0336856792273466"
"0.300917716231197","2.5150126953125","11.8500003814697","0.0338695172104053"
"0.302920409012586","2.53038427734375","11.9300003051758","0.0340676597261336"
"0.305016263155267","2.54753686523437","12.0100002288818","0.0342778184858616"
"0.307018985040486","2.5631572265625","12.0900001525879","0.0344791005773004"
"0.309021677821875","2.57869604492187","12.1700000762939","0.0347004643117543"
"0.311117531964555","2.59607202148438","12.25","0.0348488028976135"
"0.313120224745944","2.61197875976563","12.3299999237061","0.0351385642716195"
"0.315169512759894","2.62700903320312","12.4099998474121","0.0353063987859059"
"0.317265366902575","2.64349536132812","12.4899997711182","0.0355542251782026"
"0.319268059683964","2.65874658203125","12.5699996948242","0.0358202523784712"
"0.321224186336622","2.67390625","12.6499996185303","0.035990171454614"
"0.323320040479302","2.69042065429687","12.7299995422363","0.0362187529390212"
"0.325369328493252","2.70623681640625","12.8100004196167","0.0364586994692218"
"0.32732545514591","2.72064819335937","12.8900003433228","0.0365841478924267"
"0.329421309288591","2.73748120117187","12.9700002670288","0.0368073597201146"
"0.331470568198711","2.75310083007813","13.0500001907349","0.0369967565347906"
"0.333426694851369","2.767548828125","13.1300001144409","0.0371555506717414"
"0.335475982865319","2.783279296875","13.210000038147","0.037401623558253"
"0.337525241775438","2.79945849609375","13.289999961853","0.0375940835510846"
"0.339481368428096","2.8135712890625","13.3699998855591","0.0378533804905601"
"0.341577222570777","2.82919604492188","13.4499998092651","0.0380594210582785"
"0.343626510584727","2.84525610351562","13.5299997329712","0.0382303405785933"
"0.345629203366116","2.85938330078125","13.6099996566772","0.0384455597668421"
"0.347631925251335","2.87410546875","13.6899995803833","0.0385850144084543"
"0.349774345522746","2.89090356445312","13.7700004577637","0.0387342915928457"
"0.351730472175404","2.90466284179687","13.8500003814697","0.038978334487183"
"0.353733164956793","2.91902392578125","13.9300003051758","0.0391898684029002"
"0.355829019099474","2.93443505859375","14.0100002288818","0.0393459740735125"
"0.357878307113424","2.94898803710938","14.0900001525879","0.0396157156501431"
"0.359834433766082","2.9625478515625","14.1700000762939","0.0398393021896482"
"0.361930287908763","2.97831616210938","14.25","0.0399588279833551"
"0.363932980690151","2.993236328125","14.3299999237061","0.0401570032408927"
"0.36593567347154","3.0075224609375","14.4099998474121","0.0403993362851907"
"0.36798496148549","3.02342529296875","14.4899997711182","0.0405295431846753"
"0.37003424949944","3.0379658203125","14.5699996948242","0.0407171501137782"
"0.371990376152098","3.0511474609375","14.6499996185303","0.0409124877478462"
"0.374086230294779","3.06656616210938","14.7299995422363","0.0411029468523338"
"0.376135489204898","3.08152856445313","14.8100004196167","0.0413234120060224"
"0.378138211090118","3.09520654296875","14.8900003433228","0.0414496898883954"
"0.380234065232798","3.11067260742188","14.9700002670288","0.0416979564761277"
"0.382283324142918","3.12501611328125","15.0500001907349","0.0418772287957836"
"0.384239450795576","3.13820385742188","15.1300001144409","0.0420554169977549"
"0.386242172680795","3.15241528320312","15.210000038147","0.0422133089159615"
"0.388337997719646","3.16767602539062","15.289999961853","0.0424062927777413"
"0.390340719604865","3.180765625","15.3699998855591","0.0426377555413637"
"0.392389978514984","3.195533203125","15.4499998092651","0.0427568447776139"
"0.394485832657665","3.21038354492187","15.5299997329712","0.0430200598202646"
"0.396441959310323","3.223859375","15.6099996566772","0.0431862608820666"
"0.398444681195542","3.23786181640625","15.6899995803833","0.0433415843872353"
"0.400540535338223","3.25323876953125","15.7700004577637","0.0435474394180346"
"0.402496661990881","3.26626147460937","15.8500003814697","0.0436822738265619"
"0.404545920901","3.28040673828125","15.9300003051758","0.0438887436757796"
"0.406641775043681","3.29569750976562","16.0100002288818","0.0441459487774409"
"0.4086444969289","3.309712890625","16.0900001525879","0.0443307908426505"
"0.410647189710289","3.323095703125","16.1700000762939","0.0444419565610588"
"0.41274304385297","3.33831982421875","16.25","0.0446805606770795"
"0.414745736634359","3.35108740234375","16.3299999237061","0.0448109822173137"
"0.416701863287017","3.36390844726562","16.4099998474121","0.0450152074336074"
"0.418797717429698","3.3787900390625","16.4899997711182","0.0451516680186614"
"0.420847005443648","3.39269995117187","16.5699996948242","0.0452995373052545"
"0.422803132096305","3.40558227539062","16.6499996185303","0.0455343724752311"
"0.424898986238986","3.419498046875","16.7299995422363","0.045710286940448"
"0.426948245149106","3.43373315429687","16.8099994659424","0.0459720504295547"
"0.428904371801764","3.445958984375","16.8899993896484","0.0460901428596117"
"0.431000225944445","3.46017993164063","16.9699993133545","0.0462415300717112"
"0.433049513958395","3.4748671875","17.0499992370605","0.0464130243926775"
"0.435005640611053","3.48743798828125","17.1299991607666","0.0466156416223384"
"0.437101494753733","3.50205078125","17.2099990844727","0.0467755016870797"
"0.439150782767683","3.51594409179688","17.2900009155273","0.0469715523649938"
"0.441153475549072","3.52920654296875","17.3700008392334","0.0471199273306411"
"0.443202763563022","3.54244897460938","17.4500007629395","0.0473327418148983"
"0.445252022473142","3.5574501953125","17.5300006866455","0.0474690677947365"
"0.44725471525453","3.5699013671875","17.6100006103516","0.0476761306344997"
"0.44925743713975","3.58321313476563","17.6900005340576","0.0478533947898541"
"0.45135329128243","3.59743188476563","17.7700004577637","0.0480340531794354"
"0.453355984063819","3.61062524414063","17.8500003814697","0.0481794122606516"
"0.455358676845208","3.62328125","17.9300003051758","0.0483683033962734"
"0.457454530987889","3.63872094726563","18.0100002288818","0.0485549317090772"
"0.459457252873108","3.6511025390625","18.0900001525879","0.0487575998704415"
"0.461413379525766","3.66423193359375","18.1700000762939","0.0488596560899168"
"0.463509233668447","3.67897729492188","18.25","0.0490658276248723"
"0.465511926449835","3.69219897460938","18.3299999237061","0.0492586732434575"
"0.467514619231224","3.705154296875","18.4099998474121","0.0493533916596789"
"0.469610473373905","3.72029858398438","18.4899997711182","0.0496641150675714"
"0.471659761387855","3.73362915039062","18.5699996948242","0.0497730798088014"
"0.473615888040513","3.746439453125","18.6499996185303","0.0499157831654884"
"0.475711742183194","3.76099975585938","18.7299995422363","0.0500579953950364"
"0.477761001093313","3.77489208984375","18.8099994659424","0.0503676637890749"
"0.479717127745971","3.78721362304687","18.8899993896484","0.0504829367855564"
"0.481812981888652","3.80093798828125","18.9699993133545","0.0506190626765601"
"0.483862269902602","3.81507202148437","19.0499992370605","0.0508277880726382"
"0.48581839655526","3.8269560546875","19.1299991607666","0.0509579658682924"
"0.48786768456921","3.84063110351563","19.2099990844727","0.0511112230014987"
"0.48996350960806","3.85482983398437","19.2900009155273","0.0513120503455866"
"0.491919636260718","3.86737817382813","19.3700008392334","0.0514398816449102"
"0.493968953378499","3.88056665039062","19.4500007629395","0.0517269145348109"
"0.496018212288618","3.89488159179687","19.5300006866455","0.0518622946401592"
"0.498020905070007","3.90727685546875","19.6100006103516","0.0519762397743762"
"0.500070163980126","3.92012377929688","19.6900005340576","0.0522059490322135"
"0.502119481097907","3.93403247070313","19.7700004577637","0.05231349132373"
"0.504122173879296","3.94723974609375","19.8500003814697","0.0525126997672487"
"0.506171432789415","3.96109643554687","19.9300003051758","0.0526260737387929"
"0.508267316035926","3.97502709960938","20.0100002288818","0.0528339005541056"
"0.510270008817315","3.98758911132813","20.0900001525879","0.0530131874256767"
"0.512272701598704","4.00001318359375","20.1700000762939","0.0532161102455575"
"0.514321960508823","4.01360888671875","20.25","0.053333533287514"
"0.516324711497873","4.02653515625","20.3299999237061","0.0534858882019762"
"0.518327404279262","4.03877124023438","20.4099998474121","0.0537040796189103"
"0.520423229318112","4.05294580078125","20.4899997711182","0.0539174034202006"
"0.522472488228232","4.06620703125","20.5699996948242","0.0540692162758205"
"0.52442861488089","4.07779296875","20.6499996185303","0.0542214838787913"
"0.52647793199867","4.0908720703125","20.7299995422363","0.0543753667443525"
"0.52852719090879","4.10357177734375","20.8099994659424","0.0545280272490345"
"0.530529883690178","4.11632958984375","20.8899993896484","0.0547464733244851"
"0.532579200807959","4.129244140625","20.9699993133545","0.0548868629266508"
"0.534628459718078","4.14275","21.0499992370605","0.0550584045413416"
"0.536631152499467","4.15461376953125","21.1299991607666","0.0551403682038654"
"0.538680411409587","4.16719873046875","21.2099990844727","0.055355099902954"
"0.540776294656098","4.18093994140625","21.2900009155273","0.0554919970454648"
"0.542732421308756","4.19251953125","21.3700008392334","0.0556447084818501"
"0.544781680218875","4.20513037109375","21.4500007629395","0.0558340034331195"
"0.546830939128995","4.2192392578125","21.5300006866455","0.0559821492061019"
"0.548833690118045","4.23123974609375","21.6100006103516","0.0561732995265629"
"0.550882949028164","4.2432880859375","21.6900005340576","0.0563168796361424"
"0.552932207938284","4.256810546875","21.7700004577637","0.0564775655220728"
"0.554934900719672","4.2684482421875","21.8500003814697","0.0566395974601619"
"0.556937651708722","4.2804970703125","21.9300003051758","0.0567452007089742"
"0.559033476747572","4.29404541015625","22.0100002288818","0.0569493458897341"
"0.561036169528961","4.30594140625","22.0900001525879","0.0570627234992571"
"0.56303886231035","4.3177509765625","22.1700000762939","0.0572538119740784"
"0.56508817942813","4.33143701171875","22.25","0.0574091754970141"
"0.56713743833825","4.34392724609375","22.3299999237061","0.0575362937524915"
"0.569140131119639","4.35549658203125","22.4099998474121","0.0576864476897754"
"0.57123601436615","4.36796240234375","22.4899997711182","0.0579005136387423"
"0.573238707147539","4.38094091796875","22.5699996948242","0.0580678570258897"
"0.575241399928927","4.3923193359375","22.6499996185303","0.0582201682846062"
"0.577290658839047","4.40589404296875","22.7299995422363","0.0583411783736665"
"0.579339975956827","4.41875390625","22.8099994659424","0.0585294037591666"
"0.581296102609485","4.4302431640625","22.8899993896484","0.0586815585847944"
"0.583391927648336","4.4435146484375","22.9699993133545","0.0588221919315401"
"0.585441186558455","4.45594677734375","23.0499992370605","0.0589969058637507"
"0.587443937547505","4.46813037109375","23.1299991607666","0.0591463831369765"
"0.589493196457624","4.48131787109375","23.2099990844727","0.0592806172790006"
"0.591495889239013","4.49373388671875","23.2900009155273","0.0594487501075491"
"0.593545148149133","4.5061513671875","23.3700008392334","0.0596315003349446"
"0.595547899138182","4.51796240234375","23.4500007629395","0.0597935722908005"
"0.597643724177033","4.5310244140625","23.5300006866455","0.059948146372335"
"0.599646416958421","4.54260498046875","23.6100006103516","0.0600660459895153"
"0.60164910973981","4.55491162109375","23.6900005340576","0.0602609470661264"
"0.603744992986321","4.567509765625","23.7700004577637","0.0603986845817417"
"0.60574768576771","4.57968408203125","23.8500003814697","0.0605517489020713"
"0.607750378549099","4.5920234375","23.9300003051758","0.0607651818427257"
"0.60984626179561","4.60441162109375","24.0100002288818","0.0608975096838549"
"0.611848954576999","4.61597412109375","24.0900001525879","0.0610509450780228"
"0.613851647358388","4.62811474609375","24.1700000762939","0.0611160648986697"
"0.615947472397238","4.6417255859375","24.25","0.0614038945059292"
"0.617950223386288","4.6533994140625","24.3299999237061","0.061536455177702"
"0.619952916167676","4.66571728515625","24.4099998474121","0.0616079123574309"
"0.622048741206527","4.67879150390625","24.4899997711182","0.0618666963418946"
"0.624051433987916","4.6902392578125","24.5699996948242","0.0619619095232338"
"0.626007560640574","4.70108935546875","24.6499996185303","0.062123013776727"
"0.628056877758354","4.713455078125","24.7299995422363","0.0623353189439513"
"0.630152702797204","4.72625146484375","24.8099994659424","0.0623825180809945"
"0.632108829449862","4.7370078125","24.8899993896484","0.0625663087703288"
"0.634204712696373","4.74992578125","24.9699993133545","0.0627302433713339"
"0.636253971606493","4.7630810546875","25.0499992370605","0.0628740963293239"
"0.638256664387882","4.77440576171875","25.1299991607666","0.0630882568657398"
"0.640305923298001","4.78616796875","25.2099990844727","0.0631086222711019"
"0.642355240415782","4.798544921875","25.2900009155273","0.0632884039077908"
"0.64431136706844","4.80919775390625","25.3700008392334","0.0634554962744005"
"0.646360625978559","4.82120751953125","25.4500007629395","0.0636080731055699"
"0.64845650922507","4.834830078125","25.5300006866455","0.0638081037322991"
"0.650412635877728","4.845962890625","25.6100006103516","0.0639379068161361"
"0.652415328659117","4.85765625","25.6900005340576","0.0640989164821804"
"0.654511153697968","4.8708896484375","25.7700004577637","0.0642991653876379"
"0.656513846479356","4.88224951171875","25.8500003814697","0.0644081446807832"
"0.658516597468406","4.89378125","25.9300003051758","0.0645473119220696"
"0.660612422507256","4.90703466796875","26.0100002288818","0.0646716798655689"
"0.662661681417376","4.91924365234375","26.0900001525879","0.0648677014396526"
"0.664664374198765","4.93083642578125","26.1700000762939","0.0650187648716383"
"0.666760257445276","4.94465478515625","26.25","0.0651830632705241"
"0.668762950226665","4.9561962890625","26.3299999237061","0.0653027454973198"
"0.670765643008053","4.96730224609375","26.4099998474121","0.0653991446597502"
"0.672814960125834","4.97959326171875","26.4899997711182","0.0655309995636344"
"0.674864219035953","4.99262939453125","26.5699996948242","0.065783693571575"
"0.676820345688611","5.00383251953125","26.6499996185303","0.0659377692500129"
"0.678916170727462","5.0170166015625","26.7299995422363","0.0660176228848286"
"0.680965487845242","5.0308828125","26.8099994659424","0.0662517923046835"
"0.6829216144979","5.042841796875","26.8899993896484","0.0664066756144166"
"0.68497087340802","5.0564326171875","26.9699993133545","0.0665881962049752"
"0.687020132318139","5.06941259765625","27.0499992370605","0.0667663553031161"
"0.689022825099528","5.08223779296875","27.1299991607666","0.0668979701003991"
"0.691072142217308","5.09515185546875","27.2099990844727","0.0671036832500249"
"0.693121401127428","5.109181640625","27.2900009155273","0.0671564630465582"
"0.695170660037547","5.12184423828125","27.3700008392334","0.0673841350362636"
"0.697173411026597","5.13376416015625","27.4500007629395","0.0675509654683992"
"0.699269236065447","5.1478974609375","27.5300006866455","0.0677005155012012"
"0.701271928846836","5.15983056640625","27.6100006103516","0.0678533397149295"
"0.703274621628225","5.1722509765625","27.6900005340576","0.0680304074194282"
"0.705323938746005","5.18594970703125","27.7700004577637","0.0682997779222205"
"0.707373197656125","5.19863330078125","27.8500003814697","0.0684281185385771"
"0.709329324308783","5.21062646484375","27.9300003051758","0.068551380536519"
"0.711425149347633","5.2246787109375","28.0100002288818","0.0687337887939066"
"0.713427900336683","5.236673828125","28.0900001525879","0.0689149528625421"
"0.715430593118072","5.24919580078125","28.1700000762939","0.0690520682837814"
"0.717526418156922","5.26274609375","28.25","0.0692603716743179"
"0.719529110938311","5.2752822265625","28.3299999237061","0.0694268746883608"
"0.72153186192736","5.287693359375","28.4099998474121","0.0695674534654245"
"0.723627686966211","5.301240234375","28.4899997711182","0.069743262429256"
"0.725630379747599","5.3139267578125","28.5699996948242","0.0699638476362452"
"0.727633072528988","5.32577001953125","28.6499996185303","0.0701061217114329"
"0.729682389646769","5.338861328125","28.7299995422363","0.0702621618984267"
"0.731778214685619","5.35253662109375","28.8099994659424","0.0704547928762622"
"0.733734341338277","5.36419189453125","28.8899993896484","0.070577698352281"
"0.735783658456057","5.37660009765625","28.9699993133545","0.0707656290614977"
"0.737879483494908","5.38984375","29.0499992370605","0.0709380328771658"
"0.739835610147566","5.4015234375","29.1299991607666","0.0711125758243725"
"0.741884869057685","5.41389013671875","29.2099990844727","0.0712770633981563"
"0.743980752304196","5.42779150390625","29.2900009155273","0.0714452107786201"
"0.745936878956854","5.4395517578125","29.3700008392334","0.0715384085197002"
"0.747986137866974","5.451498046875","29.4500007629395","0.0717827424523421"
"0.750035396777093","5.4644951171875","29.5300006866455","0.0719559611752629"
"0.752038147766143","5.47684033203125","29.6100006103516","0.0720309544703923"
"0.753994274418801","5.4881572265625","29.6900005340576","0.0722530530765653"
"0.756090099457651","5.50299658203125","29.7700004577637","0.0725030186004005"
"0.758139358367771","5.51517138671875","29.8500003814697","0.0726000653230585"
"0.760188675485551","5.52764599609375","29.9300003051758","0.0727693477529101"
"0.762237934395671","5.541212890625","30.0100002288818","0.0729818566469476"
"0.76428719330579","5.55378076171875","30.0900001525879","0.0731450418243185"
"0.766243319958448","5.56521923828125","30.1700000762939","0.0732767657609656"
"0.768292637076229","5.578384765625","30.25","0.0734475252102129"
"0.770341895986348","5.591240234375","30.3299999237061","0.073564711783547"
"0.772344588767737","5.60253076171875","30.4099998474121","0.0737812661100179"
"0.774440472014248","5.61601220703125","30.4899997711182","0.0739292445359752"
"0.776489730924368","5.62896533203125","30.5699996948242","0.0741474577807821"
"0.778445857577026","5.6398681640625","30.6499996185303","0.0742452248232439"
"0.780495116487145","5.65235205078125","30.7299995422363","0.0744887584005482"
"0.782544433604926","5.66536376953125","30.8099994659424","0.0746738151065074"
"0.784500560257584","5.676833984375","30.8899993896484","0.0747695594327524"
"0.786549819167703","5.6894091796875","30.9699993133545","0.0749472383176908"
"0.788645644206554","5.70347900390625","31.0499992370605","0.0751149855204858"
"0.790648395195603","5.715330078125","31.1299991607666","0.0753468266339041"
"0.792697654105723","5.728189453125","31.2099990844727","0.0754311186028644"
"0.794746913015842","5.74135595703125","31.2900009155273","0.0756906883907504"
"0.7967030396685","5.75307470703125","31.3700008392334","0.075820877100341"
"0.798752356786281","5.76570703125","31.4500007629395","0.075956282671541"
"0.800848181825131","5.77949658203125","31.5300006866455","0.0760868642828427"
"0.80285087460652","5.791263671875","31.6100006103516","0.0762941854191013"
"0.804853567387909","5.80368115234375","31.6900005340576","0.0765332151786424"
"0.80694945063442","5.81712646484375","31.7700004577637","0.0765984659665264"
"0.808952143415809","5.82946240234375","31.8500003814697","0.0768364116083831"
"0.810908270068467","5.8413837890625","31.9300003051758","0.0769638863857836"
"0.813004095107317","5.8550361328125","32.0099983215332","0.0770929618738592"
"0.815053412225097","5.86742333984375","32.0900001525879","0.0773144565755501"
"0.817056105006486","5.87955419921875","32.1699981689453","0.0775238513597287"
"0.819151930045336","5.89274267578125","32.25","0.0776451925048605"
"0.821154681034386","5.9055166015625","32.3300018310547","0.0779168985900469"
"0.823110807687044","5.91679296875","32.4099998474121","0.0779856782173738"
"0.825206632725894","5.93022509765625","32.4900016784668","0.0782023635110818"
"0.827302457764745","5.9442900390625","32.5699996948242","0.0783618161221966"
"0.829212018288672","5.9550205078125","32.6500015258789","0.078531913459301"
"0.831261335406452","5.9681650390625","32.7299995422363","0.0786987075116485"
"0.833357160445303","5.98313525390625","32.810001373291","0.0789091718615964"
"0.835359853226691","5.99438330078125","32.8899993896484","0.0790814447100274"
"0.83736254600808","6.00702978515625","32.9700012207031","0.0792533974163234"
"0.839458429254591","6.02090966796875","33.0499992370605","0.0793619474279694"
"0.841414555907249","6.032720703125","33.1300010681152","0.079603138146922"
"0.843463814817369","6.04557373046875","33.2099990844727","0.0797665561549366"
"0.84555969806388","6.05916357421875","33.2900009155273","0.079939556599129"
"0.847562390845269","6.07115771484375","33.3699989318848","0.0800930210971273"
"0.849518517497927","6.0829873046875","33.4500007629395","0.0802133436081931"
"0.851614342536777","6.0965810546875","33.5299987792969","0.0805247982498258"
"0.853617093525827","6.1085888671875","33.6100006103516","0.0806263342383318"
"0.855666352435946","6.12131640625","33.689998626709","0.0807448959676549"
"0.857762177474797","6.1347412109375","33.7700004577637","0.0809770135674626"
"0.859764870256186","6.14792822265625","33.8499984741211","0.0811647696536966"
"0.861720996908844","6.15946826171875","33.9300003051758","0.0812994840089232"
"0.863863446284086","6.17286865234375","34.0099983215332","0.0814928134786896"
"0.865866139065474","6.18569921875","34.0900001525879","0.0816394385765307"
"0.867822265718132","6.1986416015625","34.1699981689453","0.0818109620013274"
"0.869871582835913","6.21182666015625","34.25","0.0820225468487479"
"0.871967407874763","6.2260009765625","34.3300018310547","0.0822420697659254"
"0.873970100656152","6.23778515625","34.4099998474121","0.0824038506834768"
"0.876019417773932","6.25106787109375","34.4900016784668","0.0825560782686807"
"0.878068676684052","6.26443310546875","34.5699996948242","0.0827363910502754"
"0.88002480333671","6.2755947265625","34.6500015258789","0.0829762866487727"
"0.882027496118098","6.28763818359375","34.7299995422363","0.0830951539683156"
"0.884123321156949","6.302001953125","34.810001373291","0.0832100122352131"
"0.886126072145998","6.31390087890625","34.8899993896484","0.0834053425933234"
"0.888221897184849","6.327095703125","34.9700012207031","0.0835565006127581"
"0.89031778043136","6.3413232421875","35.0499992370605","0.0837714687804691"
"0.892273907084018","6.35220166015625","35.1300010681152","0.08397957572015"
"0.894230033736676","6.36433642578125","35.2099990844727","0.0841371220303699"
"0.896325858775526","6.377734375","35.2900009155273","0.0843772504595108"
"0.898328551556915","6.39021142578125","35.3699989318848","0.0844415990286507"
"0.900377868674695","6.40321435546875","35.4500007629395","0.0846549737616442"
"0.902473693713546","6.4173828125","35.5299987792969","0.0848481577122584"
"0.904429820366204","6.4293798828125","35.6100006103516","0.0850016513140872"
"0.906432513147593","6.44165380859375","35.689998626709","0.0852039083838463"
"0.908481830265373","6.45575146484375","35.7700004577637","0.0854029131005518"
"0.910531089175493","6.4684345703125","35.8499984741211","0.0855497564771213"
"0.912487215828151","6.48010302734375","35.9300003051758","0.0857092454680242"
"0.914629606995732","6.494955078125","36.0099983215332","0.0859640058479272"
"0.916632357984781","6.5077509765625","36.0900001525879","0.0860810687299818"
"0.91863505076617","6.51903125","36.1699981689453","0.0862598099047318"
"0.92073087580502","6.5331103515625","36.25","0.0864500689203851"
"0.922733568586409","6.54593359375","36.3300018310547","0.0866139307618141"
"0.924736319575459","6.55758984375","36.4099998474121","0.0868664938025177"
"0.926785578485578","6.57075390625","36.4900016784668","0.0869769573910162"
"0.928881403524429","6.584294921875","36.5699996948242","0.08715434523765"
"0.930837530177087","6.59608447265625","36.6500015258789","0.087372689449694"
"0.932933413423598","6.60933544921875","36.7299995422363","0.0875131008797325"
"0.934982672333717","6.62368603515625","36.810001373291","0.0876365957083181"
"0.936938798986375","6.6352353515625","36.8899993896484","0.0878678110893816"
"0.938941491767764","6.6476279296875","36.9700012207031","0.0880411826074123"
"0.941037375014275","6.66177978515625","37.0499992370605","0.0882334570633247"
"0.942993501666933","6.67488916015625","37.1300010681152","0.0883756438270211"
"0.945042760577053","6.68795947265625","37.2099990844727","0.0885220433701761"
"0.947138643823564","6.70247802734375","37.2900009155273","0.088789442088455"
"0.949187902733684","6.71475341796875","37.3699989318848","0.0889316070242785"
"0.951144029386342","6.72668115234375","37.4500007629395","0.0891424278961495"
"0.953239854425192","6.7407109375","37.5299987792969","0.0892714233486913"
"0.955242605414242","6.7540224609375","37.6100006103516","0.0894815602805465"
"0.95724529819563","6.765478515625","37.689998626709","0.0896871060831472"
"0.959341123234481","6.7800146484375","37.7700004577637","0.0898573562153615"
"0.961343816015869","6.79267724609375","37.8499984741211","0.0899823644431308"
"0.963346567004919","6.80493115234375","37.9300003051758","0.0901864696061239"
"0.965395825915039","6.8185556640625","38.0099983215332","0.0903989421203732"
"0.967491650953889","6.83176611328125","38.0900001525879","0.0906559289433062"
"0.969447777606547","6.84326318359375","38.1699981689453","0.0907540961634368"
"0.971497094724327","6.8574306640625","38.25","0.0909642549231648"
"0.973546353634447","6.87171923828125","38.3300018310547","0.0911349925445393"
"0.975549046415836","6.88326611328125","38.4099998474121","0.0912289615371265"
"0.977598363533616","6.89769921875","38.4900016784668","0.091429399617482"
"0.979694188572466","6.91124365234375","38.5699996948242","0.091681577032432"
"0.981650315225124","6.92281591796875","38.6500015258789","0.0918156947591342"
"0.983699574135244","6.93640283203125","38.7299995422363","0.0920116217457689"
"0.985795399174094","6.95111181640625","38.810001373291","0.0922986728255637"
"0.987751525826752","6.96277783203125","38.8899993896484","0.0923458937904797"
"0.989754218608141","6.975869140625","38.9700012207031","0.0925708300201222"
"0.991896726191044","6.9893271484375","39.0499992370605","0.092794252850581"
"0.993852852843702","7.00081201171875","39.1300010681152","0.0929067027755082"
"0.995855545625091","7.01323779296875","39.2099990844727","0.0931854156078771"
"0.997951370663941","7.02729833984375","39.2900009155273","0.0933469491428696"
"0.99995406344533","7.04118310546875","39.3699989318848","0.0935179996304214"
"1.00195675622672","7.0538828125","39.4500007629395","0.093655486125499"
"1.00405258126557","7.067560546875","39.5299987792969","0.0938364901230671"
"1.00605539046228","7.0797568359375","39.6100006103516","0.0940691243158653"
"1.00801151711494","7.09225537109375","39.689998626709","0.0942468759603798"
"1.01010734215379","7.10684521484375","39.7700004577637","0.0943727936828509"
"1.01215660106391","7.120390625","39.8499984741211","0.0945891661103815"
"1.0141592938453","7.13291162109375","39.9300003051758","0.0947724038269371"
"1.01625511888415","7.14685400390625","40.0099983215332","0.0950202884268947"
"1.01825781166553","7.16107275390625","40.0900001525879","0.0951451365835965"
"1.02021393831819","7.172939453125","40.1699981689453","0.0953463459154591"
"1.02230987977237","7.18601416015625","40.25","0.0955261130002327"
"1.02435913868248","7.199798828125","40.3300018310547","0.0957415904849768"
"1.02631526533514","7.2121943359375","40.4099998474121","0.0959172466536984"
"1.02836452424526","7.22607666015625","40.4900016784668","0.0960985780693591"
"1.03046034928411","7.2395576171875","40.5699996948242","0.096378025773447"
"1.0324630420655","7.25149072265625","40.6500015258789","0.0964846185524948"
"1.03446573484689","7.2641982421875","40.7299995422363","0.0966078296187334"
"1.03651499375701","7.27841552734375","40.810001373291","0.0968090462265536"
"1.03851780295372","7.290341796875","40.8899993896484","0.0970166074694134"
"1.04056706186384","7.30402783203125","40.9700012207031","0.0972376728896052"
"1.04266288690269","7.31872412109375","41.0499992370605","0.0974354916252196"
"1.04466557968408","7.3315234375","41.1300010681152","0.0976133233052678"
"1.04666827246547","7.34463720703125","41.2099990844727","0.0978291500359774"
"1.04876409750432","7.35905859375","41.2900009155273","0.0979719043243676"
"1.05076679028571","7.37155859375","41.3699989318848","0.0981584962573834"
"1.05272291693836","7.3832001953125","41.4500007629395","0.0982761266641319"
"1.05481885839254","7.39860888671875","41.5299987792969","0.0985610531643033"
"1.05686811730266","7.4121201171875","41.6100006103516","0.0987781750154682"
"1.05887081008404","7.4237373046875","41.689998626709","0.0988864703685977"
"1.0609666351229","7.43748779296875","41.7700004577637","0.0991466004052199"
"1.06296932790428","7.450970703125","41.8499984741211","0.099295713880565"
"1.06492545455694","7.46337060546875","41.9300003051758","0.0995352238533087"
"1.06702127959579","7.47717041015625","42.0099983215332","0.0997470051515847"
"1.0690240887925","7.49094873046875","42.0900001525879","0.0998418836388737"
"1.07102678157389","7.50285546875","42.1699981689453","0.100084907899145"
"1.07307604048401","7.51718310546875","42.25","0.1002313074423"
"1.07517186552286","7.53085595703125","42.3300018310547","0.100481185654644"
"1.07717455830425","7.5434169921875","42.4099998474121","0.100609642686322"
"1.07922381721437","7.55755517578125","42.4900016784668","0.10081916116178"
"1.08127307612449","7.57226171875","42.5699996948242","0.101097633887548"
"1.08327576890588","7.58451806640625","42.6500015258789","0.101204990642145"
"1.08527857810259","7.5977783203125","42.7299995422363","0.101341953268275"
"1.08737440314144","7.61221923828125","42.810001373291","0.101617544714827"
"1.08937709592283","7.6248232421875","42.8899993896484","0.101713798358105"
"1.09137978870422","7.6380849609375","42.9700012207031","0.101951554825064"
"1.09347561374307","7.65191796875","43.0499992370605","0.102148500445765"
"1.09543174039572","7.663982421875","43.1300010681152","0.102299651189242"
"1.09743443317711","7.6769345703125","43.2099990844727","0.102518162748311"
"1.09953037463129","7.69155078125","43.2900009155273","0.102746576885693"
"1.10153306741267","7.70431396484375","43.3699989318848","0.102917401818559"
"1.10353576019406","7.71637890625","43.4500007629395","0.103076476079877"
"1.10563158523291","7.73087109375","43.5299987792969","0.103349055279978"
"1.1076342780143","7.7437841796875","43.6100006103516","0.103501515695825"
"1.10963697079569","7.75553271484375","43.689998626709","0.103668753581587"
"1.11173279583454","7.7704306640625","43.7700004577637","0.103834885521792"
"1.11378205474466","7.7837294921875","43.8499984741211","0.104050814115908"
"1.11573818139732","7.796033203125","43.9300003051758","0.104201419162564"
"1.11783412285149","7.8105625","44.0099983215332","0.104477905551903"
"1.11988338176161","7.82415869140625","44.0900001525879","0.104572565760463"
"1.12183950841427","7.836513671875","44.1699981689453","0.104807601019274"
"1.12388876732439","7.8504228515625","44.25","0.10504469537409"
"1.12598459236324","7.86474365234375","44.3300018310547","0.105281556898262"
"1.1279407190159","7.87699365234375","44.4099998474121","0.105410203104839"
"1.12998997792602","7.89048681640625","44.4900016784668","0.105566570709925"
"1.13208591938019","7.90470361328125","44.5699996948242","0.105792918475345"
"1.13404204603285","7.91694970703125","44.6500015258789","0.105992541648448"
"1.13604473881423","7.92913671875","44.7299995422363","0.106162966403645"
"1.13814056385309","7.9441455078125","44.810001373291","0.106369006971363"
"1.14014325663447","7.95765234375","44.8899993896484","0.10655519872671"
"1.14219251554459","7.97078466796875","44.9700012207031","0.106745428638533"
"1.14428834058344","7.98537841796875","45.0499992370605","0.106974744994659"
"1.14629114978015","7.99815234375","45.1300010681152","0.107139072497375"
"1.14824727643281","8.0104296875","45.2099990844727","0.107377534732223"
"1.15034310147166","8.0247265625","45.2900009155273","0.10758812277345"
"1.15234579425305","8.0387001953125","45.3699989318848","0.107867293991148"
"1.15434848703444","8.0511669921875","45.4500007629395","0.107957464933861"
"1.15644431207329","8.0663935546875","45.5299987792969","0.10816512076417"
"1.15849357098341","8.08002734375","45.6100006103516","0.10837701120181"
"1.16044969763607","8.09247998046875","45.689998626709","0.108551132143475"
"1.16249907296151","8.106470703125","45.7700004577637","0.108743159216829"
"1.16454833187163","8.11997265625","45.8499984741211","0.108935011667199"
"1.16650445852429","8.13242626953125","45.9300003051758","0.109137916297186"
"1.16860028356314","8.14736962890625","46.0099983215332","0.109359039925039"
"1.17064954247326","8.16178125","46.0900001525879","0.109508961031679"
"1.17265223525465","8.174623046875","46.1699981689453","0.109717693703715"
"1.1747480602935","8.18787548828125","46.25","0.109953798528295"
"1.17679743561894","8.201953125","46.3300018310547","0.110078690340742"
"1.1787535622716","8.213943359375","46.4099998474121","0.110349217720795"
"1.18075625505298","8.2270185546875","46.4900016784668","0.110464592580684"
"1.18285208009183","8.2419775390625","46.5699996948242","0.110745429992676"
"1.18485477287322","8.2549208984375","46.6500015258789","0.110967470391188"
"1.18685746565461","8.268076171875","46.7299995422363","0.111107525299303"
"1.18895329069346","8.2830869140625","46.810001373291","0.111334746179637"
"1.19095598347485","8.295947265625","46.8899993896484","0.111595349153504"
"1.1934710200876","-0.351182067871094","46.923999786377","-0.937424541916698"