File: BreakingLoadData/Kevlar/200mm/Trial1/17-4PH-300C-4h-482-1h-01-Test Run 7 07-22-25 16 16 37 PM/DAQ- Crosshead, … - (Timed).csv
"File Path: C:\Users\Administrator\Desktop\Test Run 7 07-22-25 16 16 37 PM\DAQ- Crosshead, … - (Timed).csv   "
"Test: 17-4PH"
"Test Run: Test Run 7"
"Date: 7/22/2025 4:14:35 PM"
""
""
"Crosshead ","Load ","Time ","Extensometer "
"mm","kN","sec","mm"
"4.65744811606328E-05","0.132498825073242","0.00999999977648258","6.5909588897739E-05"
"0.00163010679443687","0.147900268554687","0.0799999982118607","0.000311159112698078"
"0.00339993698617036","0.167093643188477","0.150000005960464","0.000483936730688583"
"0.00535606523044407","0.18468701171875","0.219999998807907","0.000761497801704536"
"0.00721904416423058","0.200237747192383","0.28999999165535","0.0010208523235633"
"0.00898887446965091","0.214084350585937","0.360000014305115","0.00134415506636287"
"0.0108052790892543","0.2281943359375","0.430000007152557","0.0014578931768483"
"0.0126682589325355","0.241596084594727","0.5","0.00168365352237743"
"0.0143915140142781","0.255205123901367","0.569999992847443","0.00194969038602721"
"0.0161613443196984","0.268771484375","0.639999985694885","0.00217758906728704"
"0.0179777489393018","0.2828486328125","0.709999978542328","0.00243688486989413"
"0.0197475801542168","0.296477508544922","0.779999971389771","0.00264673303718155"
"0.0214708343264647","0.309921478271484","0.850000023841858","0.00282990845335007"
"0.0232406655413797","0.323052795410156","0.920000016689301","0.00307631648865936"
"0.0251036453846609","0.337472259521484","0.990000009536743","0.00338341169481282"
"0.0268734747805865","0.350593200683594","1.05999994277954","0.00356418672708969"
"0.0285967307718238","0.36393896484375","1.12999999523163","0.00366557924280642"
"0.030459710615105","0.377650360107422","1.20000004768372","0.00394621065424872"
"0.0322761152347084","0.391306915283203","1.26999998092651","0.00419886555391713"
"0.0339527941832785","0.404284088134766","1.3400000333786","0.00435627680417383"
"0.0357226272171829","0.417533874511719","1.4099999666214","0.00461711670141085"
"0.0375390300177969","0.432002868652344","1.48000001907349","0.00473153158964124"
"0.0393088594137225","0.445519470214844","1.54999995231628","0.00495110998599557"
"0.041078692447627","0.458788024902344","1.62000000476837","0.00520150251759333"
"0.0428485218435526","0.472830413818359","1.69000005722046","0.0054781721701147"
"0.0446649246441666","0.487124267578125","1.75999999046326","0.00569911935599521"
"0.046434757678071","0.500443664550781","1.83000004291534","0.00586975556871039"
"0.0481580136693083","0.5140439453125","1.89999997615814","0.00613633392276824"
"0.0499744164699223","0.528506958007813","1.97000002861023","0.00631585680821445"
"0.0517908229085151","0.542278015136719","2.03999996185303","0.00644755800749408"
"0.0535140788997523","0.555214294433594","2.10999989509583","0.00675068713462679"
"0.055283908295678","0.569800842285156","2.1800000667572","0.00693307811161503"
"0.0571468881389592","0.584381652832031","2.25","0.00712100973032648"
"0.0588701441301964","0.597601501464844","2.3199999332428","0.00735392177375616"
"0.060639973526122","0.611194946289062","2.39000010490417","0.00759839349484537"
"0.0624563763267361","0.625682067871094","2.46000003814697","0.00774315594753716"
"0.0642727827653289","0.639778442382813","2.52999997138977","0.00795977121015312"
"0.0659960351185873","0.652744323730469","2.59999990463257","0.00817039835965261"
"0.0677192947478034","0.666410522460937","2.67000007629395","0.00838665255287196"
"0.0695822745910846","0.681002563476563","2.74000000953674","0.00860805539559806"
"0.0713521003490314","0.694182678222656","2.80999994277954","0.00882779568200931"
"0.0730753599782474","0.707575073242187","2.88000011444092","0.00901040857570479"
"0.0748917664168403","0.721715270996094","2.95000004768372","0.00930406895349734"
"0.0767081655794755","0.73522216796875","3.01999998092651","0.00952464506553952"
"0.0784314252086915","0.748321166992188","3.08999991416931","0.00969097163761035"
"0.0801546775619499","0.761322692871094","3.16000008583069","0.00987891507975291"
"0.0820176574052311","0.775971374511719","3.23000001907349","0.0101671930679004"
"0.0837874904391356","0.789702392578125","3.29999995231628","0.0103805296021164"
"0.085510742792394","0.802523132324219","3.36999988555908","0.0105833978523151"
"0.0872805758262984","0.816459716796875","3.44000005722046","0.010726799700933"
"0.0891435556695797","0.830608642578125","3.50999999046326","0.0109416541818064"
"0.0908668080228381","0.843763000488281","3.57999992370605","0.0112052057374967"
"0.0926366410567425","0.857899536132813","3.65000009536743","0.0113710166260717"
"0.0944530474953353","0.873120300292969","3.72000002861023","0.0116113615149516"
"0.0962694466579705","0.887512817382813","3.78999996185303","0.0118655361802666"
"0.0979927062871866","0.900963134765625","3.85999989509583","0.0121093980851583"
"0.0997625320451334","0.9154970703125","3.9300000667572","0.0122529118016246"
"0.101578938483726","0.930310607910156","4","0.01249725028174"
"0.103348771517631","0.94407421875","4.07000017166138","0.0127255643747048"
"0.105072023870889","0.9577578125","4.1399998664856","0.0130016405819333"
"0.106888430309482","0.971885070800781","4.21000003814697","0.0131293209051364"
"0.108704836748075","0.986978881835938","4.28000020980835","0.0132784543893649"
"0.110428089101333","1.00022137451172","4.34999990463257","0.0136167518576258"
"0.112151348730549","1.01414086914063","4.42000007629395","0.0138486439027474"
"0.11401432857383","1.02890197753906","4.48999977111816","0.0140589363581967"
"0.115737580927089","1.04249133300781","4.55999994277954","0.0142144090204965"
"0.117460840556305","1.05653698730469","4.63000011444092","0.0144231198646594"
"0.119323820399586","1.07098034667969","4.69999980926514","0.0147212276715436"
"0.121140219562221","1.08637951660156","4.76999998092651","0.014899787856848"
"0.122863479191437","1.0995654296875","4.84000015258789","0.015081508536241"
"0.124633312225342","1.11363391113281","4.90999984741211","0.0153094770212192"
"0.126496292068623","1.12856091308594","4.98000001907349","0.0154796725837514"
"0.128266110550612","1.14308349609375","5.05000019073486","0.0157603444677079"
"0.129989377455786","1.15619909667969","5.11999988555908","0.0158977163664531"
"0.13175921048969","1.17070397949219","5.19000005722046","0.0160802210302791"
"0.133622175781056","1.18508081054688","5.26000022888184","0.0163297736435197"
"0.13534544268623","1.19926916503906","5.32999992370605","0.0165863239089958"
"0.137068695039488","1.21321020507813","5.40000009536743","0.0167190046340693"
"0.138885094202124","1.22816943359375","5.46999979019165","0.017007791029755"
"0.140701507916674","1.24251428222656","5.53999996185303","0.0171709307323908"
"0.142424760269932","1.2560068359375","5.6100001335144","0.0174098404386314"
"0.144194593303837","1.27025671386719","5.67999982833862","0.0177155125129502"
"0.146010992466472","1.28523156738281","5.75","0.0178571299329633"
"0.147780825500377","1.29912585449219","5.82000017166138","0.0180416609509848"
"0.149504077853635","1.31280712890625","5.8899998664856","0.0182614821824245"
"0.151320491568185","1.32780090332031","5.96000003814697","0.0185001335921697"
"0.153136890730821","1.34318151855469","6.03000020980835","0.0187332461791812"
"0.154860143084079","1.35694775390625","6.09999990463257","0.0189030834008008"
"0.156629976117983","1.37056701660156","6.17000007629395","0.0190569426194998"
"0.158492955961265","1.38695495605469","6.23999977111816","0.0192981515283464"
"0.160262788995169","1.40082348632813","6.30999994277954","0.0195550128410105"
"0.161986041348428","1.41416772460938","6.38000011444092","0.0197530243895017"
"0.163755874382332","1.42899096679687","6.44999980926514","0.0199384139705217"
"0.165618854225613","1.44434985351562","6.51999998092651","0.0201967541215708"
"0.167342106578872","1.45842077636719","6.59000015258789","0.0203376803256106"
"0.16906535893213","1.47212036132813","6.65999984741211","0.0205058040592121"
"0.170928338775411","1.48726599121094","6.73000001907349","0.020685180061264"
"0.172698171809316","1.50163122558594","6.80000019073486","0.0209188801818527"
"0.174421424162574","1.51476281738281","6.86999988555908","0.0211431852221722"
"0.176191257196479","1.529330078125","6.94000005722046","0.0214075207622955"
"0.178007656359114","1.54450207519531","7.01000022888184","0.0214901938306866"
"0.179730923264287","1.55797302246094","7.07999992370605","0.0217702709051082"
"0.181500741746277","1.57175866699219","7.15000009536743","0.0220142428588588"
"0.183317155460827","1.58748937988281","7.21999979019165","0.0221988830162445"
"0.185133554623462","1.60193566894531","7.28999996185303","0.0223938313865801"
"0.186856806976721","1.61512829589844","7.3600001335144","0.022612075554207"
"0.188673220691271","1.6295830078125","7.42999982833862","0.0228208064072533"
"0.190489619853906","1.64477770996094","7.5","0.0230301520787179"
"0.192212872207165","1.65806286621094","7.57000017166138","0.023209835489979"
"0.193936139112338","1.67147424316406","7.6399998664856","0.0233928440138698"
"0.195752538274974","1.6858642578125","7.71000003814697","0.0236145442613633"
"0.197568937437609","1.70059118652344","7.78000020980835","0.0238706361415097"
"0.199338770471513","1.71379675292969","7.84999990463257","0.0240474855672801"
"0.201108603505418","1.7274951171875","7.92000007629395","0.0242490350501612"
"0.202925002668053","1.74224951171875","7.98999977111816","0.024466062313877"
"0.204694835701957","1.755923828125","8.0600004196167","0.0246049621637212"
"0.206418088055216","1.76856787109375","8.13000011444092","0.0248623000516091"
"0.208234501769766","1.78316088867188","8.19999980926514","0.0250810408033431"
"0.210004334803671","1.79713171386719","8.27000045776367","0.0252175468631322"
"0.211727587156929","1.81031506347656","8.34000015258789","0.0254550632234896"
"0.213497420190834","1.82379382324219","8.40999984741211","0.0256754810834536"
"0.215360400034115","1.83886096191406","8.47999954223633","0.0258034688158659"
"0.217130218516104","1.85210913085938","8.55000019073486","0.0260006836469984"
"0.218900051550008","1.86531762695313","8.61999988555908","0.0261784152826294"
"0.220669884583913","1.87913354492188","8.6899995803833","0.0264097998297075"
"0.222486283746548","1.89401232910156","8.76000022888184","0.0265867201960646"
"0.224256116780452","1.9067275390625","8.82999992370605","0.0268379699264187"
"0.225979369133711","1.91970776367188","8.89999961853027","0.0270208856818499"
"0.227795782848261","1.93420532226563","8.97000026702881","0.02716784911172"
"0.229612182010897","1.94780676269531","9.03999996185303","0.0273726309387712"
"0.231335434364155","1.96055920410156","9.10999965667725","0.0275958027486922"
"0.233105267398059","1.97382702636719","9.18000030517578","0.0277778308372945"
"0.23492168111261","1.98878662109375","9.25","0.0279947653325507"
"0.236691499594599","2.00188525390625","9.31999969482422","0.028122960429755"
"0.238414766499773","2.01445690917969","9.39000034332275","0.0283757271972718"
"0.240231165662408","2.02837390136719","9.46000003814697","0.0284945544990478"
"0.242047564825043","2.04228344726562","9.52999973297119","0.028678921808023"
"0.243770831730217","2.0553515625","9.60000038146973","0.0288977771560894"
"0.245540664764121","2.06871850585937","9.67000007629395","0.0291061733150855"
"0.247357063926756","2.08315283203125","9.73999977111816","0.0293159882858163"
"0.249126896960661","2.09630615234375","9.8100004196167","0.0294975034194067"
"0.250850134762004","2.10962475585938","9.88000011444092","0.029699378501391"
"0.25266656302847","2.12374487304688","9.94999980926514","0.0298544218821917"
"0.254529528319836","2.13826684570313","10.0200004577637","0.0301020518236328"
"0.256252795225009","2.15072290039063","10.0900001525879","0.030247005270212"
"0.257976033026353","2.16338891601562","10.1599998474121","0.0304563727695495"
"0.259792461292818","2.17778002929687","10.2299995422363","0.0306239562632982"
"0.261608860455453","2.191123046875","10.3000001907349","0.0307648733723909"
"0.263332098256797","2.204294921875","10.3699998855591","0.0309378738165833"
"0.265101931290701","2.217951171875","10.4399995803833","0.031173913157545"
"0.266918330453336","2.23246630859375","10.5100002288818","0.0313530363200698"
"0.268688163487241","2.24466137695312","10.5799999237061","0.0315236575261224"
"0.270411430392414","2.25714111328125","10.6499996185303","0.0317059275403153"
"0.27222782955505","2.2707783203125","10.7200002670288","0.0318925231113099"
"0.274044228717685","2.28384033203125","10.789999961853","0.0320529215969145"
"0.275767495622858","2.29656127929688","10.8599996566772","0.0322639280057047"
"0.277537328656763","2.30999169921875","10.9300003051758","0.0324243919749279"
"0.279353727819398","2.32431274414063","11","0.0326365079672541"
"0.281123560853302","2.3370693359375","11.0699996948242","0.0328413443639874"
"0.282893393887207","2.34882275390625","11.1400003433228","0.0329592694470193"
"0.284709793049842","2.3630888671875","11.210000038147","0.0331563569488935"
"0.286526192212477","2.37601928710938","11.2799997329712","0.0333825337293092"
"0.288249459117651","2.38794482421875","11.3500003814697","0.0335491313308012"
"0.289972696918994","2.40033422851563","11.4200000762939","0.0337274650519248"
"0.291835691314191","2.41490942382813","11.4899997711182","0.0338960489898454"
"0.293605524348095","2.42800830078125","11.5600004196167","0.0340802434948273"
"0.295328762149438","2.4398916015625","11.6300001144409","0.0342941675626207"
"0.297098595183343","2.45295751953125","11.6999998092651","0.034460324968677"
"0.298961589578539","2.466923828125","11.7700004577637","0.0346560336765833"
"0.300684827379882","2.47798828125","11.8400001525879","0.0347697023244109"
"0.302408094285056","2.49007299804687","11.9099998474121","0.0349803667631932"
"0.304224493447691","2.50351489257813","11.9799995422363","0.0351765884261113"
"0.306040892610326","2.51651928710938","12.0500001907349","0.0353047216776758"
"0.307717593386769","2.52779248046875","12.1199998855591","0.0355167358065955"
"0.309533992549405","2.5406669921875","12.1899995803833","0.0356187592842616"
"0.31139695784077","2.55459448242188","12.2600002288818","0.0358226752723567"
"0.313120224745944","2.56624145507813","12.3299999237061","0.0360231279046275"
"0.314890057779849","2.57735595703125","12.3999996185303","0.0361979946319479"
"0.316706456942484","2.5906513671875","12.4700002670288","0.0363471226592083"
"0.318522856105119","2.60344921875","12.539999961853","0.0365697233064566"
"0.320246123010293","2.61470776367188","12.6099996566772","0.0366935491911136"
"0.321969389915466","2.62678198242188","12.6800003051758","0.0369453991879709"
"0.323832355206832","2.64048413085938","12.75","0.0370930829376448"
"0.325602188240737","2.65210595703125","12.8199996948242","0.0372003378288355"
"0.32732545514591","2.66373046875","12.8900003433228","0.0373171496903524"
"0.329141854308546","2.67668676757813","12.960000038147","0.0375297640857752"
"0.330958253471181","2.68908520507813","13.0299997329712","0.037740588595625"
"0.332681520376354","2.7007373046875","13.1000003814697","0.0378642944269814"
"0.334404758177698","2.71215063476563","13.1700000762939","0.0380110686819535"
"0.336267752572894","2.72562060546875","13.2399997711182","0.0382532198273111"
"0.337990990374237","2.73721533203125","13.3100004196167","0.0383953884011135"
"0.339760823408142","2.74850952148438","13.3800001144409","0.0385015155188739"
"0.341530656442046","2.76053100585938","13.4499998092651","0.038765309000155"
"0.343393650837243","2.77384521484375","13.5200004577637","0.0388976732210722"
"0.345116888638586","2.78462231445313","13.5900001525879","0.0390240311389789"
"0.34688672167249","2.79630712890625","13.6599998474121","0.0392069450754207"
"0.348703120835125","2.80869970703125","13.7299995422363","0.0393184564018156"
"0.350519549101591","2.82093505859375","13.8000001907349","0.0395874412788544"
"0.352242786902934","2.83160961914063","13.8699998855591","0.0396931864088401"
"0.354012619936839","2.84334399414062","13.9399995803833","0.0397699732275214"
"0.355829019099474","2.8558916015625","14.0100002288818","0.0400160606659483"
"0.357598852133378","2.867291015625","14.0799999237061","0.0401968536607455"
"0.359322119038552","2.878025390625","14.1499996185303","0.040363895095652"
"0.361138518201187","2.89073193359375","14.2200002670288","0.0404632555728313"
"0.362954917363822","2.90265112304688","14.289999961853","0.0406351136916783"
"0.364678184268996","2.91339599609375","14.3599996566772","0.0407905354222748"
"0.366448017302901","2.92467065429688","14.4300003051758","0.0409837157349102"
"0.368264416465536","2.93716430664063","14.5","0.0411035580327734"
"0.37003424949944","2.94806591796875","14.5699996948242","0.0412905901612248"
"0.371757487300783","2.9585615234375","14.6400003433228","0.0414296628150623"
"0.373573915567249","2.96987036132812","14.710000038147","0.0415984795836266"
"0.375390314729884","2.98253173828125","14.7799997329712","0.0417537812609226"
"0.377113552531227","2.99289770507812","14.8500003814697","0.0419783100369386"
"0.378883385565132","3.003798828125","14.9200000762939","0.0421117038058583"
"0.380746379960328","3.0160576171875","14.9899997711182","0.042245868826285"
"0.382516212994233","3.0267705078125","15.0600004196167","0.0424475583713502"
"0.384239450795576","3.03706884765625","15.1300001144409","0.0425070902565494"
"0.38600928382948","3.04829736328125","15.1999998092651","0.0427450613642577"
"0.387825682992116","3.05994262695312","15.2700004577637","0.0428472740168218"
"0.38959551602602","3.07038745117188","15.3400001525879","0.043042531615356"
"0.391318782931194","3.0813203125","15.4099998474121","0.043137351894984"
"0.39318174822256","3.09372680664063","15.4799995422363","0.0433333843830042"
"0.394951581256464","3.10432836914062","15.5500001907349","0.0435407309851144"
"0.396674848161638","3.11460205078125","15.6199998855591","0.0436867667303886"
"0.398444681195542","3.12516186523438","15.6899995803833","0.0437869275629055"
"0.400261080358177","3.13671557617188","15.7600002288818","0.0439980540249962"
"0.402030913392082","3.14674243164063","15.8299999237061","0.0440979565610178"
"0.403754151193425","3.15699951171875","15.8999996185303","0.0442487908003386"
"0.405570579459891","3.16906762695313","15.9700002670288","0.0444662327936385"
"0.407386978622526","3.18059936523438","16.0400009155273","0.0445526238763705"
"0.409110216423869","3.19037353515625","16.1100006103516","0.0447060410806444"
"0.410926644690335","3.20061352539062","16.1800003051758","0.0448623977717943"
"0.41274304385297","3.212228515625","16.25","0.0450628031103406"
"0.414512876886874","3.22232690429687","16.3199996948242","0.0452122148999479"
"0.416236114688218","3.23185107421875","16.3899993896484","0.0453021784778684"
"0.418005947722122","3.24281982421875","16.4599990844727","0.0454389628430363"
"0.419868942117319","3.25417041015625","16.5300006866455","0.0456265443062875"
"0.421592179918662","3.26366162109375","16.6000003814697","0.0457365858892445"
"0.423315446823835","3.27392626953125","16.6700000762939","0.0458889080618974"
"0.425178412115201","3.28483666992188","16.7399997711182","0.0460638766526245"
"0.426948245149106","3.29580004882812","16.8099994659424","0.0462632560811471"
"0.428671512054279","3.30554321289063","16.8799991607666","0.0463413234683685"
"0.430441345088184","3.31572998046875","16.9500007629395","0.0465660341433249"
"0.432257744250819","3.32752319335937","17.0200004577637","0.046654102334287"
"0.434027577284724","3.33736865234375","17.0900001525879","0.046909786760807"
"0.435750844189897","3.34786694335938","17.1599998474121","0.0470403610961512"
"0.437613809481263","3.35923706054687","17.2299995422363","0.0471615530841518"
"0.439383642515168","3.37012329101562","17.2999992370605","0.047310211812146"
"0.441153475549072","3.37984741210937","17.3700008392334","0.0474409134767484"
"0.442923308582976","3.38981909179688","17.4400005340576","0.0476113491458818"
"0.444739707745612","3.40112231445312","17.5100002288818","0.0477773173770402"
"0.446509540779516","3.4111767578125","17.5799999237061","0.0479001428175252"
"0.44823280768469","3.42076684570313","17.6499996185303","0.0479727059428114"
"0.450049206847325","3.43152172851563","17.7199993133545","0.0481282477267087"
"0.45186560600996","3.44248168945313","17.7900009155273","0.0483499752590433"
"0.453588872915134","3.45188452148437","17.8600006103516","0.0484562078781892"
"0.455358676845208","3.4623955078125","17.9300003051758","0.0486164753965568"
"0.457175105111673","3.47325561523437","18","0.0487255165353417"
"0.458944909041747","3.48302587890625","18.0699996948242","0.04892182914773"
"0.460668175946921","3.4925771484375","18.1399993896484","0.0490734928462189"
"0.462438008980826","3.50322485351563","18.2099990844727","0.0491495557071175"
"0.464254408143461","3.5141328125","18.2800006866455","0.04933609670843"
"0.466024241177365","3.52408227539062","18.3500003814697","0.0495310050609987"
"0.46779407421127","3.53343530273438","18.4200000762939","0.0496604698128067"
"0.469610473373905","3.5447841796875","18.4899997711182","0.0497673936479259"
"0.471380306407809","3.55548828125","18.5599994659424","0.0499495909025427"
"0.473103573312983","3.56457373046875","18.6299991607666","0.0500237838423345"
"0.474919972475618","3.57551879882813","18.7000007629395","0.0502737675560638"
"0.476736371638253","3.58642211914063","18.7700004577637","0.0503112241858616"
"0.478506204672158","3.5958798828125","18.8400001525879","0.0504859672219027"
"0.480229471577331","3.60481372070313","18.9099998474121","0.0506177493662108"
"0.482045870739967","3.615490234375","18.9799995422363","0.0507660552102607"
"0.483862269902602","3.62597192382812","19.0499992370605","0.0509506098751444"
"0.485585536807775","3.634861328125","19.1200008392334","0.0510256686538924"
"0.48735536984168","3.64504809570313","19.1900005340576","0.0512315527885221"
"0.489171769004315","3.65589111328125","19.2600002288818","0.0513937447976787"
"0.490941572934389","3.66568579101562","19.3299999237061","0.051609273214126"
"0.492664868943393","3.67472094726563","19.3999996185303","0.0516618092660792"
"0.494481239002198","3.68561401367187","19.4699993133545","0.0518326778546907"
"0.496297667268664","3.6957900390625","19.5400009155273","0.0519483073730953"
"0.498020905070007","3.704458984375","19.6100006103516","0.0520911817147862"
"0.499790767207742","3.71464965820312","19.6800003051758","0.052266324928496"
"0.501607137266546","3.72502270507813","19.75","0.0523867056472227"
"0.503376999404281","3.73494702148438","19.8199996948242","0.0525305040355306"
"0.505100237205625","3.74485473632813","19.8899993896484","0.0526829171576537"
"0.50691666547209","3.75504858398438","19.9599990844727","0.0527717420482077"
"0.508779601659626","3.76580688476563","20.0300006866455","0.0529874014318921"
"0.51050289766863","3.77509594726562","20.1000003814697","0.0530893958057277"
"0.512226135469973","3.783998046875","20.1700000762939","0.0532182384631597"
"0.514042505528778","3.79440625","20.2399997711182","0.0533935453859158"
"0.515858933795244","3.80441186523438","20.3099994659424","0.053518913773587"
"0.517582171596587","3.81393286132813","20.3799991607666","0.053651980124414"
"0.519352033734322","3.82424560546875","20.4500007629395","0.0538288077223115"
"0.521215028129518","3.83478173828125","20.5200004577637","0.054040447139414"
"0.522938265930861","3.8440859375","20.5900001525879","0.0541401168447919"
"0.524708069860935","3.85303198242188","20.6599998474121","0.0542456837138161"
"0.52647793199867","3.86342431640625","20.7299995422363","0.0544853246537969"
"0.528294302057475","3.87313720703125","20.7999992370605","0.0545792099728715"
"0.530017598066479","3.88215112304688","20.8700008392334","0.0546950905118138"
"0.531787401996553","3.89178686523438","20.9400005340576","0.054843898396939"
"0.533603830263019","3.90305346679688","21.0100002288818","0.0549382893950678"
"0.535373634193093","3.9122265625","21.0799999237061","0.0551415359950624"
"0.537143496330827","3.92114721679688","21.1499996185303","0.055281154345721"
"0.538959866389632","3.93150268554687","21.2199993133545","0.055457217968069"
"0.540776294656098","3.94153125","21.2900009155273","0.055582157074241"
"0.542499532457441","3.95054248046875","21.3600006103516","0.0556592567590997"
"0.544222770258784","3.95968725585938","21.4300003051758","0.055843291193014"
"0.546085764653981","3.9706513671875","21.5","0.0559704567422159"
"0.547855626791716","3.98044970703125","21.5699996948242","0.0560855696676299"
"0.549578864593059","3.98939672851562","21.6399993896484","0.0562943096156232"
"0.551395292859524","3.99867626953125","21.7099990844727","0.0564125075470656"
"0.553211662918329","4.00900073242188","21.7800006866455","0.0565413574804552"
"0.554934900719672","4.01763037109375","21.8500003814697","0.056715085520409"
"0.556658196728677","4.02637670898438","21.9200000762939","0.0567997958569322"
"0.558474566787481","4.03620092773437","21.9899997711182","0.0569757794437464"
"0.560290995053947","4.04680786132812","22.0599994659424","0.0571496348129585"
"0.56201423285529","4.055697265625","22.1299991607666","0.0572879798710346"
"0.563784094993025","4.06551171875","22.2000007629395","0.0573499382880982"
"0.56560046505183","4.07570263671875","22.2700004577637","0.0575812082388438"
"0.567370327189565","4.08467309570312","22.3400001525879","0.0577028476982377"
"0.569140131119639","4.09356909179688","22.4099998474121","0.0578681865590625"
"0.570956559386104","4.10401953125","22.4799995422363","0.0579785410081968"
"0.572772929444909","4.11403076171875","22.5499992370605","0.0581123822485097"
"0.574496225453913","4.1231865234375","22.6200008392334","0.0582623761147261"
"0.576219463255256","4.13253564453125","22.6900005340576","0.0584813969908282"
"0.578035891521722","4.143072265625","22.7600002288818","0.0586152418691199"
"0.579852261580527","4.1535009765625","22.8299999237061","0.0586980895604938"
"0.581575557589531","4.16266357421875","22.8999996185303","0.0588632428843994"
"0.583391927648336","4.173078125","22.9699993133545","0.0589812407270074"
"0.585208355914801","4.18310302734375","23.0400009155273","0.0591703465033788"
"0.586931593716145","4.19278955078125","23.1100006103516","0.0593183613091242"
"0.588654831517488","4.2022890625","23.1800003051758","0.0594293524045497"
"0.590517825912684","4.21341357421875","23.25","0.0596136269450653"
"0.592287688050419","4.223119140625","23.3199996948242","0.0597873186052311"
"0.594010925851762","4.2326806640625","23.3899993896484","0.0599357226747088"
"0.595827295910567","4.2423642578125","23.4599990844727","0.060014925111318"
"0.597643724177033","4.253548828125","23.5300006866455","0.0601771898800507"
"0.599366961978376","4.26318896484375","23.6000003814697","0.0603217376919929"
"0.601136824116111","4.27311328125","23.6700000762939","0.0604633351031225"
"0.602999818511307","4.284640625","23.7399997711182","0.0606302965024952"
"0.604769622441381","4.2957333984375","23.8099994659424","0.0607451183896046"
"0.606492860242724","4.3049853515625","23.8799991607666","0.0609801318205427"
"0.608262722380459","4.3148916015625","23.9500007629395","0.0610950810369104"
"0.610079092439264","4.32608642578125","24.0200004577637","0.0612823059782386"
"0.611848954576999","4.3363388671875","24.0900001525879","0.0614330856478773"
"0.613572192378342","4.3458974609375","24.1599998474121","0.0615428580204025"
"0.615388620644808","4.35740283203125","24.2299995422363","0.0617185942246579"
"0.617204990703613","4.3680390625","24.2999992370605","0.0619030543020926"
"0.618928286712617","4.3776904296875","24.3700008392334","0.0620063001406379"
"0.620698090642691","4.38780322265625","24.4400005340576","0.0621148356003687"
"0.622514518909156","4.39927294921875","24.5100002288818","0.0622833176748827"
"0.62428432283923","4.4090966796875","24.5799999237061","0.0623779851594009"
"0.626007560640574","4.41929443359375","24.6499996185303","0.0626055771135725"
"0.627823988907039","4.42933642578125","24.7199993133545","0.0627064946456812"
"0.629640417173505","4.44083056640625","24.7900009155273","0.0628437919658609"
"0.631363654974848","4.45082763671875","24.8600006103516","0.0629342321190052"
"0.633180025033653","4.461103515625","24.9300003051758","0.0632015071460046"
"0.634996453300118","4.47274560546875","25","0.0633382660453208"
"0.636766315437853","4.48377099609375","25.0699996948242","0.0634726093267091"
"0.638489553239197","4.493486328125","25.1399993896484","0.0635800170130096"
"0.640259357169271","4.5038369140625","25.2099990844727","0.0636831173324026"
"0.642075785435736","4.51516943359375","25.2800006866455","0.0638605779386126"
"0.64384558936581","4.52513037109375","25.3500003814697","0.0639739009784535"
"0.645568885374814","4.535701171875","25.4200000762939","0.0641795559204184"
"0.647385255433619","4.54727197265625","25.4899997711182","0.0643365128780715"
"0.649201683700085","4.55776220703125","25.5599994659424","0.0644409592496231"
"0.650924921501428","4.56782177734375","25.6299991607666","0.0646714470349252"
"0.652694783639163","4.57784033203125","25.7000007629395","0.0648084751446731"
"0.654511153697968","4.58816064453125","25.7700004577637","0.0649170760880224"
"0.656234391499311","4.59854833984375","25.8400001525879","0.0650142392260022"
"0.658004253637046","4.608072265625","25.9099998474121","0.0651622758596204"
"0.659820681903511","4.618884765625","25.9799995422363","0.0653095485176891"
"0.661683618091047","4.63014306640625","26.0499992370605","0.0654315954307094"
"0.663360289763659","4.63981591796875","26.1200008392334","0.0656048650853336"
"0.665176718030125","4.649458984375","26.1900005340576","0.0657454511383548"
"0.666993146296591","4.660919921875","26.2600002288818","0.0658849312458187"
"0.668762950226665","4.66982080078125","26.3299999237061","0.0660134028294124"
"0.670486188028008","4.6799873046875","26.3999996185303","0.0661273516016081"
"0.672256050165743","4.689466796875","26.4699993133545","0.0662932579871267"
"0.674119044560939","4.701564453125","26.5400009155273","0.0664333419990726"
"0.675842282362282","4.71088232421875","26.6100006103516","0.0665091138216667"
"0.677612086292356","4.72071728515625","26.6800003051758","0.0667037311359309"
"0.679428514558822","4.73093994140625","26.75","0.0668997527100146"
"0.681198318488896","4.74180224609375","26.8199996948242","0.0670100998831913"
"0.6829216144979","4.75214404296875","26.8899993896484","0.0671333473292179"
"0.684691418427974","4.761830078125","26.9599990844727","0.0671940215397626"
"0.68655441282317","4.77319482421875","27.0300006866455","0.0673990871291608"
"0.688277650624514","4.784123046875","27.1000003814697","0.0675927440170199"
"0.690000946633518","4.79419580078125","27.1700000762939","0.0677156494930387"
"0.691863882821053","4.804888671875","27.2399997711182","0.0677930438541807"
"0.693680311087519","4.816130859375","27.3099994659424","0.0679242875776254"
"0.695356982760131","4.8255546875","27.3799991607666","0.0681109449942596"
"0.697173411026597","4.83534033203125","27.4500007629395","0.0682724712532945"
"0.698989781085402","4.847568359375","27.5200004577637","0.0683431571815163"
"0.700759643223137","4.856267578125","27.5900001525879","0.0685285122017376"
"0.70248288102448","4.86668701171875","27.6599998474121","0.0686382190906443"
"0.704299309290946","4.8772177734375","27.7299995422363","0.0688338113832287"
"0.70606911322102","4.88751611328125","27.7999992370605","0.0689173029968515"
"0.707838917151093","4.897484375","27.8700008392334","0.0691583918523975"
"0.709608779288828","4.90846435546875","27.9400005340576","0.0692676330800168"
"0.711425149347633","4.918501953125","28.0100002288818","0.0694169575581327"
"0.713195011485368","4.92964208984375","28.0799999237061","0.0695581620675512"
"0.714918249286711","4.9389833984375","28.1499996185303","0.0697020441293716"
"0.716734677553177","4.9496962890625","28.2199993133545","0.0697828800184652"
"0.718504481483251","4.96101318359375","28.2900009155273","0.0699391966918483"
"0.720227777492255","4.9710078125","28.3600006103516","0.0701252502040006"
"0.721997581422329","4.980509765625","28.4300003051758","0.0701742246747017"
"0.723860575817525","4.99279150390625","28.5","0.070354035415221"
"0.725630379747599","5.00281591796875","28.5699996948242","0.0705617640051059"
"0.727353675756603","5.01271728515625","28.6399993896484","0.0706446662661619"
"0.729170045815408","5.02369189453125","28.7099990844727","0.070732094172854"
"0.731033040210605","5.03552734375","28.7800006866455","0.0709633968654089"
"0.732756278011948","5.045193359375","28.8500003814697","0.0710889216861688"
"0.734526140149683","5.0553486328125","28.9200000762939","0.0712395121809095"
"0.736295944079757","5.06586279296875","28.9899997711182","0.0713753688614815"
"0.738112372346222","5.07677001953125","29.0599994659424","0.0716040231054649"
"0.739835610147566","5.08677099609375","29.1299991607666","0.0715768110239878"
"0.74160541407764","5.0970810546875","29.2000007629395","0.0718229275662452"
"0.743421842344105","5.10803076171875","29.2700004577637","0.0719784802640788"
"0.74519170448184","5.11835009765625","29.3400001525879","0.0721163742127828"
"0.746914942283183","5.12811279296875","29.4099998474121","0.072298054874409"
"0.748731312341988","5.13880419921875","29.4799995422363","0.0724073470337316"
"0.750547740608454","5.15016650390625","29.5499992370605","0.0725355857866816"
"0.752270978409797","5.159763671875","29.6200008392334","0.0726569560356438"
"0.753994274418801","5.1690224609375","29.6900005340576","0.072837108746171"
"0.755857210606337","5.18134033203125","29.7600002288818","0.0729554667486809"
"0.757627072744071","5.19276416015625","29.8299999237061","0.0730970496078953"
"0.759396876674145","5.20270458984375","29.8999996185303","0.0732679545762949"
"0.761213304940611","5.21383544921875","29.9699993133545","0.0734461427782662"
"0.763029674999416","5.22551220703125","30.0400009155273","0.0736367001081817"
"0.76475297100842","5.23523681640625","30.1100006103516","0.0737269147066399"
"0.766476208809763","5.24422216796875","30.1800003051758","0.0738073140382767"
"0.768292637076229","5.25573681640625","30.25","0.0739745300961658"
"0.770109007135034","5.26688232421875","30.3199996948242","0.0741171897971071"
"0.771832303144038","5.27637939453125","30.3899993896484","0.0742548363632523"
"0.773602107074112","5.28730810546875","30.4599990844727","0.0744294302421622"
"0.775465101469308","5.29893408203125","30.5300006866455","0.0745644574635662"
"0.777188339270651","5.30786572265625","30.6000003814697","0.0747120648156852"
"0.778958201408386","5.31764208984375","30.6700000762939","0.0748188176658005"
"0.780774571467191","5.3290703125","30.7399997711182","0.0749608734622598"
"0.782497809268534","5.339349609375","30.8099994659424","0.0751098486944102"
"0.784267671406269","5.34914013671875","30.8799991607666","0.0751997577026486"
"0.786037475336343","5.3597314453125","30.9500007629395","0.0753666536184028"
"0.787853903602809","5.37149365234375","31.0200004577637","0.0755444416427054"
"0.789670331869274","5.38188916015625","31.0900001525879","0.0756389126763679"
"0.791393569670618","5.391943359375","31.1599998474121","0.0758236637921073"
"0.793209939729422","5.40317041015625","31.2299995422363","0.0759560571168549"
"0.794979801867157","5.41441796875","31.2999992370605","0.0761602495913394"
"0.7967030396685","5.42443798828125","31.3700008392334","0.0763150455895811"
"0.798472901806235","5.434365234375","31.4400005340576","0.0764096112106927"
"0.80028927186504","5.44621875","31.5100002288818","0.0765569129725918"
"0.802152266260237","5.4578095703125","31.5799999237061","0.0768013196648099"
"0.803828937932849","5.46669091796875","31.6499996185303","0.0769183825468644"
"0.805645366199315","5.47794580078125","31.7199993133545","0.0770431724959053"
"0.807461736258119","5.489845703125","31.7900009155273","0.0772090570535511"
"0.809185032267123","5.4998388671875","31.8600006103516","0.0772775820223615"
"0.810908270068467","5.509357421875","31.9300003051758","0.0774014479247853"
"0.812771264463663","5.52114794921875","32","0.0776316664996557"
"0.814541068393737","5.53171923828125","32.0699996948242","0.077748263720423"
"0.81626430619508","5.54136328125","32.1399993896484","0.0779627007432282"
"0.818080734461546","5.55237548828125","32.2099990844727","0.0780340415076353"
"0.819897162728012","5.5641884765625","32.2799987792969","0.0782356510171667"
"0.821666966658086","5.5743662109375","32.3499984741211","0.0784352087066509"
"0.823390204459429","5.58425244140625","32.4199981689453","0.0784524527261965"
"0.825206632725894","5.59553515625","32.4900016784668","0.0786184318712912"
"0.82702306099236","5.6076806640625","32.560001373291","0.0788883771747351"
"0.828746298793703","5.61682470703125","32.6300010681152","0.0789877667557448"
"0.830516102723777","5.627279296875","32.7000007629395","0.0790941994637251"
"0.832379097118974","5.6398701171875","32.7700004577637","0.0792893479228951"
"0.834102334920317","5.6498681640625","32.8400001525879","0.0793974832049571"
"0.835825630929321","5.65994580078125","32.9099998474121","0.0795510350144468"
"0.837642000988126","5.6711240234375","32.9799995422363","0.0796831664047204"
"0.839411863125861","5.68301171875","33.0499992370605","0.0798470209701918"
"0.841181667055935","5.692970703125","33.1199989318848","0.0799436966190115"
"0.842904963064939","5.7028759765625","33.189998626709","0.0801582064013928"
"0.844767899252474","5.71476025390625","33.2599983215332","0.0802789072622545"
"0.846537761390209","5.72555615234375","33.3300018310547","0.0803961738711223"
"0.848260999191552","5.73523193359375","33.4000015258789","0.080530131526757"
"0.850077427458018","5.7469208984375","33.4700012207031","0.080694691860117"
"0.851893797516823","5.75805517578125","33.5400009155273","0.0808939657872543"
"0.853617093525827","5.7681669921875","33.6100006103516","0.0809987541288137"
"0.855386897455901","5.7778515625","33.6800003051758","0.0811440913821571"
"0.857249891851097","5.79007763671875","33.75","0.0813006263342686"
"0.859066261909902","5.8007265625","33.8199996948242","0.0814893282949924"
"0.860742933582515","5.81084814453125","33.8899993896484","0.0816220272099599"
"0.862512795720249","5.82126806640625","33.9599990844727","0.0817472027847543"
"0.864375790115446","5.8336962890625","34.0299987792969","0.0819934211904183"
"0.866099027916789","5.8432138671875","34.0999984741211","0.0820896457298659"
"0.867822265718132","5.8538759765625","34.1699981689453","0.0821972571429797"
"0.869638693984598","5.86516064453125","34.2400016784668","0.0824354938231409"
"0.871455064043403","5.8767275390625","34.310001373291","0.0825463357614353"
"0.873178360052407","5.88686083984375","34.3800010681152","0.0827259500510991"
"0.874948163982481","5.8972587890625","34.4500007629395","0.082872917118948"
"0.876764592248946","5.909216796875","34.5200004577637","0.0829650016385131"
"0.878580962307751","5.92052587890625","34.5900001525879","0.0831752331578173"
"0.880257692188025","5.92927685546875","34.6599998474121","0.0832744335639291"
"0.882074062246829","5.94013720703125","34.7299995422363","0.0833744561532512"
"0.883890490513295","5.9514326171875","34.7999992370605","0.0835263053886592"
"0.885613728314638","5.9619052734375","34.8699989318848","0.0836566905491054"
"0.887383590452373","5.97218701171875","34.939998626709","0.0838785636005923"
"0.889246526639909","5.98464501953125","35.0099983215332","0.0839869389892556"
"0.891016388777643","5.994529296875","35.0800018310547","0.0841655855765566"
"0.892786192707717","6.0043798828125","35.1500015258789","0.0842360896058381"
"0.894509430509061","6.01439208984375","35.2200012207031","0.0844470268930309"
"0.896325858775526","6.02651318359375","35.2900009155273","0.0845672038849443"
"0.898095720913261","6.0369365234375","35.3600006103516","0.0847449191496707"
"0.899865524843335","6.0474931640625","35.4300003051758","0.0849640564410947"
"0.901681953109801","6.05974169921875","35.5","0.0850659198476933"
"0.903451757039875","6.07069970703125","35.5699996948242","0.0852289522299543"
"0.905221560969949","6.08077294921875","35.6399993896484","0.0854391619213857"
"0.906944856978953","6.09146240234375","35.7099990844727","0.0855011458043009"
"0.908761227037758","6.10305126953125","35.7799987792969","0.0856648402987048"
"0.910531089175493","6.1132861328125","35.8499984741211","0.0858319326653145"
"0.912254326976836","6.1240546875","35.9199981689453","0.0859704887261614"
"0.914070755243301","6.13591748046875","35.9900016784668","0.0861561493366025"
"0.915887125302106","6.147439453125","36.060001373291","0.0863419336383231"
"0.917656987439841","6.1572978515625","36.1300010681152","0.0864131507114507"
"0.919380225241184","6.16712109375","36.2000007629395","0.0865714464453049"
"0.921289785765111","6.1799697265625","36.2700004577637","0.0867334674694575"
"0.922966457437724","6.1899423828125","36.3400001525879","0.0868578281369992"
"0.924736319575459","6.199265625","36.4099998474121","0.0870248841238208"
"0.926552689634264","6.21126953125","36.4799995422363","0.0871042720973492"
"0.928369117900729","6.222810546875","36.5499992370605","0.0872918317327276"
"0.930092355702072","6.2328544921875","36.6199989318848","0.0874405959621072"
"0.931862217839807","6.24362646484375","36.689998626709","0.0876671620062552"
"0.933678587898612","6.25508154296875","36.7599983215332","0.0877633792697452"
"0.935448450036347","6.2664326171875","36.8300018310547","0.0879175349837169"
"0.93717168783769","6.276201171875","36.9000015258789","0.0880537700140849"
"0.938941491767764","6.28768701171875","36.9700012207031","0.0882960666785948"
"0.94075792003423","6.2986728515625","37.0400009155273","0.0883882967173122"
"0.942527723964304","6.30993505859375","37.1100006103516","0.0885339177330025"
"0.944251019973308","6.32059765625","37.1800003051758","0.0886999623617157"
"0.946113956160843","6.3328623046875","37.25","0.0888771610334516"
"0.947930384427309","6.34361376953125","37.3199996948242","0.0889853836270049"
"0.949653622228652","6.35360595703125","37.3899993896484","0.0891819508979097"
"0.951423484366387","6.36439599609375","37.4599990844727","0.0893691321834922"
"0.953239854425192","6.3760390625","37.5299987792969","0.0894892145879567"
"0.955009716562927","6.38724267578125","37.5999984741211","0.0896277706488036"
"0.95673295436427","6.39649609375","37.6699981689453","0.0897812860785052"
"0.958549382630736","6.40810009765625","37.7400016784668","0.0899665028555319"
"0.96031918656081","6.4198603515625","37.810001373291","0.0901309322216548"
"0.962089048698545","6.43045947265625","37.8800010681152","0.0902678075362928"
"0.963858852628618","6.4415517578125","37.9500007629395","0.0903832624317147"
"0.965675280895084","6.45287646484375","38.0200004577637","0.090561450633686"
"0.967445084825158","6.46378857421875","38.0900001525879","0.0907563517102972"
"0.969168322626501","6.473369140625","38.1599998474121","0.0908924776013009"
"0.970938184764236","6.48569873046875","38.2299995422363","0.091038629761897"
"0.972801179159433","6.49774267578125","38.2999992370605","0.0913063049665652"
"0.974524416960776","6.50753076171875","38.3699989318848","0.0913457188289613"
"0.976247654762119","6.51847900390625","38.439998626709","0.0915013879421167"
"0.978110707364976","6.53043017578125","38.5099983215332","0.0916100616450422"
"0.979880453087389","6.54219970703125","38.5800018310547","0.0919034719117917"
"0.981650315225124","6.55273974609375","38.6500015258789","0.0919525846256875"
"0.983420177362859","6.56339404296875","38.7200012207031","0.0921121027204208"
"0.985283171758056","6.57578662109375","38.7900009155273","0.0923461993806995"
"0.987006351351738","6.585662109375","38.8600006103516","0.0924354317248799"
"0.988729647360742","6.59634814453125","38.9300003051758","0.0926270222407766"
"0.990592641755939","6.6076943359375","39","0.0927757500903681"
"0.992362387478352","6.61931787109375","39.0699996948242","0.0928689332795329"
"0.994085683487356","6.6290126953125","39.1399993896484","0.0930298410821706"
"0.995855545625091","6.63915966796875","39.2099990844727","0.0932119583012536"
"0.997671973891556","6.65106689453125","39.2799987792969","0.0933028786676005"
"0.9994882857427","6.663240234375","39.3499984741211","0.0935011994442903"
"1.0012115817517","6.67293408203125","39.4199981689453","0.0936664946493693"
"1.00302801001817","6.6848408203125","39.4900016784668","0.093803639174439"
"1.0047978721559","6.69537744140625","39.560001373291","0.0940086683840491"
"1.00656761787832","6.70621435546875","39.6300010681152","0.0940017853281461"
"1.00829091388732","6.71708984375","39.7000007629395","0.0942905317060649"
"1.01010734215379","6.7288095703125","39.7700004577637","0.0944924904615618"
"1.01192377042025","6.7405625","39.8400001525879","0.0945966457948089"
"1.01364695001394","6.750955078125","39.9099998474121","0.0947304652072489"
"1.0154633782804","6.7629111328125","39.9799995422363","0.0949473833316006"
"1.01727980654687","6.775029296875","40.0499992370605","0.0950594912865199"
"1.01900298614055","6.7848564453125","40.1199989318848","0.0952262344071642"
"1.02072628214955","6.7941015625","40.189998626709","0.0953281050897203"
"1.02254271041602","6.8065341796875","40.2599983215332","0.0955229406827129"
"1.02435913868248","6.8185673828125","40.3300018310547","0.0957074153120629"
"1.02608231827617","6.82848583984375","40.4000015258789","0.0959086464717984"
"1.02789874654263","6.8396865234375","40.4700012207031","0.0960372926783748"
"1.0297151748091","6.85200830078125","40.5400009155273","0.0962082922342233"
"1.0314384708181","6.86202099609375","40.6100006103516","0.096281808509957"
"1.03316165041178","6.872623046875","40.6800003051758","0.0964449864113703"
"1.03497807867825","6.8834306640625","40.75","0.0966507795965299"
"1.03679450694472","6.89586669921875","40.8199996948242","0.0967792002484202"
"1.03847112040967","6.9055458984375","40.8899993896484","0.0969750180956908"
"1.04028754867613","6.916609375","40.9599990844727","0.0970951005001552"
"1.0421039769426","6.93026220703125","41.0299987792969","0.0972245106822811"
"1.04392040520906","6.941158203125","41.0999984741211","0.0974335052887909"
"1.04564370121807","6.9517734375","41.1699981689453","0.0976163792074658"
"1.04746001306921","6.9636953125","41.2400016784668","0.0977917443378828"
"1.04927644133568","6.97536572265625","41.310001373291","0.0979143660515547"
"1.05099973734468","6.9860498046875","41.3800010681152","0.098110394901596"
"1.0527694830671","6.99697607421875","41.4500007629395","0.0982578421826474"
"1.05458591133356","7.0086845703125","41.5200004577637","0.0984448561212048"
"1.05640233960003","7.02061865234375","41.5900001525879","0.0985886945272796"
"1.0580790694803","7.0311875","41.6599998474121","0.0986871600616723"
"1.05989538133144","7.0418642578125","41.7299995422363","0.0989354302873835"
"1.06175837572664","7.05500732421875","41.7999992370605","0.0990003027254716"
"1.06431997846812","-0.195141265869141","41.8450012207031","-0.908951798919588"