File: BreakingLoadData/Kevlar/200mm/Trial1/17-4PH-300C-4h-01-Test Run 5 07-22-25 16 06 09 PM/DAQ- Crosshead, … - (Timed).csv
"File Path: C:\Users\Administrator\Desktop\Test Run 5 07-22-25 16 06 09 PM\DAQ- Crosshead, … - (Timed).csv   "
"Test: 17-4PH"
"Test Run: Test Run 5"
"Date: 7/22/2025 4:02:16 PM"
""
""
"Crosshead ","Load ","Time ","Extensometer "
"mm","kN","sec","mm"
"0.000652042729143432","0.0115979642868042","0.0549999997019768","5.9091127546651E-06"
"0.00726561893316102","0.0509371452331543","0.305000007152557","0.000249290081910658"
"0.0137394717967254","0.0704153289794922","0.555000007152557","0.000298606636306431"
"0.0200736012629932","0.0870086517333984","0.805000007152557","0.000255051077147073"
"0.026454305043444","0.104531097412109","1.05499994754791","0.000316315208692686"
"0.0327884336002171","0.123471054077148","1.30499994754791","0.000416294710703369"
"0.0391225621569902","0.144525146484375","1.55499994754791","0.000471616857566914"
"0.0455032677564304","0.168618789672852","1.80499994754791","0.000704919784766389"
"0.0518373963132035","0.192469223022461","2.0550000667572","0.000858876148868148"
"0.058218098274665","0.217529510498047","2.3050000667572","0.0010635544640536"
"0.0645522304694168","0.245218185424805","2.5550000667572","0.00124880864404986"
"0.0708863590261899","0.276277618408203","2.8050000667572","0.00155613838614954"
"0.0772670609876513","0.308306518554687","3.0550000667572","0.00189218428658933"
"0.0836011895444244","0.343089202880859","3.3050000667572","0.00228140697799972"
"0.0899353181011975","0.379748779296875","3.5550000667572","0.00267568225353898"
"0.0963160273386165","0.419209686279297","3.8050000667572","0.0031628414944862"
"0.10265015589539","0.459843170166016","4.05499982833862","0.00358432862412883"
"0.108984284452163","0.504519256591797","4.30499982833862","0.00408149389841128"
"0.115318413008936","0.551912902832031","4.55499982833862","0.00472788360639242"
"0.121699114970397","0.601037658691406","4.80499982833862","0.00536260768058128"
"0.128079816931859","0.652339599609375","5.05499982833862","0.00599806980972062"
"0.134413945488632","0.702468811035156","5.30499982833862","0.0066172624428873"
"0.140748074045405","0.754112060546875","5.55499982833862","0.00732112584955757"
"0.147082202602178","0.804895263671875","5.80499982833862","0.00801709211373236"
"0.153416331158951","0.856554870605469","6.05499982833862","0.00868049482960487"
"0.159843621077016","0.907797241210938","6.30499982833862","0.00941291546041612"
"0.166131168953143","0.958635803222656","6.55499982833862","0.0100312936410774"
"0.172511878190562","1.0091455078125","6.80499982833862","0.0106268562376499"
"0.178799426066689","1.06021276855469","7.05499982833862","0.0113629494080669"
"0.185180135304108","1.11202368164063","7.30499982833862","0.0119709065984352"
"0.191560829989612","1.16313708496094","7.55499982833862","0.0127115745272022"
"0.197894958546385","1.21459094238281","7.80499982833862","0.0133710282170796"
"0.204275667783804","1.26535949707031","8.05500030517578","0.0139894527819706"
"0.210563230211847","1.31653234863281","8.30500030517578","0.0146569518619799"
"0.21694392489735","1.3682529296875","8.55500030517578","0.015383038771688"
"0.223324634134769","1.4200576171875","8.80500030517578","0.0160152176249539"
"0.229658762691543","1.47077185058594","9.05500030517578","0.0166564823302906"
"0.235992891248316","1.52164086914063","9.30500030517578","0.0173131702467799"
"0.242327019805089","1.57137548828125","9.55500030517578","0.0180148126673885"
"0.248707714490592","1.62175463867188","9.80500030517578","0.0186287506949157"
"0.255041843047366","1.67228344726562","10.0550003051758","0.0192806655832101"
"0.261375971604139","1.72136535644531","10.3050003051758","0.019966799300164"
"0.267756695393473","1.77144897460938","10.5550003051758","0.0205830110644456"
"0.274090823950246","1.82014489746094","10.8050003051758","0.0211689803109039"
"0.28047151863575","1.86920397949219","11.0550003051758","0.0218643199332291"
"0.286805647192523","1.91733581542969","11.3050003051758","0.022467429516837"
"0.293139775749296","1.96573657226563","11.5550003051758","0.0230592504522065"
"0.2995204704348","2.01317651367187","11.8050003051758","0.023684035113547"
"0.305808032862842","2.06006787109375","12.0550003051758","0.024303408281412"
"0.312188727548346","2.10705102539062","12.3050003051758","0.0248369142354932"
"0.31856945133768","2.15207177734375","12.5550003051758","0.0253939797403291"
"0.324903579894453","2.19808227539062","12.8050003051758","0.0260826127487235"
"0.331237708451226","2.24281884765625","13.0550003051758","0.0266557199211093"
"0.337571837007999","2.28671533203125","13.3050003051758","0.0271305743808625"
"0.343952531693503","2.33026586914063","13.5550003051758","0.0277364306384698"
"0.350286660250276","2.37295092773437","13.8050003051758","0.0283029421552783"
"0.35666735493578","2.41553930664063","14.0550003051758","0.0288022965833079"
"0.363001483492553","2.45761474609375","14.3050003051758","0.0293808625428937"
"0.369335612049326","2.49835571289062","14.5550003051758","0.0298966697300784"
"0.375669740606099","2.53982006835938","14.8050003051758","0.0304577515635174"
"0.382097030524164","2.58088916015625","15.0550003051758","0.0309678762278054"
"0.388384592952207","2.62084790039063","15.3050003051758","0.031462222978007"
"0.394765287637711","2.66134448242188","15.5550003051758","0.03203909000149"
"0.401052850065753","2.70106127929688","15.8050003051758","0.0324481006828137"
"0.407433544751257","2.74183374023437","16.0550003051758","0.0330586954078171"
"0.413814239436761","2.78104956054688","16.3050003051758","0.0335124459525105"
"0.420148367993534","2.8195458984375","16.5550003051758","0.0339287653332576"
"0.426529091782868","2.85851806640625","16.8050003051758","0.0344970831065439"
"0.43281665421091","2.89693286132812","17.0550003051758","0.0349051879311446"
"0.439197348896414","2.93652514648437","17.3050003051758","0.0354276635334827"
"0.445578043581918","2.97392578125","17.5550003051758","0.0359144469257444"
"0.451912172138691","3.01103344726563","17.8050003051758","0.0363914805348031"
"0.458246300695464","3.04760375976563","18.0550003051758","0.0368085347872693"
"0.464580429252237","3.0847158203125","18.3050003051758","0.0371827154594939"
"0.470961153041571","3.1215478515625","18.5550003051758","0.0377150790882297"
"0.477295281598344","3.15840380859375","18.8050003051758","0.0381770441890694"
"0.483675976283848","3.19429443359375","19.0550003051758","0.038524351111846"
"0.490010075736791","3.2297138671875","19.3050003051758","0.0389782253478188"
"0.496344233397394","3.26517407226563","19.5550003051758","0.0394130038330331"
"0.502678332850337","3.30005126953125","19.8050003051758","0.039924056181917"
"0.509059056639671","3.33614721679688","20.0550003051758","0.0403533304051962"
"0.515393214300275","3.37057397460938","20.3050003051758","0.0407325387641322"
"0.521773879881948","3.40619189453125","20.5550003051758","0.0411271430493798"
"0.528061471413821","3.44015112304688","20.8050003051758","0.0416743496316485"
"0.534442136995494","3.47561157226562","21.0550003051758","0.0421045951952692"
"0.540822860784829","3.50983178710938","21.3050003051758","0.0424450518039521"
"0.547156960237771","3.54518774414062","21.5550003051758","0.0427989034506027"
"0.553491117898375","3.57960791015625","21.8050003051758","0.0432863416790497"
"0.559825275558978","3.613513671875","22.0550003051758","0.0436980262747966"
"0.566205941140652","3.64773583984375","22.3050003051758","0.0441026822954882"
"0.572540098801255","3.68169677734375","22.5550003051758","0.0444820361735765"
"0.578874198254198","3.71620581054687","22.8050003051758","0.0449606886832044"
"0.585254922043532","3.75129809570313","23.0550003051758","0.0454523142252583"
"0.591589021496475","3.78558764648437","23.3050003051758","0.0457240676041692"
"0.597969745285809","3.81930249023438","23.5550003051758","0.0460972696600948"
"0.604303902946413","3.8539296875","23.8050003051758","0.0465974881080911"
"0.610638002399355","3.88711279296875","24.0550003051758","0.0469792939838953"
"0.616972160059959","3.92114379882813","24.3050003051758","0.0473722029710189"
"0.623352825641632","3.95493383789062","24.5550003051758","0.0477931898785755"
"0.629686983302236","3.988083984375","24.8050003051758","0.0481644019600935"
"0.636067648883909","4.02147802734375","25.0550003051758","0.0486587996419985"
"0.642401806544513","4.0535029296875","25.3050003051758","0.0489493104396388"
"0.648735905997455","4.08760864257813","25.5550003051758","0.0493511724926066"
"0.655070063658059","4.11978369140625","25.8050003051758","0.0496612228744198"
"0.661450787447393","4.152787109375","26.0550003051758","0.0501701688335743"
"0.667831453029066","4.184625","26.3050003051758","0.0504913186887279"
"0.67416561068967","4.215984375","26.5550003051758","0.0509110504935961"
"0.680499710142612","4.24734375","26.8050003051758","0.0512083897774573"
"0.686833867803216","4.27971337890625","27.0550003051758","0.0515981228090823"
"0.693214533384889","4.31260791015625","27.3050003051758","0.0519709028594662"
"0.699548691045493","4.3451962890625","27.5550003051758","0.0523942762811203"
"0.705882790498435","4.3779580078125","27.8050003051758","0.0527720876561943"
"0.71226351428777","4.410109375","28.0550003051758","0.0531246987520717"
"0.718597671948373","4.443078125","28.3050003051758","0.0535514664079528"
"0.724931771401316","4.47690869140625","28.5550003051758","0.0540241017006338"
"0.73131249519065","4.5104443359375","28.8050003051758","0.054431555327028"
"0.737646594643593","4.54340673828125","29.0550003051758","0.0548493917449377"
"0.744027318432927","4.57625048828125","29.3050003051758","0.0552489582332782"
"0.75036141788587","4.6092783203125","29.5550003051758","0.0555875521968119"
"0.756695575546473","4.64209765625","29.8050003051758","0.0560565094929188"
"0.763076299335808","4.67665966796875","30.0550003051758","0.0565481859666761"
"0.769363832660019","4.7093134765625","30.3050003051758","0.0568821815249976"
"0.775791122578084","4.74310107421875","30.5550003051758","0.0573393263039179"
"0.782078655902296","4.77502392578125","30.8050003051758","0.0577747450734023"
"0.788459379691631","4.80875146484375","31.0550003051758","0.0582797401875723"
"0.794793479144573","4.84212451171875","31.3050003051758","0.0586507921980228"
"0.801127636805177","4.87540771484375","31.5550003051758","0.059161535318708"
"0.80750830238685","4.9095224609375","31.8050003051758","0.0596300706092734"
"0.813842460047454","4.94241796875","32.0550003051758","0.0600811144977342"
"0.820223183836788","4.97647021484375","32.3050003051758","0.0604756241955329"
"0.826557283289731","5.00954248046875","32.5550003051758","0.060930018662475"
"0.832938007079065","5.0438095703125","32.8050003051758","0.0613906813669018"
"0.839225540403277","5.07746484375","33.0550003051758","0.0617908299318515"
"0.845606264192611","5.11021923828125","33.3050003051758","0.0623130908934399"
"0.851940363645554","5.14403369140625","33.5550003051758","0.0627472472842783"
"0.858321087434888","5.1781669921875","33.8050003051758","0.0632061346550472"
"0.864655245095491","5.2115576171875","34.0550003051758","0.063626270275563"
"0.870989344548434","5.2461962890625","34.3050003051758","0.0641238657408394"
"0.877370068337768","5.27942822265625","34.5550003051758","0.0646388361928985"
"0.883704167790711","5.3140791015625","34.8050003051758","0.0651428927085362"
"0.890084891580045","5.34758935546875","35.0550003051758","0.0655818512313999"
"0.896372424904257","5.3802958984375","35.3050003051758","0.0659476645523682"
"0.902753148693591","5.41515478515625","35.5550003051758","0.0665460393065587"
"0.909087248146534","5.448630859375","35.8050003051758","0.0669316868879832"
"0.915467971935868","5.483251953125","36.0550003051758","0.0675074479659088"
"0.921848695725203","5.517107421875","36.3050003051758","0.0679021977703087"
"0.928136229049414","5.551619140625","36.5550003051758","0.0684176193317398"
"0.934516952838749","5.585568359375","36.8050003051758","0.0689128064550459"
"0.940804486162961","5.6205654296875","37.0550003051758","0.0693783003953286"
"0.947185209952295","5.654990234375","37.3050003051758","0.0698004660080187"
"0.953519309405237","5.690212890625","37.5550003051758","0.0703545883879997"
"0.959900033194572","5.72508203125","37.8050003051758","0.0708279621903785"
"0.966234132647514","5.75948193359375","38.0550003051758","0.0713668850949034"
"0.972614856436849","5.7941865234375","38.3050003051758","0.0718866212991998"
"0.978949014097452","5.8293603515625","38.5550003051758","0.0723476041457616"
"0.985329737886786","5.86475830078125","38.8050003051758","0.0729148887330666"
"0.991663779132068","5.89878271484375","39.0550003051758","0.0733150081941858"
"0.997997936792672","5.93249853515625","39.3050003051758","0.0738971357350238"
"1.00437866058201","5.9675517578125","39.5550003051758","0.0743937052902766"
"1.01071281824261","6.002158203125","39.8050003051758","0.0748740494600497"
"1.01709354203194","6.0372607421875","40.0550003051758","0.0755030778236687"
"1.02338101714849","6.071494140625","40.3050003051758","0.0759366521378979"
"1.02976174093783","6.107216796875","40.5550003051758","0.0763793359510601"
"1.03609589859843","6.14160107421875","40.8050003051758","0.0769996113376692"
"1.04243005625904","6.17632275390625","41.0550003051758","0.0774915097281337"
"1.04881066363305","6.21264892578125","41.3050003051758","0.0780676637077704"
"1.05514482129365","6.24829833984375","41.5550003051758","0.0785478623583913"
"1.06147897895426","6.2836337890625","41.8050003051758","0.0791664278949611"
"1.06781313661486","6.31796435546875","42.0550003051758","0.0796337990323082"
"1.07419374398887","6.35368115234375","42.3050003051758","0.0801632777438499"
"1.08057446777821","6.389318359375","42.5550003051758","0.0806789976195432"
"1.08690862543881","6.42489306640625","42.8050003051758","0.0812657526694238"
"1.09324278309941","6.46061767578125","43.0550003051758","0.0817885229480453"
"1.09957694076002","6.4953447265625","43.3050003051758","0.0824174931040034"
"1.1059109820053","6.5300537109375","43.5550003051758","0.0829398923087865"
"1.11229170579463","6.56472900390625","43.8050003051758","0.0834934544400312"
"1.11867242958397","6.6005146484375","44.0550003051758","0.0840444045024924"
"1.1250531533733","6.6362958984375","44.3050003051758","0.0846327166073024"
"1.1313873110339","6.67151953125","44.5550003051758","0.0851578079164028"
"1.13767478615046","6.70595751953125","44.8050003051758","0.0857167760841548"
"1.14405550993979","6.7417373046875","45.0550003051758","0.0863697059685364"
"1.15038966760039","6.77534814453125","45.3050003051758","0.0868997958605178"
"1.15677039138973","6.81242236328125","45.5550003051758","0.0874909674166702"
"1.16305786650628","6.8477724609375","45.8050003051758","0.0880306906765327"
"1.16943859029561","6.88427734375","46.0550003051758","0.0886547422851436"
"1.17581931408495","6.9198349609375","46.3050003051758","0.0893225005711429"
"1.18215347174555","6.95488232421875","46.5550003051758","0.0898826037882827"
"1.18848762940615","6.99189453125","46.8050003051758","0.0904949774849229"
"1.19482167065144","7.02755419921875","47.0550003051758","0.091160625743214"
"1.20120239444077","7.06436962890625","47.3050003051758","0.0916804565349594"
"1.20753655210137","7.09919287109375","47.5550003051758","0.092426584160421"
"1.21391727589071","7.13451708984375","47.8050003051758","0.0929926536628045"
"1.22025131713599","7.16982958984375","48.0550003051758","0.0936413562158123"
"1.22658547479659","7.20524072265625","48.3050003051758","0.0942521510296501"
"1.23296619858593","7.24121484375","48.5550003051758","0.0948569722822867"
"1.23930035624653","7.27697412109375","48.8050003051758","0.095502648036927"
"1.24568108003587","7.31239111328125","49.0550003051758","0.0961007317528129"
"1.25196855515242","7.3467958984375","49.3050003051758","0.0968043314060196"
"1.25834927894175","7.38267138671875","49.5550003051758","0.0975330549408682"
"1.26468343660235","7.41838916015625","49.8050003051758","0.0980548356892541"
"1.27106416039169","7.45496728515625","50.0550003051758","0.0987825405900367"
"1.27739820163697","7.488642578125","50.3050003051758","0.0994587171589956"
"1.28373235929757","7.5250390625","50.5550003051758","0.100083962024655"
"1.29006651695818","7.56009326171875","50.8050003051758","0.100781762739643"
"1.29640067461878","7.59637744140625","51.0550003051758","0.101492209068965"
"1.30278139840811","7.63315283203125","51.3050003051758","0.102182006230578"
"1.3091154396534","7.66800341796875","51.5550003051758","0.102851561678108"
"1.31549616344273","7.7044541015625","51.8050003051758","0.103628051874693"
"1.32183032110333","7.7385068359375","52.0550003051758","0.104323160485364"
"1.32816447876394","7.773369140625","52.3050003051758","0.105090875877067"
"1.33454508613795","7.808234375","52.5550003051758","0.1057282788679"
"1.34087924379855","7.8435078125","52.8050003051758","0.106491257611196"
"1.34721340145916","7.87907763671875","53.0550003051758","0.107364801806398"
"1.35359412524849","7.91472412109375","53.3050003051758","0.108013096905779"
"1.3599282829091","7.94894873046875","53.5550003051758","0.108734144305345"
"1.36630889028311","7.9839345703125","53.8050003051758","0.109491607872769"
"1.37264304794371","8.01934521484375","54.0550003051758","0.11026972788386"
"1.37897720560431","8.0531787109375","54.3050003051758","0.111022563942242"
"1.38535792939365","8.0888095703125","54.5550003051758","0.111823668703437"
"1.39169208705425","8.12298193359375","54.8050003051758","0.112659290607553"
"1.39807269442827","8.15875927734375","55.0550003051758","0.113459835120011"
"1.40436028596014","8.1935615234375","55.3050003051758","0.114269707410131"
"1.41074100974947","8.2292861328125","55.5550003051758","0.115141956484877"
"1.41707516741008","8.2633359375","55.8050003051758","0.115952992928214"
"1.42340920865536","8.2988505859375","56.0550003051758","0.116795170470141"
"1.42978993244469","8.332439453125","56.3050003051758","0.11774950689869"
"1.4361240901053","8.365693359375","56.5550003051758","0.118583186122123"
"1.44250481389463","8.400138671875","56.8050003051758","0.119424432341475"
"1.44879228901118","8.433248046875","57.0550003051758","0.120319775305688"
"1.45517301280051","8.4673974609375","57.3050003051758","0.121278870210517"
"1.46155373658985","8.50098828125","57.5550003051758","0.122162600746378"
"1.46788789425045","8.5334423828125","57.8050003051758","0.1231054920936"
"1.47426861803979","8.56621484375","58.0550003051758","0.124066951684654"
"1.48055609315634","8.599451171875","58.3050003051758","0.124965197755955"
"1.48693681694567","8.6331259765625","58.5550003051758","0.125972452224232"
"1.49327097460628","8.6654365234375","58.8050003051758","0.126910861581564"
"1.49965169839561","8.697865234375","59.0550003051758","0.127913968754001"
"1.50598585605621","8.7299599609375","59.3050003051758","0.129027044749819"
"1.5123198973015","8.763072265625","59.5550003051758","0.130050466395915"
"1.5186540549621","8.7955068359375","59.8050003051758","0.131033157231286"
"1.52503477875143","8.82865234375","60.0550003051758","0.132210057927296"
"1.53136893641204","8.85984375","60.3050003051758","0.133284920593724"
"1.53774954378605","8.891712890625","60.5550003051758","0.134424175485037"
"1.54408370144665","8.92214453125","60.8050003051758","0.135538706672378"
"1.55041785910726","8.9538720703125","61.0550003051758","0.136741815367714"
"1.55679858289659","8.985052734375","61.3050003051758","0.137962342705578"
"1.56313274055719","9.014484375","61.5550003051758","0.139093273901381"
"1.56946678180248","9.044205078125","61.8050003051758","0.140363568789326"
"1.57580093946308","9.0733056640625","62.0550003051758","0.141559779876843"
"1.58218166325241","9.1029306640625","62.3050003051758","0.142865697853267"
"1.58856238704175","9.1325751953125","62.5550003051758","0.144201723742299"
"1.59489642828703","9.1609208984375","62.8050003051758","0.145558020449243"
"1.60123058594763","9.1891435546875","63.0550003051758","0.1470342540415"
"1.60756474360824","9.2168515625","63.3050003051758","0.148371342220344"
"1.61394546739757","9.243576171875","63.5550003051758","0.149807208799757"
"1.62027962505817","9.2712705078125","63.8050003051758","0.151299231220037"
"1.62666023243219","9.2977802734375","64.0550003051758","0.152867127326317"
"1.63294782396406","9.3236220703125","64.3050003051758","0.15445047756657"
"1.63932854775339","9.3496298828125","64.5550003051758","0.156098525621928"
"1.645662705414","9.374677734375","64.8050003051758","0.157671311171725"
"1.65204342920333","9.399939453125","65.0550003051758","0.159422750584781"
"1.65837747044861","9.42303125","65.3050003051758","0.161115967785008"
"1.66471162810922","9.446986328125","65.5550003051758","0.16296211106237"
"1.67109235189855","9.4683916015625","65.8050003051758","0.164829558343627"
"1.67742650955915","9.4906240234375","66.0550003051758","0.166618716320954"
"1.68380711693317","9.51225","66.3050003051758","0.168654456501827"
"1.69014127459377","9.53277734375","66.5550003051758","0.170543848071247"
"1.69647543225437","9.554326171875","66.8050003051758","0.172709682374261"
"1.70280958991498","9.573724609375","67.0550003051758","0.174809465534054"
"1.70914363116026","9.5934189453125","67.3050003051758","0.176987989107147"
"1.71552435494959","9.61141796875","67.5550003051758","0.179194044903852"
"1.7218585126102","9.6291806640625","67.8050003051758","0.181559051270597"
"1.72823923639953","9.64658984375","68.0550003051758","0.183859330718406"
"1.73457339406013","9.664236328125","68.3050003051758","0.186339573701844"
"1.74090743530542","9.6799833984375","68.5550003051758","0.188795907888561"
"1.74728815909475","9.69538671875","68.8050003051758","0.191435960005037"
"1.75362231675535","9.70921875","69.0550003051758","0.193945350474678"
"1.75995647441596","9.7220927734375","69.3050003051758","0.196661203517579"
"1.76633719820529","9.7372294921875","69.5550003051758","0.199401692952961"
"1.77267123945057","9.7496220703125","69.8050003051758","0.202208349946886"
"1.77905196323991","9.762388671875","70.0550003051758","0.205029980861582"
"1.78538612090051","9.7730634765625","70.3050003051758","0.207919714739546"
"1.79172027856112","9.7840908203125","70.5550003051758","0.21094101248309"
"1.7980543198064","9.7943984375","70.8050003051758","0.213900406379253"
"1.804388477467","9.805349609375","71.0550003051758","0.21691620349884"
"1.81081576738507","9.8158798828125","71.3050003051758","0.220102432649583"
"1.81710335891694","9.8235810546875","71.5550003051758","0.223239781917073"
"1.82348408270627","9.833412109375","71.8050003051758","0.226493997615762"
"1.82981812395155","9.841080078125","72.0550003051758","0.229697208851576"
"1.83615228161216","9.8503798828125","72.3050003051758","0.233059618039988"
"1.84253300540149","9.8584658203125","72.5550003051758","0.236349573242478"
"1.8488671630621","9.8658681640625","72.8050003051758","0.23985818552319"
"1.85520120430738","9.873142578125","73.0550003051758","0.243304690229706"
"1.86158192809671","9.879400390625","73.3050003051758","0.246719893766567"
"1.86791608575732","9.886005859375","73.5550003051758","0.250352692091838"
"1.87425024341792","9.8934169921875","73.8050003051758","0.253958423854783"
"1.88063096720725","9.8992900390625","74.0550003051758","0.257520703598857"
"1.88696500845253","9.9045419921875","74.3050003051758","0.261198088992387"
"1.89334573224187","9.9101357421875","74.5550003051758","0.264846283243969"
"1.89963332377374","9.9148251953125","74.8050003051758","0.268515927018598"
"1.90606061369181","9.9207373046875","75.0550003051758","0.272315664915368"
"1.91234808880836","9.9253759765625","75.3050003051758","0.27606773073785"
"1.91872881259769","9.930876953125","75.5550003051758","0.279868225334212"
"1.9250629702583","9.9353056640625","75.8050003051758","0.283652567304671"
"1.9313971279189","9.939951171875","76.0550003051758","0.287518225377426"
"1.93777785170823","9.9448828125","76.3050003051758","0.291464995825663"
"1.94411189295352","9.9491640625","76.5550003051758","0.295252481009811"
"1.95049261674285","9.9549091796875","76.8050003051758","0.299333594739437"
"1.95678020827472","9.958412109375","77.0550003051758","0.303247943520546"
"1.96316093206406","9.9632998046875","77.3050003051758","0.307297887047753"
"1.96954165585339","9.966333984375","77.5550003051758","0.311308889649808"
"1.97587581351399","9.9706015625","77.8050003051758","0.315411540213972"
"1.9822099711746","9.974736328125","78.0550003051758","0.319493236020207"
"1.98854389600456","9.9784501953125","78.3050003051758","0.323501648381352"
"1.99492461979389","9.9816904296875","78.5550003051758","0.327706860844046"
"2.0012587774545","9.9851474609375","78.8050003051758","0.331804010784253"
"2.00763950124383","9.9874755859375","79.0550003051758","0.335894001182169"
"2.0139270927757","9.9905888671875","79.3050003051758","0.339971797075123"
"2.02030781656504","9.9945546875","79.5550003051758","0.344151922035962"
"2.02664197422564","9.99772265625","79.8050003051758","0.348331755958498"
"2.03302269801497","10.0013798828125","80.0550003051758","0.352461880538613"
"2.03935685567558","10.003451171875","80.3050003051758","0.356608565198258"
"2.04573734663427","10.0068623046875","80.5550003051758","0.360818026820198"
"2.05207150429487","10.009947265625","80.8050003051758","0.364962383173406"
"2.05840566195548","10.012978515625","81.0550003051758","0.369153945939615"
"2.06478638574481","10.0173564453125","81.3050003051758","0.373357412172481"
"2.07112054340541","10.0196171875","81.5550003051758","0.377668882720172"
"2.07745470106602","10.0225517578125","81.8050003051758","0.38187438622117"
"2.08378885872662","10.0255673828125","82.0550003051758","0.386111525585875"
"2.09012301638722","10.02998828125","82.3050003051758","0.390384724596515"
"2.09650374017656","10.03318359375","82.5550003051758","0.394766248064116"
"2.10283766500652","10.035521484375","82.8050003051758","0.39908813778311"
"2.10921838879585","10.0380283203125","83.0550003051758","0.403481535613537"
"2.11555254645646","10.040283203125","83.3050003051758","0.407773826736957"
"2.12193327024579","10.0428896484375","83.5550003051758","0.412106834119186"
"2.12826742790639","10.04596484375","83.8050003051758","0.41643570875749"
"2.134601585567","10.048685546875","84.0550003051758","0.42085480527021"
"2.1409357432276","10.05080078125","84.3050003051758","0.425191741669551"
"2.14731646701694","10.053228515625","84.5550003051758","0.429569132393226"
"2.15365062467754","10.0553369140625","84.8050003051758","0.433932349551469"
"2.16003111563623","10.05944921875","85.0550003051758","0.438291986938566"
"2.16636527329683","10.0616298828125","85.3050003051758","0.442679069237784"
"2.17269943095744","10.0643955078125","85.5550003051758","0.447002559667453"
"2.17903358861804","10.06658984375","85.8050003051758","0.451478757895529"
"2.18536774627864","10.0696103515625","86.0550003051758","0.455854955362156"
"2.19179503619671","10.072736328125","86.3050003051758","0.460290117189288"
"2.19808262772858","10.075287109375","86.5550003051758","0.464868411654606"
"2.20446335151792","10.078470703125","86.8050003051758","0.469309452455491"
"2.21079750917852","10.0800419921875","87.0550003051758","0.473717605927959"
"2.21713143400848","10.082947265625","87.3050003051758","0.478176953038201"
"2.22351215779781","10.0847607421875","87.5550003051758","0.482696224935353"
"2.22984631545842","10.0874287109375","87.8050003051758","0.487189478008077"
"2.23618047311902","10.0903603515625","88.0550003051758","0.491703627631068"
"2.24256119690835","10.0925810546875","88.3050003051758","0.496187538374215"
"2.24889535456896","10.0947021484375","88.5550003051758","0.500697351526469"
"2.25522951222956","10.097107421875","88.8050003051758","0.505209201946855"
"2.2616102360189","10.09928515625","89.0550003051758","0.509691541083157"
"2.2679443936795","10.10205078125","89.3050003051758","0.514200539328158"
"2.27432488463819","10.1054365234375","89.5550003051758","0.518762622959912"
"2.28061247617006","10.1077197265625","89.8050003051758","0.523328664712608"
"2.28703976608813","10.1110185546875","90.0550003051758","0.527871481608599"
"2.29332735762","10.111630859375","90.3050003051758","0.532403413672"
"2.29970808140934","10.1148271484375","90.5550003051758","0.536943261977285"
"2.30604223906994","10.118","90.8050003051758","0.541518267709762"
"2.31237639673054","10.1209130859375","91.0550003051758","0.546124065294862"
"2.31875712051988","10.12334375","91.3050003051758","0.550731201656163"
"2.32509127818048","10.1245771484375","91.5550003051758","0.555286067537963"
"2.33147176913917","10.127177734375","91.8050003051758","0.559883133973926"
"2.33775936067104","10.129146484375","92.0550003051758","0.564467336516827"
"2.34414008446038","10.1327646484375","92.3050003051758","0.56904146913439"
"2.35052080824971","10.134599609375","92.5550003051758","0.573773577343673"
"2.35685496591032","10.13589453125","92.8050003051758","0.578295963350683"
"2.36318912357092","10.1381220703125","93.0550003051758","0.582895125262439"
"2.36952328123152","10.1397734375","93.3050003051758","0.587415939662606"
"2.37590400502086","10.1421787109375","93.5550003051758","0.591984193306416"
"2.38223816268146","10.1449521484375","93.8050003051758","0.596501398831606"
"2.38861865364015","10.147515625","94.0550003051758","0.601189967710525"
"2.39495281130075","10.14941796875","94.3050003051758","0.605695589911193"
"2.40128696896136","10.1517333984375","94.5550003051758","0.610281596891582"
"2.40762112662196","10.1534375","94.8050003051758","0.614821445196867"
"2.4140018504113","10.157705078125","95.0550003051758","0.619507860392332"
"2.4203360080719","10.15966796875","95.3050003051758","0.624099338892847"
"2.42671673186123","10.162443359375","95.5550003051758","0.628737499937415"
"2.43305088952184","10.1645810546875","95.8050003051758","0.633424380794168"
"2.43938504718244","10.1663603515625","96.0550003051758","0.638088502455503"
"2.44576577097178","10.16932421875","96.3050003051758","0.642763334326446"
"2.45209969580173","10.171083984375","96.5550003051758","0.647374137770385"
"2.45843385346234","10.173935546875","96.8050003051758","0.652088201604784"
"2.46476801112294","10.175408203125","97.0550003051758","0.656718213576823"
"2.47114873491228","10.1772880859375","97.3050003051758","0.661364407278597"
"2.47752945870161","10.1794560546875","97.5550003051758","0.665969389956445"
"2.48381705023348","10.1817451171875","97.8050003051758","0.670627399813384"
"2.49019777402282","10.184013671875","98.0550003051758","0.675315503031015"
"2.49653193168342","10.185966796875","98.3050003051758","0.679894641507417"
"2.50291265547276","10.1873544921875","98.5550003051758","0.684620346873999"
"2.50924658030272","10.1904560546875","98.8050003051758","0.68918865872547"
"2.51558073796332","10.1924541015625","99.0550003051758","0.693831068929285"
"2.52191489562392","10.194857421875","99.3050003051758","0.698486692272127"
"2.52829561941326","10.1985556640625","99.5550003051758","0.703215773683041"
"2.53462977707386","10.2002666015625","99.8050003051758","0.707898463588208"
"2.54101050086319","10.203080078125","100.055000305176","0.712595239747316"
"2.5473446585238","10.20426171875","100.305000305176","0.717235205229372"
"2.5536788161844","10.206595703125","100.555000305176","0.721999735105783"
"2.56001274101436","10.2089326171875","100.805000305176","0.726719154044986"
"2.56634689867496","10.2109697265625","101.055000305176","0.731326581444591"
"2.57277418859303","10.213962890625","101.305000305176","0.735979119781405"
"2.5790617801249","10.2143544921875","101.555000305176","0.740717456210405"
"2.58544250391424","10.2166806640625","101.805000305176","0.745425117202103"
"2.59177666157484","10.2186611328125","102.055000305176","0.750029634218663"
"2.59811081923544","10.2216318359375","102.305000305176","0.754722917918116"
"2.60449154302478","10.2238681640625","102.555000305176","0.759438902605325"
"2.61087226681411","10.22585546875","102.805000305176","0.764123746193945"
"2.61720642447472","10.2269052734375","103.055000305176","0.768753583543003"
"2.62354034930468","10.229474609375","103.305000305176","0.773426378145814"
"2.62987450696528","10.231783203125","103.555000305176","0.778065761551261"
"2.63620866462588","10.23448828125","103.805000305176","0.782783841714263"
"2.64258938841522","10.23717578125","104.055000305176","0.787505297921598"
"2.64892354607582","10.2391201171875","104.305000305176","0.792191713117063"
"2.65530426986516","10.2416455078125","104.555000305176","0.796950422227383"
"2.66159186139703","10.243544921875","104.805000305176","0.801639922428876"
"2.66801915131509","10.246505859375","105.055000305176","0.806446420028806"
"2.6743533089757","10.24787109375","105.305000305176","0.811109435744584"
"2.68068723380566","10.250337890625","105.555000305176","0.815786654129624"
"2.68706795759499","10.2522578125","105.805000305176","0.820507877506316"
"2.69335554912686","10.253537109375","106.055000305176","0.825232767965645"
"2.6997362729162","10.256904296875","106.305000305176","0.829932512715459"
"2.7060704305768","10.2581787109375","106.555000305176","0.834668462630361"
"2.71245115436614","10.2610380859375","106.805000305176","0.83935703150928"
"2.71878531202674","10.2623564453125","107.055000305176","0.844058988150209"
"2.72511946968734","10.2643984375","107.305000305176","0.848747324198484"
"2.73150019347668","10.2666015625","107.555000305176","0.85343251703307"
"2.73783411830664","10.2688671875","107.805000305176","0.858151237480342"
"2.74421484209597","10.27174609375","108.055000305176","0.862888700794429"
"2.75050243362784","10.2735615234375","108.305000305176","0.867564813233912"
"2.75688315741718","10.276466796875","108.555000305176","0.872299948241562"
"2.76326388120651","10.27771875","108.805000305176","0.876944395713508"
"2.76959803886712","10.2804052734375","109.055000305176","0.881713756825775"
"2.77593219652772","10.2822734375","109.305000305176","0.886339868884534"
"2.78226635418832","10.2844912109375","109.555000305176","0.891139905434102"
"2.78860051184893","10.2862861328125","109.805000305176","0.8958819671534"
"2.79498100280762","10.2888740234375","110.055000305176","0.90048520360142"
"2.80136172659695","10.2899091796875","110.305000305176","0.905278371647"
"2.80769588425756","10.292537109375","110.555000305176","0.910000700969249"
"2.81403004191816","10.29318359375","110.805000305176","0.914679781999439"
"2.82036419957876","10.295404296875","111.055000305176","0.919328187592328"
"2.8267449233681","10.29840234375","111.305000305176","0.924014602787793"
"2.8330790810287","10.3000380859375","111.555000305176","0.928652414586395"
"2.83945980481803","10.3024189453125","111.805000305176","0.933343661017716"
"2.84579396247864","10.3039521484375","112.055000305176","0.938003184273839"
"2.8521278873086","10.30698046875","112.305000305176","0.942733022384346"
"2.85850861109793","10.309203125","112.555000305176","0.947438878938556"
"2.86484276875854","10.3113896484375","112.805000305176","0.952177040744573"
"2.87117692641914","10.313775390625","113.055000305176","0.95679028891027"
"2.87751108407974","10.3160615234375","113.305000305176","0.96148916054517"
"2.88389180786908","10.3186787109375","113.555000305176","0.96627906896174"
"2.89022596552968","10.3206298828125","113.805000305176","0.971037719864398"
"2.89660668931901","10.322494140625","114.055000305176","0.975763774476945"
"2.90294084697962","10.3236640625","114.305000305176","0.980498152785003"
"2.90927477180958","10.3250556640625","114.555000305176","0.985221704468131"
"2.91560892947018","10.3271796875","114.805000305176","0.98991091363132"
"2.92198965325952","10.32978515625","115.055000305176","0.994542730040848"
"2.92832381092012","10.331560546875","115.305000305176","0.999296898953617"
"2.93465796858072","10.3335693359375","115.555000305176","1.00395025219768"
"2.94103869237006","10.335","115.805000305176","1.00863527040929"
"2.94737285003066","10.336935546875","116.055000305176","1.01324100978673"
"2.95375357381999","10.340037109375","116.305000305176","1.01786374580115"
"2.9600877314806","10.34165625","116.555000305176","1.02255865931511"
"2.96642165631056","10.343767578125","116.805000305176","1.02728989440948"
"2.97275581397116","10.3454091796875","117.055000305176","1.03190471418202"
"2.97908997163177","10.347783203125","117.305000305176","1.03655981365591"
"2.98551726154983","10.3507783203125","117.555000305176","1.04123819619417"
"2.99185141921043","10.3531748046875","117.805000305176","1.04596943128854"
"2.99818557687104","10.3556748046875","118.055000305176","1.05070986319333"
"3.00451973453164","10.3567880859375","118.305000305176","1.05537718627602"
"3.01085389219224","10.358919921875","118.555000305176","1.06006662826985"
"3.01723461598158","10.360642578125","118.805000305176","1.06476957444102"
"3.02361533977091","10.3633720703125","119.055000305176","1.0694875381887"
"3.02994926460087","10.364728515625","119.305000305176","1.07418955303729"
"3.03628342226148","10.36699609375","119.555000305176","1.07886013574898"
"3.04261757992208","10.3677646484375","119.805000305176","1.08352384995669"
"3.04899830371141","10.3705498046875","120.055000305176","1.08818034641445"
"3.05533246137202","10.3717646484375","120.305000305176","1.09294184949249"
"3.06166661903262","10.3745693359375","120.555000305176","1.09757308382541"
"3.06804734282196","10.3770732421875","120.805000305176","1.10223784577101"
"3.07438150048256","10.3783564453125","121.055000305176","1.10686733387411"
"3.08076222427189","10.38096484375","121.305000305176","1.11149565782398"
"3.08709614910185","10.3822236328125","121.555000305176","1.11618207301944"
"3.09343030676246","10.3844677734375","121.805000305176","1.12080480903387"
"3.09976446442306","10.386255859375","122.055000305176","1.12551031634212"
"3.10614518821239","10.389439453125","122.305000305176","1.1301493505016"
"3.11252591200173","10.39100390625","122.555000305176","1.13478989806026"
"3.11886006966233","10.3921318359375","122.805000305176","1.13950995728374"
"3.12519422732294","10.3938740234375","123.055000305176","1.14417483564466"
"3.13152838498354","10.39496875","123.305000305176","1.14884763024747"
"3.1378623098135","10.3972021484375","123.555000305176","1.15345930680633"
"3.14424303360283","10.3993876953125","123.805000305176","1.1581783182919"
"3.15062375739217","10.4008134765625","124.055000305176","1.16276938933879"
"3.15691134892404","10.4019375","124.305000305176","1.16749911103398"
"3.16329207271338","10.4040634765625","124.555000305176","1.1720557231456"
"3.16962623037398","10.40544921875","124.805000305176","1.17667962331325"
"3.17600695416331","10.4088466796875","125.055000305176","1.18137057870626"
"3.18238767795265","10.4108984375","125.305000305176","1.18593487422913"
"3.18867526948452","10.411869140625","125.555000305176","1.19066354818642"
"3.19505599327385","10.4136611328125","125.805000305176","1.19523203466088"
"3.20138991810381","10.41463671875","126.055000305176","1.19990296661854"
"3.20772407576442","10.41853515625","126.305000305176","1.20458996389061"
"3.21410479955375","10.419806640625","126.555000305176","1.20922457426786"
"3.22043895721436","10.4223544921875","126.805000305176","1.21393927838653"
"3.22677311487496","10.423283203125","127.055000305176","1.21861277148128"
"3.23310727253556","10.4243837890625","127.305000305176","1.22316682245582"
"3.2394879963249","10.42640625","127.555000305176","1.2278261128813"
"3.2458221539855","10.4292236328125","127.805000305176","1.2325937859714"
"3.25220287777483","10.4307109375","128.054992675781","1.237150747329"
"3.25853680260479","10.4316142578125","128.304992675781","1.24182738363743"
"3.2648709602654","10.4323642578125","128.554992675781","1.24651216901839"
"3.27125168405473","10.433435546875","128.804992675781","1.25109148211777"
"3.27758584171534","10.4356220703125","129.054992675781","1.25571864191443"
"3.28391999937594","10.4369208984375","129.304992675781","1.26040319446474"
"3.29030072316527","10.4387060546875","129.554992675781","1.26502406783402"
"3.29663488082588","10.4392880859375","129.804992675781","1.26965600065887"
"3.30301560461521","10.441763671875","130.054992675781","1.27432215958834"
"3.30934976227582","10.4429482421875","130.304992675781","1.27893639728427"
"3.31568368710577","10.445103515625","130.554992675781","1.2835810193792"
"3.32201784476638","10.447654296875","130.804992675781","1.28823425620794"
"3.32835200242698","10.448802734375","131.054992675781","1.29292358178645"
"3.33477929234505","10.4510126953125","131.304992675781","1.29762338474393"
"3.34106688387692","10.451654296875","131.554992675781","1.30224449094385"
"3.34744760766625","10.4537705078125","131.804992675781","1.30688771605492"
"3.35378176532686","10.455486328125","132.054992675781","1.31158728618175"
"3.36011592298746","10.45744140625","132.304992675781","1.31630210671574"
"3.3664966467768","10.4588701171875","132.554992675781","1.32089469116181"
"3.37287713773549","10.460126953125","132.804992675781","1.32561509963125"
"3.37921129539609","10.46069921875","133.054992675781","1.33024353999645"
"3.38554545305669","10.4623662109375","133.304992675781","1.33493379689753"
"3.3918796107173","10.46453515625","133.554992675781","1.33957737125456"
"3.3982137683779","10.4659208984375","133.804992675781","1.34431419428438"
"3.40459449216723","10.4676630859375","134.054992675781","1.34894426446408"
"3.41092864982784","10.46884375","134.304992675781","1.3536277692765"
"3.41730937361717","10.4699248046875","134.554992675781","1.35836459230632"
"3.42359696514904","10.4711162109375","134.804992675781","1.36289233341813"
"3.42997745610774","10.4743720703125","135.054992675781","1.36763555929065"
"3.43635817989707","10.475953125","135.304992675781","1.3723112642765"
"3.44269233755767","10.4768720703125","135.554992675781","1.37697346508503"
"3.44907306134701","10.4787568359375","135.804992675781","1.38170982245356"
"3.45536065287888","10.47947265625","136.054992675781","1.38633814640343"
"3.46178794279695","10.4825810546875","136.304992675781","1.39109278097749"
"3.46807553432882","10.48341015625","136.554992675781","1.39577966183424"
"3.47445625811815","10.4846220703125","136.804992675781","1.40058610122651"
"3.48079041577876","10.485361328125","137.054992675781","1.40528031624854"
"3.48717113956809","10.48649609375","137.304992675781","1.40987790655345"
"3.49350506439805","10.4874111328125","137.554992675781","1.41458865255117"
"3.49988578818738","10.4896416015625","137.804992675781","1.41921464819461"
"3.50621994584799","10.490451171875","138.054992675781","1.42398884054273"
"3.51255410350859","10.4911298828125","138.304992675781","1.42860331106931"
"3.5188882611692","10.4922197265625","138.554992675781","1.43331044819206"
"3.5252224188298","10.4932314453125","138.804992675781","1.43799057696015"
"3.53160314261913","10.49511328125","139.054992675781","1.44262856338173"
"3.53793730027974","10.4965185546875","139.304992675781","1.44734827335924"
"3.54431802406907","10.49812109375","139.554992675781","1.4520714757964"
"3.5506053827703","10.49869140625","139.804992675781","1.45671202335507"
"3.55698610655963","10.500654296875","140.054992675781","1.46134046372026"
"3.56336683034897","10.5017333984375","140.304992675781","1.46605761256069"
"3.56970098800957","10.5029345703125","140.554992675781","1.47071329411119"
"3.57608171179891","10.50484375","140.804992675781","1.47547421511263"
"3.58236930333078","10.5046630859375","141.054992675781","1.48019101470709"
"3.58875002712011","10.5063701171875","141.304992675781","1.48487160913646"
"3.59508418478072","10.5058671875","141.554992675781","1.48955907206982"
"3.60146490857005","10.5071552734375","141.804992675781","1.49417866487056"
"3.60779883340001","10.507767578125","142.054992675781","1.49889779277146"
"3.61413299106061","10.5092861328125","142.304992675781","1.50352134369314"
"3.62051371484995","10.5095263671875","142.554992675781","1.50824466254562"
"3.62684787251055","10.5095859375","142.804992675781","1.51289906352758"
"3.63322859629989","10.5096826171875","143.054992675781","1.51762599125504"
"3.63956275396049","10.5097578125","143.304992675781","1.52231205720454"
"3.64589691162109","10.51092578125","143.554992675781","1.52704014908522"
"3.6522310692817","10.5111123046875","143.804992675781","1.53171562124044"
"3.65861179307103","10.51154296875","144.054992675781","1.53658748604357"
"3.66494571790099","10.5107294921875","144.304992675781","1.54132582247257"
"3.67127987556159","10.51180859375","144.554992675781","1.54606811702251"
"3.67766059935093","10.5121435546875","144.804992675781","1.55078887473792"
"3.68399475701153","10.512634765625","145.054992675781","1.55569333583117"
"3.69037548080087","10.513501953125","145.304992675781","1.56054564286023"
"3.69670963846147","10.5133798828125","145.554992675781","1.56535557471216"
"3.70304379612207","10.513333984375","145.804992675781","1.57020671758801"
"3.70937795378268","10.5128515625","146.054992675781","1.57506775576621"
"3.71575867757201","10.51370703125","146.304992675781","1.57994136679918"
"3.72209260240197","10.512765625","146.554992675781","1.58491649199277"
"3.72847332619131","10.5111494140625","146.804992675781","1.58980046398938"
"3.73480748385191","10.50858203125","147.054992675781","1.59474229440093"
"3.74114164151251","10.508130859375","147.304992675781","1.59968109801412"
"3.74752236530185","10.5087109375","147.554992675781","1.60472968127578"
"3.75385652296245","10.509","147.804992675781","1.60966906696558"
"3.76023724675179","10.50916796875","148.054992675781","1.61476549692452"
"3.76657140441239","10.5081376953125","148.304992675781","1.61977100651711"
"3.77290556207299","10.5075126953125","148.554992675781","1.6248234314844"
"3.77923948690295","10.5055703125","148.804992675781","1.62997946608812"
"3.78562021069229","10.5041630859375","149.054992675781","1.63510558195412"
"3.79195436835289","10.500349609375","149.304992675781","1.64056557696313"
"3.79833509214222","10.4980751953125","149.554992675781","1.64586747996509"
"3.8046226836741","10.49468359375","149.804992675781","1.65116519201547"
"3.81100340746343","10.4930537109375","150.054992675781","1.65649759583175"
"3.81738413125277","10.4912138671875","150.304992675781","1.66193558834493"
"3.82371828891337","10.489263671875","150.554992675781","1.66738487314433"
"3.83005244657397","10.4868173828125","150.804992675781","1.67277350556105"
"3.83638637140393","10.481904296875","151.054992675781","1.67823489755392"
"3.84276709519327","10.477904296875","151.304992675781","1.68382492847741"
"3.84910125285387","10.4703671875","151.554992675781","1.68936303816736"
"3.8554819766432","10.45855859375","151.804992675781","1.69522757641971"
"3.86181613430381","10.44582421875","152.054992675781","1.7012448515743"
"3.86815029196441","10.4314052734375","152.304992675781","1.70743768103421"
"3.87453101575375","10.3914462890625","152.554992675781","1.71465426683426"
"3.88086517341435","10.35802734375","152.804992675781","1.72176246996969"
"3.88724589720368","10.32627734375","153.054992675781","1.72898557502776"
"3.89353325590491","10.291984375","153.304992675781","1.73638144042343"
"3.89991397969425","10.2638515625","153.554992675781","1.74378743395209"
"3.90624813735485","10.234861328125","153.804992675781","1.75121170468628"
"3.91262909397483","10.2096533203125","154.054992675781","1.75855169072747"
"3.91896301880479","10.1967412109375","154.304992675781","1.76536419894546"
"3.92529694363475","10.18665625","154.554992675781","1.77205156069249"
"3.931631334126","10.17472265625","154.804992675781","1.77887745667249"
"3.93801182508469","10.160560546875","155.054992675781","1.78584293462336"
"3.94439278170466","10.1434052734375","155.304992675781","1.79296033456922"
"3.95072670653462","10.121201171875","155.554992675781","1.80006655864418"
"3.95706109702587","10.0990439453125","155.804992675781","1.80731469299644"
"3.96339502185583","10.059701171875","156.054992675781","1.81522814091295"
"3.96977597847581","10.019935546875","156.304992675781","1.82330154348165"
"3.97610990330577","9.954833984375","156.554992675781","1.83235469739884"
"3.98249039426446","9.870517578125","156.804992675781","1.84233102481812"
"3.98882478475571","9.731234375","157.054992675781","1.85449235141277"
"3.99515870958567","9.6173212890625","157.304992675781","1.86562596354634"
"4.00153966620564","9.2813896484375","157.554992675781","1.88583531416953"
"4.0078735910356","8.9804716796875","157.804992675781","1.90477771684527"
"4.01425454765558","7.54128125","158.054992675781","1.9731861539185"
"4.02058847248554","7.4292021484375","158.304992675781","1.98479485698044"
"4.02692286297679","6.88505126953125","158.554992675781","2.01456830836833"
"4.03330335393548","6.7105107421875","158.804992675781","2.0299581810832"
"4.03963727876544","6.66526904296875","159.054992675781","2.03876034356654"
"4.04597166925669","6.6267783203125","159.304992675781","2.04697879962623"
"4.05235216021538","6.59229638671875","159.554992675781","2.05484381876886"
"4.05868655070662","6.5620185546875","159.804992675781","2.06254655495286"
"4.06502047553658","6.505087890625","160.054992675781","2.07114755176008"
"4.07140143215656","6.42909033203125","160.304992675781","2.08077719435096"
"4.07773535698652","6.322478515625","160.554992675781","2.09171394817531"
"4.0841163136065","4.969998046875","160.804992675781","2.16636341065168"
"4.09040367230773","4.92004833984375","161.054992675781","2.17584241181612"
"4.09678416326642","4.89331787109375","161.304992675781","2.18396610580385"
"4.1031651198864","4.8674638671875","161.554992675781","2.1917000412941"
"4.10949904471636","4.80601318359375","161.804992675781","2.20075994729996"
"4.11583343520761","4.73376904296875","162.054992675781","2.21064873039722"
"4.12216736003757","4.6731572265625","162.304992675781","2.22005182877183"
"4.12854831665754","4.6232548828125","162.554992675781","2.22912291064858"
"4.1348822414875","4.585375","162.804992675781","2.23753042519093"
"4.14121663197875","4.54093701171875","163.054992675781","2.2461696062237"
"4.14759712293744","4.4884384765625","163.304992675781","2.25510750897229"
"4.15388448163867","4.44440087890625","163.554992675781","2.26385076530278"
"4.16026543825865","4.380560546875","163.804992675781","2.27335887029767"
"4.16664592921734","4.2776328125","164.054992675781","2.28454126045108"
"4.17298031970859","4.16965380859375","164.304992675781","2.29650922119617"
"4.17936081066728","3.94647216796875","164.554992675781","2.31431401334703"
"4.18569520115852","3.26662109375","164.804992675781","2.35869316384196"
"4.18821023777127","0.00543713474273682","164.891006469727","2.52245832234621"