File: BreakingLoadData/Kevlar/200mm/Trial1/17-4PH-300C-4h-02-Test Run 6 07-22-25 16 12 14 PM/DAQ- Crosshead, … - (Timed).csv
"File Path: C:\Users\Administrator\Desktop\Test Run 6 07-22-25 16 12 14 PM\DAQ- Crosshead, … - (Timed).csv   "
"Test: 17-4PH"
"Test Run: Test Run 6"
"Date: 7/22/2025 4:08:04 PM"
""
""
"Crosshead ","Load ","Time ","Extensometer "
"mm","kN","sec","mm"
"0.000139723439929185","0.0435094146728516","0.00999999977648258","-1.32222996995779E-05"
"0.00745191664464073","0.0773608703613281","0.300000011920929","0.000376755508568749"
"0.0149038332892815","0.100789604187012","0.589999973773956","0.00058336365782452"
"0.0222160269913729","0.122868522644043","0.879999995231628","0.000799908775661606"
"0.029667942726519","0.14641911315918","1.16999995708466","0.0010990547707479"
"0.0370267116522882","0.17375732421875","1.46000003814697","0.0013045837476966"
"0.0444320539827459","0.202754821777344","1.75","0.00161537104759191"
"0.0517908229085151","0.232849548339844","2.03999996185303","0.00198190718947444"
"0.0591495881963056","0.264755340576172","2.32999992370605","0.00236122764363245"
"0.0664617837173864","0.300220947265625","2.61999988555908","0.00273093223768228"
"0.0738205490051769","0.338472747802734","2.91000008583069","0.00326276085615973"
"0.0812258949736133","0.380011260986328","3.20000004768372","0.00372829936168273"
"0.0886312336660922","0.426019805908203","3.49000000953674","0.00435367110185325"
"0.0959900062298402","0.475492126464844","3.77999997138977","0.00501969998367713"
"0.103348771517631","0.528694641113281","4.07000017166138","0.00581940230404143"
"0.110660963400733","0.585199279785156","4.3600001335144","0.00652770631859312"
"0.118019728688523","0.644007629394531","4.65000009536743","0.00731995532987639"
"0.125425067381002","0.704963439941406","4.94000005722046","0.00821429966890719"
"0.132830420625396","0.765147766113281","5.23000001907349","0.00907591856957879"
"0.140189178637229","0.825154174804688","5.51999998092651","0.0099423659776221"
"0.147547951200977","0.8833447265625","5.80999994277954","0.0107254963950254"
"0.154860143084079","0.942025085449219","6.09999990463257","0.0116462506412063"
"0.162218915647827","1.00126531982422","6.3899998664856","0.0124798889373778"
"0.169624254340306","1.06164526367187","6.67999982833862","0.0132775821839459"
"0.176983026904054","1.12254528808594","6.96999979019165","0.0141061691465438"
"0.184388365596533","1.18357702636719","7.26000022888184","0.0150090945680859"
"0.191747138160281","1.24449926757813","7.55000019073486","0.0158533330250066"
"0.199059330043383","1.30461328125","7.84000015258789","0.0167174639500445"
"0.206418088055216","1.36589660644531","8.13000011444092","0.0174836950463941"
"0.213776860618964","1.42716662597656","8.42000007629395","0.0183759493666003"
"0.221182199311443","1.49006848144531","8.71000003814697","0.0192803981917677"
"0.228587552555837","1.55236474609375","9","0.0201596049009822"
"0.23594631056767","1.6140234375","9.28999996185303","0.0209621557587525"
"0.243258502450772","1.6746171875","9.57999992370605","0.0217453180084703"
"0.25061727501452","1.73570739746094","9.86999988555908","0.0225925523409387"
"0.257976033026353","1.79708581542969","10.1599998474121","0.0233989831031067"
"0.265381386270747","1.85954821777344","10.4499998092651","0.0242612641159212"
"0.272740144282579","1.92007836914063","10.7399997711182","0.0249838121817447"
"0.280145497526973","1.98048669433594","11.0299997329712","0.0258448362728814"
"0.287504255538806","2.03932800292969","11.3199996948242","0.0266449878836283"
"0.294816447421908","2.09841357421875","11.6099996566772","0.0273938985628774"
"0.302175234537572","2.15615087890625","11.8999996185303","0.0280877502518706"
"0.309533992549405","2.21402709960938","12.1899995803833","0.0289361723844195"
"0.316985911922529","2.27223803710937","12.4799995422363","0.0296693560812855"
"0.324344669934362","2.32840356445312","12.7700004577637","0.030412940759561"
"0.331703457050025","2.38462182617188","13.0600004196167","0.0310367140627932"
"0.339015648933128","2.43995825195312","13.3500003814697","0.0318750098813325"
"0.34637440694496","2.494572265625","13.6400003433228","0.0325099354085978"
"0.353733164956793","2.54940844726563","13.9300003051758","0.033214790164493"
"0.361138518201187","2.60459497070313","14.2200002670288","0.0339599100698251"
"0.368543871445581","2.6593935546875","14.5100002288818","0.0346488959621638"
"0.375902629457414","2.712853515625","14.8000001907349","0.035334855056135"
"0.383261387469247","2.76546459960938","15.0900001525879","0.036000128602609"
"0.390573579352349","2.81643115234375","15.3800001144409","0.036706478567794"
"0.397932366468012","2.86692895507813","15.6700000762939","0.0372472895833198"
"0.405291124479845","2.91708837890625","15.960000038147","0.0378979166271165"
"0.41274304385297","2.96672607421875","16.25","0.0385563798772637"
"0.420101801864803","3.01528735351563","16.5400009155273","0.0391410612792242"
"0.427460588980466","3.0632548828125","16.8299999237061","0.0397302683268208"
"0.434772780863568","3.11085131835938","17.1200008392334","0.0403811209253035"
"0.442131538875401","3.15877734375","17.4099998474121","0.0410246648243628"
"0.449490296887234","3.2057080078125","17.7000007629395","0.0415752110711765"
"0.456942216260359","3.2527685546875","17.9899997711182","0.042253450374119"
"0.464254408143461","3.29900830078125","18.2800006866455","0.0427635859523434"
"0.471659761387855","3.34497338867188","18.5699996948242","0.0433283421443775"
"0.478971953270957","3.3903525390625","18.8600006103516","0.0438730312453117"
"0.48633071128279","3.43351489257812","19.1499996185303","0.0444160650658887"
"0.493689498398453","3.4778896484375","19.4400005340576","0.0451043524662964"
"0.501094851642847","3.52200903320312","19.7299995422363","0.0456916095572524"
"0.50850014667958","3.56715673828125","20.0200004577637","0.0462060634163208"
"0.515858933795244","3.6098603515625","20.3099994659424","0.0467036370537244"
"0.523217720910907","3.65139038085938","20.6000003814697","0.0473243417218328"
"0.530529883690178","3.69237573242187","20.8899993896484","0.0478519395983312"
"0.537888670805842","3.73406274414062","21.1800003051758","0.0483719632029533"
"0.545294024050236","3.77589965820313","21.4699993133545","0.0489590711367782"
"0.55269937729463","3.81719311523437","21.7600002288818","0.0494425403303467"
"0.560011540073901","3.8562216796875","22.0499992370605","0.0499330162710976"
"0.567370327189565","3.89599560546875","22.3400001525879","0.050497597840149"
"0.574729056097567","3.93518627929688","22.6299991607666","0.0509465135110077"
"0.58208784321323","3.9739580078125","22.9200000762939","0.0514950042997953"
"0.589446630328894","4.0127744140625","23.2099990844727","0.0519718087161891"
"0.596851983573288","4.05109838867187","23.5","0.0524312345078215"
"0.604257278610021","4.09054736328125","23.7900009155273","0.0529097269463819"
"0.611616065725684","4.1280205078125","24.0799999237061","0.0533927559445146"
"0.618928286712617","4.16714013671875","24.3700008392334","0.0538507665623911"
"0.626287015620619","4.20575537109375","24.6599998474121","0.0543915739399381"
"0.633645802736282","4.244619140625","24.9500007629395","0.0549255419173278"
"0.641051155980676","4.28354296875","25.2399997711182","0.0553521640540566"
"0.64845650922507","4.32314892578125","25.5300006866455","0.0558652354811784"
"0.655768672004342","4.36116259765625","25.8199996948242","0.0564090514671989"
"0.663174025248736","4.400314453125","26.1100006103516","0.0569562471355312"
"0.670486188028008","4.43847265625","26.3999996185303","0.0574435762246139"
"0.677844975143671","4.477310546875","26.6900005340576","0.0579390398343094"
"0.685203762259334","4.51665234375","26.9799995422363","0.0585132038395386"
"0.692655681632459","4.55810009765625","27.2700004577637","0.0590311647101771"
"0.700014410540462","4.5971181640625","27.5599994659424","0.059530881117098"
"0.707373197656125","4.6364658203125","27.8500003814697","0.0601062165515032"
"0.714685418643057","4.675111328125","28.1399993896484","0.0605516070208978"
"0.72204414755106","4.715662109375","28.4300003051758","0.0611241775914095"
"0.729402934666723","4.7562919921875","28.7199993133545","0.0616651814198121"
"0.736854854039848","4.7974775390625","29.0100002288818","0.0622909064986743"
"0.744213641155511","4.8370576171875","29.2999992370605","0.0628516572760418"
"0.751525803934783","4.87683544921875","29.5900001525879","0.0633174568065442"
"0.758884591050446","4.917515625","29.8799991607666","0.0638655983493663"
"0.766243319958448","4.95721337890625","30.1700000762939","0.0644172905595042"
"0.773648673202842","4.9980341796875","30.4599990844727","0.0649220091872849"
"0.781007460318506","5.03716455078125","30.75","0.0655047842883505"
"0.7884128135629","5.07804931640625","31.0400009155273","0.0660913501633331"
"0.795771542470902","5.118509765625","31.3299999237061","0.066609907662496"
"0.803083763457835","5.159501953125","31.6200008392334","0.0672051319270395"
"0.810395926237106","5.19879736328125","31.9099998474121","0.067736953496933"
"0.8178012794815","5.23895654296875","32.2000007629395","0.068363813625183"
"0.825206632725894","5.28093212890625","32.4900016784668","0.0688832369633019"
"0.832611985970289","5.3232607421875","32.7799987792969","0.069473338953685"
"0.839970714878291","5.364458984375","33.0699996948242","0.0700167438481003"
"0.847282935865223","5.40444677734375","33.3600006103516","0.0706248683854938"
"0.854641722980887","5.44468994140625","33.6500015258789","0.0711764369043522"
"0.862000451888889","5.485828125","33.939998626709","0.0717359944246709"
"0.869359239004552","5.52753515625","34.2299995422363","0.072418202762492"
"0.876764592248946","5.56910205078125","34.5200004577637","0.0728977101971395"
"0.884123321156949","5.60965576171875","34.810001373291","0.0735788635211065"
"0.891528674401343","5.6511669921875","35.0999984741211","0.0740836476325057"
"0.898840895388275","5.6912333984375","35.3899993896484","0.0747461162973195"
"0.906199624296278","5.7326787109375","35.6800003051758","0.0753262720536441"
"0.913558411411941","5.774337890625","35.9700012207031","0.0759021131671034"
"0.921010330785066","5.81689111328125","36.2599983215332","0.0764633296057582"
"0.928369117900729","5.85807958984375","36.5499992370605","0.0770644401200116"
"0.935727846808732","5.899919921875","36.8400001525879","0.0777077584643848"
"0.943040067795664","5.9417109375","37.1300010681152","0.0783129144110717"
"0.950398854911327","5.98362451171875","37.4199981689453","0.0789899713709019"
"0.957711017690599","6.02466162109375","37.7099990844727","0.0796032545622438"
"0.965209503192455","6.067802734375","38","0.0802405847935006"
"0.972521724179387","6.11045361328125","38.2900009155273","0.0808046170277521"
"0.97992701921612","6.15255029296875","38.5800018310547","0.081474965554662"
"0.987285864539444","6.1945","38.8699989318848","0.0820801360532641"
"0.994598027318716","6.23473046875","39.1599998474121","0.0827312032924965"
"1.00195675622672","6.2755078125","39.4500007629395","0.0833216981845908"
"1.00936216767877","6.3183017578125","39.7400016784668","0.0839307831483893"
"1.01676746271551","6.360982421875","40.0299987792969","0.0846149923745543"
"1.02407962549478","6.4031396484375","40.3199996948242","0.0851561198942363"
"1.03148503694683","6.44585009765625","40.6100006103516","0.0859343999763951"
"1.03875063359737","6.48602392578125","40.9000015258789","0.0865777474245988"
"1.04615592863411","6.5298369140625","41.189998626709","0.087253974925261"
"1.05351477395743","6.57145556640625","41.4799995422363","0.0878814462339506"
"1.0609666351229","6.616546875","41.7700004577637","0.088642344053369"
"1.06827879790217","6.65907568359375","42.060001373291","0.0892544267117046"
"1.07568420935422","6.70071484375","42.3499984741211","0.0899565784493461"
"1.08299637213349","6.74324951171875","42.6399993896484","0.0906473869690672"
"1.0903551010415","6.78632177734375","42.9300003051758","0.091328372946009"
"1.09766738023609","6.82813232421875","43.2200012207031","0.0919696831260808"
"1.10507267527282","6.87025634765625","43.5099983215332","0.0926643333514221"
"1.11252465285361","6.9132978515625","43.7999992370605","0.0934249910642393"
"1.11988338176161","6.9555458984375","44.0900001525879","0.0941554317250848"
"1.12719554454088","6.997693359375","44.3800010681152","0.0948223969317041"
"1.13455427344888","7.0396240234375","44.6699981689453","0.0955449577304535"
"1.14191311877221","7.08281982421875","44.9599990844727","0.09628024417907"
"1.14927184768021","7.12494091796875","45.25","0.0970252731349319"
"1.15667725913227","7.17017822265625","45.5400009155273","0.0977442759904079"
"1.16403598804027","7.21314111328125","45.8300018310547","0.0986575323622674"
"1.17162766400725","7.23771435546875","46.1199989318848","0.0991361739579588"
"1.1787535622716","7.28191748046875","46.4099998474121","0.0998958275886253"
"1.18606572505087","7.32893017578125","46.7000007629395","0.10062221554108"
"1.1934710200876","7.37471240234375","46.9900016784668","0.101435434771702"
"1.20087643153965","7.41984521484375","47.2799987792969","0.102244193840306"
"1.20828172657639","7.46280126953125","47.5699996948242","0.103020342066884"
"1.21559388935566","7.50436083984375","47.8600006103516","0.103849830338731"
"1.22295273467898","7.54573779296875","48.1500015258789","0.104606137028895"
"1.23031146358699","7.5887607421875","48.439998626709","0.105408376839478"
"1.23771675862372","7.6321103515625","48.7299995422363","0.106197963759769"
"1.24507560394704","7.674345703125","49.0200004577637","0.107090760138817"
"1.25243433285505","7.7166376953125","49.310001373291","0.107844156445935"
"1.25979306176305","7.7587216796875","49.5999984741211","0.108647967863362"
"1.26710534095764","7.80131591796875","49.8899993896484","0.109468375740107"
"1.27455720212311","7.844337890625","50.1800003051758","0.110420551209245"
"1.28186936490238","7.88629150390625","50.4700012207031","0.111240340629593"
"1.28927477635443","7.929021484375","50.7599983215332","0.112160574644804"
"1.29663350526243","7.97182421875","51.0499992370605","0.113135814899579"
"1.30403891671449","8.015115234375","51.3400001525879","0.113952220999636"
"1.31135107949376","8.05733935546875","51.6300010681152","0.114892638521269"
"1.31870980840176","8.09828271484375","51.9199981689453","0.115889692096971"
"1.32602197118104","8.1393173828125","52.2099990844727","0.116785653517582"
"1.33347394876182","8.18137255859375","52.5","0.117739116831217"
"1.34083267766982","8.224521484375","52.7900009155273","0.118759569886606"
"1.34823808912188","8.26643359375","53.0800018310547","0.119697702757549"
"1.35555025190115","8.3067099609375","53.3699989318848","0.120818112918641"
"1.36295554693788","8.3480078125","53.6599998474121","0.121724100608844"
"1.37026782613248","8.389447265625","53.9500007629395","0.122691388241947"
"1.37757998891175","8.430720703125","54.2400016784668","0.123872043332085"
"1.38503185007721","8.474228515625","54.5299987792969","0.124947269796394"
"1.39239069540054","8.5149609375","54.8199996948242","0.126045881188475"
"1.39974942430854","8.555787109375","55.1100006103516","0.127114442875609"
"1.40710815321654","8.5967607421875","55.4000015258789","0.128279483760707"
"1.41446699853987","8.6378349609375","55.689998626709","0.129416293930262"
"1.42177916131914","8.6779951171875","55.9799995422363","0.130636501125991"
"1.4292310224846","8.719771484375","56.2700004577637","0.131942389998585"
"1.43658986780792","8.7587548828125","56.560001373291","0.133033521706238"
"1.44394859671593","8.7989892578125","56.8499984741211","0.134268935653381"
"1.45130732562393","8.838267578125","57.1399993896484","0.135589987621643"
"1.45866617094725","8.8767353515625","57.4300003051758","0.136844551889226"
"1.46602489985526","8.9150537109375","57.7200012207031","0.138161311042495"
"1.47343019489199","8.9535380859375","58.0099983215332","0.139498559292406"
"1.48074247408658","8.9936123046875","58.2999992370605","0.140890377224423"
"1.48814776912332","9.0333896484375","58.5900001525879","0.142355973366648"
"1.49550649803132","9.0714677734375","58.8800010681152","0.143835859489627"
"1.50286534335464","9.108625","59.1699981689453","0.145264493767172"
"1.51022407226264","9.14513671875","59.4599990844727","0.146773818414658"
"1.51758280117065","9.1830712890625","59.75","0.14837049820926"
"1.5249882126227","9.22180859375","60.0400009155273","0.150062493048608"
"1.5323469415307","9.2573974609375","60.3300018310547","0.151617918163538"
"1.53975235298276","9.29444921875","60.6199989318848","0.153360204421915"
"1.5470179496333","9.32781640625","60.9099998474121","0.155133631778881"
"1.55442324467003","9.3635712890625","61.2000007629395","0.156957117724232"
"1.56178197357804","9.39651171875","61.4900016784668","0.158805793034844"
"1.56918738503009","9.4304443359375","61.7799987792969","0.160681462148204"
"1.57654611393809","9.463064453125","62.0699996948242","0.162647760589607"
"1.58395152539015","9.49597265625","62.3600006103516","0.164617420523427"
"1.59126368816942","9.527666015625","62.6500015258789","0.166790676303208"
"1.59862241707742","9.558767578125","62.939998626709","0.168958300491795"
"1.60593457985669","9.5883125","63.2299995422363","0.171218242030591"
"1.61333999130875","9.6180986328125","63.5200004577637","0.173493550391868"
"1.62074528634548","9.64821484375","63.810001373291","0.175926208612509"
"1.62815069779754","9.6772470703125","64.0999984741211","0.178465634235181"
"1.63546286057681","9.7040205078125","64.3899993896484","0.181052091647871"
"1.64282158948481","9.7295478515625","64.6800003051758","0.183710639248602"
"1.65018043480814","9.7545400390625","64.9700012207031","0.186425939318724"
"1.65753916371614","9.779005859375","65.2600021362305","0.189333062735386"
"1.66494445875287","9.8034384765625","65.5500030517578","0.192314691958018"
"1.67230330407619","9.8250986328125","65.8399963378906","0.195356624317355"
"1.6796620329842","9.846416015625","66.129997253418","0.198571127839386"
"1.6870207618922","9.8654990234375","66.4199981689453","0.201804752578028"
"1.69437960721552","9.8844345703125","66.7099990844727","0.205123054911382"
"1.7016917699948","9.9028232421875","67","0.208569297683425"
"1.70909706503153","9.92046484375","67.2900009155273","0.212089784326963"
"1.71654904261231","9.936978515625","67.5800018310547","0.215764870517887"
"1.72386120539159","9.952744140625","67.870002746582","0.219500885577872"
"1.73121993429959","9.967498046875","68.1600036621094","0.223327762796544"
"1.73853221349418","9.981205078125","68.4499969482422","0.227335680392571"
"1.74593750853091","9.993234375","68.7399978637695","0.23133322247304"
"1.75329623743892","10.0052294921875","69.0299987792969","0.235487153986469"
"1.76070164889097","10.017224609375","69.3199996948242","0.239749613683671"
"1.76810694392771","10.02912109375","69.6100006103516","0.24406285956502"
"1.7754192231223","10.03832421875","69.9000015258789","0.248445809120312"
"1.7827779520303","10.04596875","70.1900024414063","0.252908270340413"
"1.79009011480957","10.0534140625","70.4800033569336","0.257442588917911"
"1.79749552626163","10.0600068359375","70.7699966430664","0.261993613094091"
"1.80490082129836","10.06901953125","71.0599975585938","0.2666286600288"
"1.81230611633509","10.07675","71.3499984741211","0.271370663540438"
"1.81961839552969","10.0825458984375","71.6399993896484","0.276153179584071"
"1.82697712443769","10.087693359375","71.9300003051758","0.280995009234175"
"1.83428928721696","10.093568359375","72.2200012207031","0.285765796434134"
"1.84169469866902","10.099716796875","72.5100021362305","0.290808908175677"
"1.84909999370575","10.1052509765625","72.8000030517578","0.295876932796091"
"1.85645872261375","10.110537109375","73.0899963378906","0.300881278235465"
"1.86381756793708","10.1150341796875","73.379997253418","0.305968889733776"
"1.87117629684508","10.1188818359375","73.6699981689453","0.311162759317085"
"1.87853502575308","10.1231650390625","73.9599990844727","0.316365243634209"
"1.88584730494767","10.12630078125","74.25","0.321563798934221"
"1.89325259998441","10.1307431640625","74.5400009155273","0.326807406963781"
"1.90065789502114","10.13405078125","74.8300018310547","0.332081341184676"
"1.9080633064732","10.13842578125","75.120002746582","0.337402074364945"
"1.91537546925247","10.140509765625","75.4100036621094","0.342735060257837"
"1.92273419816047","10.144103515625","75.6999969482422","0.348084140568972"
"1.93004647735506","10.1462626953125","75.9899978637695","0.353433832060546"
"1.9374517723918","10.15057421875","76.2799987792969","0.358802877599373"
"1.94485718384385","10.1547177734375","76.5699996948242","0.364195351721719"
"1.95221591275185","10.158751953125","76.8600006103516","0.369742512702942"
"1.95957464165986","10.16142578125","77.1500015258789","0.375271745724604"
"1.96693348698318","10.163060546875","77.4400024414063","0.380844896426424"
"1.97429209947586","10.1651591796875","77.7300033569336","0.386340485420078"
"1.98165094479918","10.16804296875","78.0199966430664","0.39178371662274"
"1.98905635625124","10.171900390625","78.3099975585938","0.397451309254393"
"1.99641496874392","10.17524609375","78.5999984741211","0.403089710744098"
"2.00382038019598","10.177115234375","78.8899993896484","0.408744468586519"
"2.01113265939057","10.1770439453125","79.1800003051758","0.414239708334208"
"2.01844470575452","10.1799619140625","79.4700012207031","0.419736054027453"
"2.02580355107784","10.1818193359375","79.7600021362305","0.42527326149866"
"2.03325552865863","10.185142578125","80.0500030517578","0.430899031925946"
"2.04061414115131","10.186990234375","80.3399963378906","0.436443719081581"
"2.04801955260336","10.1902666015625","80.629997253418","0.442064629169181"
"2.05528526566923","10.1922333984375","80.9199981689453","0.447592348791659"
"2.06269044429064","10.195275390625","81.2099990844727","0.453309941804036"
"2.07000272348523","10.196474609375","81.5","0.458896422060207"
"2.07740813493729","10.1989736328125","81.7900009155273","0.464582088170573"
"2.08476674742997","10.202220703125","82.0800018310547","0.470310507807881"
"2.09217215888202","10.2060869140625","82.370002746582","0.475958921015263"
"2.09953100420535","10.2081181640625","82.6600036621094","0.48170710215345"
"2.10688984952867","10.2094443359375","82.9499969482422","0.487419514684007"
"2.11420189589262","10.2107509765625","83.2399978637695","0.493122555781156"
"2.12160730734468","10.213080078125","83.5299987792969","0.498844077810645"
"2.12901271879673","10.216517578125","83.8199996948242","0.504467869177461"
"2.13637133128941","10.218099609375","84.1100006103516","0.510261859744787"
"2.14373017661273","10.2196494140625","84.4000015258789","0.515947525855154"
"2.15108902193606","10.2211640625","84.6900024414063","0.521612237207592"
"2.15840106830001","10.2237802734375","84.9800033569336","0.527297554071993"
"2.16575991362333","10.22566015625","85.2699966430664","0.53295202087611"
"2.17316532507539","10.2290888671875","85.5599975585938","0.538708933163434"
"2.18052393756807","10.2315478515625","85.8499984741211","0.54441491374746"
"2.18797591514885","10.2346796875","86.1399993896484","0.550225318875164"
"2.19528819434345","10.23662890625","86.4300003051758","0.555886246729642"
"2.20264680683613","10.2386875","86.7200012207031","0.561671622563154"
"2.20995908603072","10.24067578125","87.0100021362305","0.567435170523822"
"2.21736449748278","10.24309375","87.3000030517578","0.573233235627413"
"2.22476967610419","10.2457841796875","87.5899963378906","0.579015293624252"
"2.23217508755624","10.2491015625","87.879997253418","0.584844558034092"
"2.23948736675084","10.250267578125","88.1699981689453","0.590521027334034"
"2.24679941311479","10.2520517578125","88.4599990844727","0.596248137298971"
"2.25415825843811","10.253390625","88.75","0.601937586907297"
"2.26156366989017","10.2555712890625","89.0400009155273","0.607664929702878"
"2.26892228238285","10.2596689453125","89.3300018310547","0.613360374700278"
"2.2763276938349","10.2629892578125","89.620002746582","0.619167054537684"
"2.28368653915823","10.2658798828125","89.9100036621094","0.624958076514304"
"2.29104515165091","10.2674951171875","90.1999969482422","0.630747643299401"
"2.2983574308455","10.2684365234375","90.4899978637695","0.636508630122989"
"2.30576284229755","10.271552734375","90.7799987792969","0.642269558738917"
"2.31312145479023","10.274919921875","91.0699996948242","0.648049812298268"
"2.32052686624229","10.278193359375","91.3600006103516","0.653870520181954"
"2.32788571156561","10.279021484375","91.6500015258789","0.659719225950539"
"2.33524432405829","10.2808681640625","91.9400024414063","0.665425963234156"
"2.34255660325289","10.28333203125","92.2300033569336","0.671209534630179"
"2.34991544857621","10.2856591796875","92.5199966430664","0.676994735840708"
"2.35732062719762","10.2877607421875","92.8099975585938","0.682786165270954"
"2.36472603864968","10.28971484375","93.0999984741211","0.688445696141571"
"2.372084883973","10.2920048828125","93.3899993896484","0.694208953063935"
"2.37944349646568","10.2946259765625","93.6800003051758","0.699892931152135"
"2.38680234178901","10.2971650390625","93.9700012207031","0.705673359334469"
"2.3941146209836","10.2986669921875","94.2600021362305","0.711407512426376"
"2.40151979960501","10.30126953125","94.5500030517578","0.717120012268424"
"2.40887864492834","10.3042763671875","94.8399963378906","0.722861848771572"
"2.41633062250912","10.3098017578125","95.129997253418","0.728620623704046"
"2.42364266887307","10.3112275390625","95.4199981689453","0.734408444259316"
"2.4310015141964","10.3133779296875","95.7099990844727","0.740185205359012"
"2.43831379339099","10.31457421875","96","0.745854049455374"
"2.4457189720124","10.3176083984375","96.2900009155273","0.751754327211529"
"2.45307781733572","10.321111328125","96.5800018310547","0.757609435822815"
"2.46048322878778","10.3240791015625","96.870002746582","0.763411982916296"
"2.4678420741111","10.3250283203125","97.1600036621094","0.769066566135734"
"2.47520068660378","10.32693359375","97.4499969482422","0.774800020735711"
"2.48251296579838","10.3275947265625","97.7399978637695","0.780430971644819"
"2.48991837725043","10.3313837890625","98.0299987792969","0.786204764153808"
"2.49727698974311","10.3337412109375","98.3199996948242","0.791922560892999"
"2.50468240119517","10.337294921875","98.6100006103516","0.797620916273445"
"2.51204124651849","10.34039453125","98.9000015258789","0.803383649326861"
"2.51939985901117","10.3427099609375","99.1900024414063","0.809057441074401"
"2.52671213820577","10.3454072265625","99.4800033569336","0.814872502814978"
"2.53407098352909","10.3470390625","99.7699966430664","0.820582848973572"
"2.5414761621505","10.35079296875","100.059997558594","0.826304487418383"
"2.54883500747383","10.3525302734375","100.349998474121","0.832028163131326"
"2.55624041892588","10.3561640625","100.639999389648","0.837810686789453"
"2.56355246528983","10.35799609375","100.930000305176","0.843498099129647"
"2.57095787674189","10.360748046875","101.220001220703","0.849233358167112"
"2.57827015593648","10.3618349609375","101.51000213623","0.854912213981152"
"2.58567533455789","10.3642236328125","101.800003051758","0.860598287545145"
"2.59303417988122","10.367220703125","102.089996337891","0.866223592311144"
"2.60043959133327","10.3711337890625","102.379997253418","0.871950353030115"
"2.60779820382595","10.373623046875","102.669998168945","0.877657381352037"
"2.61515704914927","10.3748115234375","102.959999084473","0.883295899257064"
"2.62246932834387","10.3764619140625","103.25","0.889011658728123"
"2.62982794083655","10.3800673828125","103.540000915527","0.894527009222656"
"2.6372333522886","10.3837080078125","103.830001831055","0.900278449989855"
"2.64463876374066","10.3878857421875","104.120002746582","0.905978726223111"
"2.65199737623334","10.38965625","104.410003662109","0.911626208107919"
"2.65935622155666","10.391521484375","104.699996948242","0.917331606615335"
"2.66666850075126","10.39475","104.98999786377","0.923000508919358"
"2.67402711324394","10.39679296875","105.279998779297","0.928645255044103"
"2.68143252469599","10.399162109375","105.569999694824","0.934304669499397"
"2.68883793614805","10.402150390625","105.860000610352","0.939977180678397"
"2.69619654864073","10.405173828125","106.150001525879","0.945619423873723"
"2.70355539396405","10.4076748046875","106.440002441406","0.951309339143336"
"2.71086767315865","10.409982421875","106.730003356934","0.956947915256023"
"2.71822628565133","10.4116611328125","107.019996643066","0.962563790380955"
"2.72558513097465","10.4145068359375","107.309997558594","0.968308246228844"
"2.73303710855544","10.4177646484375","107.599998474121","0.973943737335503"
"2.74039572104812","10.421755859375","107.889999389648","0.979499076493084"
"2.74775456637144","10.4235078125","108.180000305176","0.985227292403579"
"2.75506684556603","10.4264658203125","108.470001220703","0.990870990790427"
"2.76242545805871","10.427935546875","108.76000213623","0.996443559415638"
"2.76978430338204","10.4306845703125","109.050003051758","1.00202369503677"
"2.77718971483409","10.4342802734375","109.339996337891","1.00764585658908"
"2.78459489345551","10.4378447265625","109.629997253418","1.01325393188745"
"2.7919071726501","10.4397744140625","109.919998168945","1.01892498787493"
"2.79931258410215","10.442513671875","110.209999084473","1.02465925738215"
"2.8066246304661","10.44402734375","110.5","1.03012030012906"
"2.81398347578943","10.4464189453125","110.790000915527","1.03568693157285"
"2.82134232111275","10.4485537109375","111.080001831055","1.04127707891166"
"2.82879406586289","10.4522978515625","111.370002746582","1.04688631836325"
"2.83615291118622","10.4554931640625","111.660003662109","1.05248263571411"
"2.84351175650954","10.4574169921875","111.949996948242","1.05800351593643"
"2.85082380287349","10.4598017578125","112.23999786377","1.06361682992429"
"2.85818264819682","10.4627578125","112.529998779297","1.06913095805794"
"2.86554149352014","10.465533203125","112.819999694824","1.0747293708846"
"2.87299347110093","10.469095703125","113.110000610352","1.0802565375343"
"2.88035208359361","10.4721826171875","113.400001525879","1.08597369398922"
"2.88771092891693","10.4749443359375","113.690002441406","1.09165103640407"
"2.89506977424026","10.477783203125","113.980003356934","1.09722942579538"
"2.90238182060421","10.4791044921875","114.269996643066","1.10279791988432"
"2.90974066592753","10.4806240234375","114.559997558594","1.10833591315895"
"2.91714607737958","10.482634765625","114.849998474121","1.11392128746957"
"2.924551256001","10.48725390625","115.139999389648","1.11951876897365"
"2.93191010132432","10.489291015625","115.430000305176","1.12507177982479"
"2.93926894664764","10.49159765625","115.720001220703","1.13054655957967"
"2.94658099301159","10.4929716796875","116.01000213623","1.13601062912494"
"2.95393983833492","10.497107421875","116.300003051758","1.14166282583028"
"2.96134524978697","10.4997763671875","116.589996337891","1.14722969010472"
"2.96875042840838","10.5031015625","116.879997253418","1.15274370182306"
"2.97606270760298","10.50530078125","117.169998168945","1.15828984417021"
"2.98346811905503","10.5082421875","117.459999084473","1.16383074782789"
"2.99078016541898","10.511212890625","117.75","1.16939400322735"
"2.99813901074231","10.513673828125","118.040000915527","1.17496901657432"
"3.00549785606563","10.515828125","118.330001831055","1.18053681217134"
"3.01290303468704","10.5187099609375","118.620002746582","1.18612730875611"
"3.0203084461391","10.521755859375","118.910003662109","1.19169149547815"
"3.02766729146242","10.524265625","119.199996948242","1.19724532123655"
"3.03497933782637","10.5261357421875","119.48999786377","1.20277795940638"
"3.0423381831497","10.5270283203125","119.779998779297","1.2084151385352"
"3.04974359460175","10.5297744140625","120.069999694824","1.21387408580631"
"3.05710220709443","10.5314892578125","120.360000610352","1.21939112432301"
"3.06450761854649","10.5366552734375","120.650001525879","1.22493924573064"
"3.07181989774108","10.5385361328125","120.940002441406","1.23048492241651"
"3.07922507636249","10.5410556640625","121.230003356934","1.23601756058633"
"3.08653735555708","10.542314453125","121.519996643066","1.24154810328037"
"3.09389620088041","10.54473828125","121.809997558594","1.24709191732109"
"3.10125481337309","10.5477607421875","122.099998474121","1.25267566181719"
"3.10870679095387","10.5516123046875","122.389999389648","1.2583319330588"
"3.1160656362772","10.554701171875","122.680000305176","1.2638735352084"
"3.12342424876988","10.55599609375","122.970001220703","1.2693862663582"
"3.13073652796447","10.557458984375","123.26000213623","1.27490540035069"
"3.1380953732878","10.5599580078125","123.550003051758","1.28047750331461"
"3.14550055190921","10.562662109375","123.839996337891","1.2860419228673"
"3.15290596336126","10.5650146484375","124.129997253418","1.29155081231147"
"3.16026480868459","10.5668447265625","124.419998168945","1.29694899078459"
"3.16757685504854","10.5686171875","124.709999084473","1.30253937095404"
"3.17493570037186","10.5718779296875","125","1.30808085668832"
"3.18229454569519","10.5742626953125","125.290000915527","1.31356331985444"
"3.18965315818787","10.5761875","125.580001831055","1.31922250147909"
"3.19705856963992","10.57901953125","125.870002746582","1.32470764219761"
"3.20446398109198","10.5827333984375","126.160003662109","1.33027520496398"
"3.21182259358466","10.5856552734375","126.449996948242","1.33593485224992"
"3.21918143890798","10.5873828125","126.73999786377","1.34150858502835"
"3.22649371810257","10.5886298828125","127.029998779297","1.34711514692754"
"3.23385233059525","10.5898857421875","127.319999694824","1.35263032279909"
"3.24125774204731","10.5932734375","127.610000610352","1.35826016776264"
"3.24861658737063","10.5966689453125","127.900001525879","1.36386405210942"
"3.25602176599205","10.598767578125","128.190002441406","1.36942858807743"
"3.26333404518664","10.5995546875","128.479995727539","1.37499766424298"
"3.27069289050996","10.6006796875","128.770004272461","1.38039700686932"
"3.27805150300264","10.602748046875","129.059997558594","1.38599670026451"
"3.28541034832597","10.6057490234375","129.350006103516","1.3915307354182"
"3.29281575977802","10.6082275390625","129.639999389648","1.39706255868077"
"3.30022117123008","10.6104912109375","129.929992675781","1.40265375375748"
"3.30757978372276","10.6132607421875","130.220001220703","1.40818627551198"
"3.31489206291735","10.6141611328125","130.509994506836","1.41366827301681"
"3.32225067541003","10.617658203125","130.800003051758","1.4192609814927"
"3.32960952073336","10.6196015625","131.089996337891","1.42479711212218"
"3.33706149831414","10.6232587890625","131.380004882813","1.43049098551273"
"3.34442034363747","10.6243857421875","131.669998168945","1.43608392681926"
"3.35177895613015","10.627021484375","131.960006713867","1.44161551725119"
"3.35909123532474","10.6286708984375","132.25","1.44717842340469"
"3.36645008064806","10.6304833984375","132.539993286133","1.45283748861402"
"3.37380869314075","10.6314873046875","132.830001831055","1.45839550532401"
"3.3812141045928","10.633388671875","133.119995117188","1.46397773642093"
"3.38857294991612","10.6365166015625","133.410003662109","1.46958720870316"
"3.3959315624088","10.6387900390625","133.699996948242","1.4751311391592"
"3.40333697386086","10.641484375","133.990005493164","1.48072838783264"
"3.41064925305545","10.641357421875","134.279998779297","1.48633099161088"
"3.41800786554813","10.6437939453125","134.570007324219","1.49190449155867"
"3.42536671087146","10.64633203125","134.860000610352","1.49743305519223"
"3.43281868845224","10.6505546875","135.149993896484","1.50315882638097"
"3.44013073481619","10.65139453125","135.440002441406","1.50879484135658"
"3.44753614626825","10.654263671875","135.729995727539","1.51437742169946"
"3.45480185933411","10.6547890625","136.020004272461","1.51994393672794"
"3.46220703795552","10.6579853515625","136.309997558594","1.52568507473916"
"3.46956588327885","10.6595615234375","136.600006103516","1.53124914504588"
"3.4769712947309","10.6621044921875","136.889999389648","1.53688667342067"
"3.48432990722358","10.6637099609375","137.179992675781","1.54258566908538"
"3.49173531867564","10.6655126953125","137.470001220703","1.54826510697603"
"3.49904759787023","10.66746875","137.759994506836","1.55388040002435"
"3.50640621036291","10.6686025390625","138.050003051758","1.55956554226577"
"3.51376505568624","10.6693681640625","138.339996337891","1.56512821558863"
"3.52117046713829","10.6718662109375","138.630004882813","1.5707720303908"
"3.5285756457597","10.6745732421875","138.919998168945","1.57629861496389"
"3.53593449108303","10.676353515625","139.210006713867","1.58191088121384"
"3.54324677027762","10.6783515625","139.5","1.5875807730481"
"3.55055881664157","10.679544921875","139.789993286133","1.5932401875034"
"3.55796422809362","10.6819111328125","140.080001831055","1.59894779790193"
"3.56532307341695","10.68356640625","140.369995117188","1.60464027430862"
"3.57272825203836","10.6866279296875","140.660003662109","1.61034241318703"
"3.58008709736168","10.6883994140625","140.949996948242","1.61601847503334"
"3.58749250881374","10.6898134765625","141.240005493164","1.62174156866968"
"3.59480455517769","10.6906591796875","141.529998779297","1.62746466230601"
"3.60216340050101","10.6922685546875","141.820007324219","1.63317751139402"
"3.60952224582434","10.693314453125","142.110000610352","1.63883646018803"
"3.61692742444575","10.695759765625","142.399993896484","1.64444954134524"
"3.6243328358978","10.6982607421875","142.690002441406","1.65020325221121"
"3.63169168122113","10.6994267578125","142.979995727539","1.65583961643279"
"3.63900372758508","10.700146484375","143.270004272461","1.66153907775879"
"3.6463625729084","10.7022568359375","143.559997558594","1.66719208937138"
"3.65372141823173","10.704146484375","143.850006103516","1.67292065452784"
"3.66112659685314","10.7057470703125","144.139999389648","1.67861627414823"
"3.66848544217646","10.7077294921875","144.429992675781","1.68430106714368"
"3.67589085362852","10.709625","144.720001220703","1.69007864315063"
"3.68320289999247","10.7117392578125","145.009994506836","1.69571512378752"
"3.69056174531579","10.713244140625","145.300003051758","1.70149025507271"
"3.69792059063911","10.7136630859375","145.589996337891","1.70719157904387"
"3.70527920313179","10.71498046875","145.880004882813","1.71290244907141"
"3.71268461458385","10.7183203125","146.169998168945","1.71872449573129"
"3.7200900260359","10.7199052734375","146.460006713867","1.72448996454477"
"3.72744887135923","10.7207822265625","146.75","1.73023890238255"
"3.73476091772318","10.7211279296875","147.039993286133","1.73594220541418"
"3.74207319691777","10.72218359375","147.330001831055","1.74160185270011"
"3.74947860836983","10.72409765625","147.619995117188","1.74733833409846"
"3.75688378699124","10.72665234375","147.910003662109","1.75309996120632"
"3.76424263231456","10.7286240234375","148.199996948242","1.75892561674118"
"3.77160147763789","10.7300185546875","148.490005493164","1.76472077146173"
"3.77891352400184","10.730626953125","148.779998779297","1.77044328302145"
"3.78631893545389","10.73270703125","149.070007324219","1.77620945032686"
"3.79367778077722","10.7337431640625","149.360000610352","1.78209599107504"
"3.80108295939863","10.7359091796875","149.649993896484","1.78789289202541"
"3.80844180472195","10.7367509765625","149.940002441406","1.79369968827814"
"3.81584721617401","10.739087890625","150.229995727539","1.79955619387329"
"3.82315926253796","10.73978125","150.520004272461","1.80545321200043"
"3.83051810786128","10.7407138671875","150.809997558594","1.81123323272914"
"3.83783038705587","10.7412841796875","151.100006103516","1.81707378942519"
"3.84528213180602","10.7430458984375","151.389999389648","1.82280864100903"
"3.85264097712934","10.7437978515625","151.679992675781","1.82864919770509"
"3.8600463885814","10.7458828125","151.970001220703","1.83452072087675"
"3.86735843494534","10.7472275390625","152.259994506836","1.84026057831943"
"3.87471728026867","10.7483095703125","152.550003051758","1.84615713078529"
"3.88207612559199","10.748587890625","152.839996337891","1.85200630221516"
"3.88943473808467","10.7500244140625","153.130004882813","1.85785547364503"
"3.89684014953673","10.7530048828125","153.419998168945","1.86369230505079"
"3.90424556098878","10.7549931640625","153.710006713867","1.86954624950886"
"3.91160417348146","10.756228515625","154","1.87551171984524"
"3.91891645267606","10.7558359375","154.289993286133","1.88132224138826"
"3.92622873187065","10.75663671875","154.580001831055","1.88723905012012"
"3.93358757719398","10.75794921875","154.869995117188","1.89315341413021"
"3.94103955477476","10.760263671875","155.160003662109","1.89909746404737"
"3.9483979344368","10.7603232421875","155.449996948242","1.90509541425854"
"3.95580334588885","10.761599609375","155.740005493164","1.91096984781325"
"3.96306905895472","10.7616416015625","156.029998779297","1.91680574789643"
"3.97047447040677","10.763451171875","156.320007324219","1.92266760859638"
"3.97783331573009","10.7641181640625","156.610000610352","1.92868802696466"
"3.98523872718215","10.7652734375","156.899993896484","1.93461601156741"
"3.99259710684419","10.7662802734375","157.190002441406","1.94059452041984"
"3.99995595216751","10.7682080078125","157.479995727539","1.94647011812776"
"4.00731479749084","10.7692958984375","157.770004272461","1.95244746282697"
"4.01467364281416","10.7699736328125","158.059997558594","1.95837626233697"
"4.02198592200875","10.7702587890625","158.350006103516","1.96440960280597"
"4.02939133346081","10.7712138671875","158.639999389648","1.9703428260982"
"4.03679627925158","10.77293359375","158.929992675781","1.97633425705135"
"4.04420169070363","10.7739833984375","159.220001220703","1.98239018209279"
"4.05151396989822","10.7743701171875","159.509994506836","1.98842445388436"
"4.05887281522155","10.7740087890625","159.800003051758","1.9943374209106"
"4.06623166054487","10.774802734375","160.089996337891","2.00030906125903"
"4.0735905058682","10.77514453125","160.380004882813","2.00630538165569"
"4.08094888553023","10.7773974609375","160.669998168945","2.01233779080212"
"4.08835429698229","10.7777861328125","160.960006713867","2.01841536909342"
"4.09575970843434","10.77909765625","161.25","2.02441541478038"
"4.10307198762894","10.7788037109375","161.539993286133","2.03049695119262"
"4.11043083295226","10.7799072265625","161.830001831055","2.03649583272636"
"4.11774311214685","10.7803974609375","162.119995117188","2.0426029805094"
"4.12514805793762","10.78185546875","162.410003662109","2.04867799766362"
"4.13260003551841","10.7831953125","162.699996948242","2.05482426099479"
"4.13995888084173","10.783392578125","162.990005493164","2.060939790681"
"4.14727116003633","10.7836240234375","163.279998779297","2.06702668219805"
"4.15458343923092","10.7841025390625","163.570007324219","2.07326444797218"
"4.16194228455424","10.7839228515625","163.860000610352","2.07936787046492"
"4.16934723034501","10.7839052734375","164.149993896484","2.08557327277958"
"4.17675264179707","10.7834384765625","164.440002441406","2.091706963256"
"4.18411148712039","10.785236328125","164.729995727539","2.09776661358774"
"4.19147033244371","10.7854609375","165.020004272461","2.10393965244293"
"4.19882917776704","10.7858154296875","165.309997558594","2.1101632155478"
"4.20614145696163","10.785490234375","165.600006103516","2.11614277213812"
"4.2135464027524","10.7853173828125","165.889999389648","2.12236819788814"
"4.22090524807572","10.7870947265625","166.179992675781","2.1284834947437"
"4.22835722565651","10.7889765625","166.470001220703","2.13484209962189"
"4.2356695048511","10.788193359375","166.759994506836","2.14103003963828"
"4.24302835017443","10.7880517578125","167.050003051758","2.14723986573517"
"4.25034062936902","10.788099609375","167.339996337891","2.15354515239596"
"4.25774557515979","10.7887685546875","167.630004882813","2.15977034531534"
"4.26510442048311","10.7889208984375","167.919998168945","2.16618343256414"
"4.27250983193517","10.788576171875","168.210006713867","2.17253575101495"
"4.27986867725849","10.78776171875","168.5","2.17877048999071"
"4.28722752258182","10.787544921875","168.789993286133","2.18507833778858"
"4.29458636790514","10.787666015625","169.080001831055","2.19138083048165"
"4.30189818143845","10.7866337890625","169.369995117188","2.19769473187625"
"4.3093035928905","10.786591796875","169.660003662109","2.20402353443205"
"4.31666243821383","10.786095703125","169.949996948242","2.21031834371388"
"4.32411441579461","10.7882099609375","170.240005493164","2.21669371239841"
"4.3314266949892","10.7867509765625","170.529998779297","2.22307769581676"
"4.33878554031253","10.786044921875","170.820007324219","2.22949683666229"
"4.34609735384583","10.7843388671875","171.110000610352","2.23585171625018"
"4.35350276529789","10.78462109375","171.399993896484","2.24228645674884"
"4.36090817674994","10.7846044921875","171.690002441406","2.24877684377134"
"4.368313588202","10.785287109375","171.979995727539","2.25531938485801"
"4.37562586739659","10.7836259765625","172.270004272461","2.26182909682393"
"4.38298471271992","10.7819541015625","172.559997558594","2.26834509521723"
"4.39029699191451","10.77916796875","172.850006103516","2.27477913722396"
"4.39770193770528","10.7788583984375","173.139999389648","2.28126370348036"
"4.4050607830286","10.7782958984375","173.429992675781","2.28784931823611"
"4.41246619448066","10.7774013671875","173.720001220703","2.29438301175833"
"4.41987160593271","10.7758427734375","174.009994506836","2.30097607709467"
"4.42718388512731","10.7733564453125","174.300003051758","2.30748835019767"
"4.4344961643219","10.7720517578125","174.589996337891","2.31406325474381"
"4.44185454398394","10.769873046875","174.880004882813","2.32076621614397"
"4.44925995543599","10.7691435546875","175.169998168945","2.32742889784276"
"4.45666536688805","10.7667529296875","175.460006713867","2.33415886759758"
"4.46402421221137","10.76521875","175.75","2.34075705520809"
"4.47133649140596","10.76246484375","176.039993286133","2.34759785234928"
"4.47874190285802","10.7609736328125","176.330001831055","2.3543902207166"
"4.48605371639132","10.7559267578125","176.619995117188","2.36125686205924"
"4.49345912784338","10.753029296875","176.910003662109","2.36803293228149"
"4.5008179731667","10.749599609375","177.199996948242","2.37491261214018"
"4.50822338461876","10.7481044921875","177.490005493164","2.38181045278907"
"4.51562879607081","10.743875","177.779998779297","2.38879374228418"
"4.52294107526541","10.73834765625","178.070007324219","2.3956757504493"
"4.53025288879871","10.7331201171875","178.360000610352","2.40252749063075"
"4.53761173412204","10.7288212890625","178.649993896484","2.4094944819808"
"4.54501714557409","10.72526953125","178.940002441406","2.41642049513757"
"4.55246912315488","10.720859375","179.229995727539","2.42354511283338"
"4.55978140234947","10.714310546875","179.520004272461","2.43068230338395"
"4.5671402476728","10.707119140625","179.809997558594","2.43775616399944"
"4.5744520612061","10.6993583984375","180.100006103516","2.44501256383955"
"4.58181090652943","10.6908828125","180.389999389648","2.45226477272809"
"4.58921631798148","10.6826376953125","180.679992675781","2.45957286097109"
"4.59662172943354","10.673197265625","180.970001220703","2.46696546673775"
"4.60398057475686","10.6653056640625","181.259994506836","2.47430405579507"
"4.61133942008018","10.654853515625","181.550003051758","2.48166103847325"
"4.61869779974222","10.64523828125","181.839996337891","2.48903082683682"
"4.62601007893682","10.6345087890625","182.130004882813","2.49653263017535"
"4.63341549038887","10.62465625","182.419998168945","2.5037657469511"
"4.64082090184093","10.6147080078125","182.710006713867","2.51130596734583"
"4.64822631329298","10.603501953125","183","2.51876469701529"
"4.65553859248757","10.5905673828125","183.289993286133","2.5263181887567"
"4.66289697214961","10.5770126953125","183.580001831055","2.53386655822396"
"4.6702092513442","10.5610615234375","183.869995117188","2.54145008511841"
"4.67761466279626","10.54299609375","184.160003662109","2.54917494021356"
"4.68497350811958","10.524853515625","184.449996948242","2.55706557072699"
"4.69237891957164","10.49730078125","184.740005493164","2.56526190787554"
"4.69973776489496","10.442119140625","185.029998779297","2.57441820576787"
"4.70714317634702","10.3229423828125","185.320007324219","2.58573587052524"
"4.71445498988032","10.255490234375","185.610000610352","2.59546469897032"
"4.72181383520365","10.2270537109375","185.899993896484","2.6037881616503"
"4.72917268052697","10.2019296875","186.190002441406","2.61199404485524"
"4.73657809197903","10.160314453125","186.479995727539","2.6207878254354"
"4.74398350343108","10.101916015625","186.770004272461","2.63011315837502"
"4.75129578262568","10.0463740234375","187.059997558594","2.63924081809819"
"4.75860759615898","9.9893017578125","187.350006103516","2.64851353131235"
"4.76601300761104","9.8806083984375","187.639999389648","2.65964050777256"
"4.7726733610034","-0.780752502441406","187.850997924805","3.0710157006979"